File: data/ThreePoint Core/Core50-15.is_comp_RawData/CoreBend50-15.csv
Time,Extension,Load
(sec),(mm),(N)
0.00000,0.00000,-0.01688
0.20000,-0.05124,0.02271
0.40000,-0.11820,-0.02279
0.60000,-0.17985,-0.00218
0.80000,-0.24005,-0.00977
1.00000,-0.30014,-0.03190
1.20000,-0.36011,-0.04253
1.40000,-0.42020,-0.05814
1.60000,-0.48017,-0.07259
1.80000,-0.54002,-0.07944
2.00000,-0.60005,-0.07779
2.20000,-0.66008,-0.07908
2.40000,-0.72010,-0.07710
2.60000,-0.78001,-0.07780
2.80000,-0.84004,-0.08803
3.00000,-0.90007,-0.09420
3.20000,-0.96004,-0.09652
3.40000,-1.02007,-0.10769
3.60000,-1.08004,-0.11619
3.80000,-1.13995,-0.12293
4.00000,-1.19998,-0.12330
4.20000,-1.26006,-0.12525
4.40000,-1.32003,-0.14235
4.60000,-1.38000,-0.14844
4.80000,-1.44003,-0.16056
5.00000,-1.50006,-0.17091
5.20000,-1.56009,-0.18616
5.40000,-1.62006,-0.19983
5.60000,-1.68008,-0.21578
5.80000,-1.74005,-0.22533
6.00000,-1.80008,-0.24278
6.20000,-1.85999,-0.24023
6.40000,-1.92002,-0.23303
6.60000,-1.97975,-0.23928
6.80000,-2.03996,-0.23958
7.00000,-2.10017,-0.23385
7.20000,-2.16002,-0.23409
7.40000,-2.21992,-0.23054
7.60000,-2.27995,-0.23356
7.80000,-2.33992,-0.23252
8.00000,-2.39995,-0.23305
8.20000,-2.45998,-0.23264
8.40000,-2.51989,-0.23584
8.60000,-2.58016,-0.23260
8.80000,-2.64007,-0.23649
9.00000,-2.70009,-0.23436
9.20000,-2.76006,-0.23783
9.40000,-2.82003,-0.23833
9.60000,-2.88012,-0.24240
9.80000,-2.94003,-0.24298
10.00000,-3.00006,-0.24602
10.20000,-3.06009,-0.25427
10.40000,-3.12017,-0.25772
10.60000,-3.18002,-0.25714
10.80000,-3.23993,-0.26164
11.00000,-3.29996,-0.26415
11.20000,-3.36005,-0.27370
11.40000,-3.41996,-0.28695
11.60000,-3.48005,-0.28235
11.80000,-3.54002,-0.29363
12.00000,-3.60005,-0.30100
12.20000,-3.66001,-0.31136
12.40000,-3.72010,-0.32251
12.60000,-3.78013,-0.32666
12.80000,-3.84004,-0.33588
13.00000,-3.89995,-0.34455
13.20000,-3.96004,-0.34874
13.40000,-4.02007,-0.35915
13.60000,-4.08004,-0.36635
13.80000,-4.14000,-0.37186
14.00000,-4.20009,-0.38295
14.20000,-4.26012,-0.38637
14.40000,-4.32009,-0.38750
14.60000,-4.38006,-0.40047
14.80000,-4.44003,-0.40113
15.00000,-4.50000,-0.41102
15.20000,-4.55991,-0.42043
15.40000,-4.61999,-0.42849
15.60000,-4.68014,-0.43755
15.80000,-4.74011,-0.44632
16.00000,-4.79996,-0.45425
16.20000,-4.86005,-0.46692
16.40000,-4.91996,-0.47821
16.60000,-4.97993,-0.48604
16.80000,-5.04020,-0.50138
17.00000,-5.10010,-0.50901
17.20000,-5.15995,-0.52437
17.40000,-5.21992,-0.53854
17.60000,-5.28001,-0.53968
17.80000,-5.34010,-0.56169
18.00000,-5.40007,-0.56705
18.20000,-5.46004,-0.57858
18.40000,-5.51995,-0.58976
18.60000,-5.58009,-0.60458
18.80000,-5.64018,-0.60805
19.00000,-5.70009,-0.62651
19.20000,-5.75994,-0.63759
19.40000,-5.81991,-0.65383
19.60000,-5.87994,-0.67112
19.80000,-5.94003,-0.68908
20.00000,-6.00000,-0.70371
20.20000,-6.06002,-0.71682
20.40000,-6.12005,-0.73963
20.60000,-6.18008,-0.75580
20.80000,-6.24011,-0.77105
21.00000,-6.30008,-0.79070
21.20000,-6.36017,-0.80446
21.40000,-6.42002,-0.82096
21.60000,-6.47999,-0.83417
21.80000,-6.53995,-0.85112
22.00000,-6.60004,-0.86556
22.20000,-6.66001,-0.88089
22.40000,-6.72004,-0.90226
22.60000,-6.78001,-0.91721
22.80000,-6.84010,-0.93002
23.00000,-6.90001,-0.94644
23.20000,-6.96004,-0.95007
23.40000,-7.02006,-0.94559
23.60000,-7.07997,-0.93433
23.80000,-7.13994,-0.92576
24.00000,-7.19997,-0.92096
24.20000,-7.26006,-0.93365
24.40000,-7.32009,-0.93037
24.60000,-7.38000,-0.93922
24.80000,-7.44003,-0.93729
25.00000,-7.50011,-0.93388
25.20000,-7.56008,-0.92503
25.40000,-7.62005,-0.91143
25.60000,-7.68008,-0.89478
25.80000,-7.73999,-0.88181
26.00000,-7.80002,-0.86824
26.20000,-7.85993,-0.85695
26.40000,-7.91996,-0.84549
26.60000,-7.98016,-0.83800
26.80000,-8.04007,-0.82367
27.00000,-8.10010,-0.80899
27.20000,-8.16007,-0.79859
27.40000,-8.22004,-0.78281
27.60000,-8.28007,-0.77063
27.80000,-8.34010,-0.75760
28.00000,-8.39995,-0.74677
28.20000,-8.45992,-0.73794
28.40000,-8.52000,-0.73450
28.60000,-8.58003,-0.76092
28.80000,-8.64006,-0.79636
29.00000,-8.70003,-0.83127
29.20000,-8.76000,-0.86721
29.40000,-8.82003,-0.89894
29.60000,-8.88000,-0.93741
29.80000,-8.93991,-0.97084
30.00000,-8.99999,-0.99749
30.20000,-9.05996,-1.00688
30.40000,-9.11999,-0.97931
30.60000,-9.18002,-0.96071
30.80000,-9.24011,-0.93861
31.00000,-9.30008,-0.92107
31.20000,-9.36005,-0.90819
31.40000,-9.42002,-0.91109
31.60000,-9.47998,-0.94382
31.80000,-9.53995,-0.97883
32.00000,-9.59998,-1.01600
32.20000,-9.66001,-1.05808
32.40000,-9.72004,-1.09787
32.60000,-9.78007,-1.14123
32.80000,-9.84010,-1.18536
33.00000,-9.90012,-1.22834
33.20000,-9.96009,-1.27225
33.40000,-10.02006,-1.31027
33.60000,-10.07997,-1.35009
33.80000,-10.13994,-1.39583
34.00000,-10.19997,-1.43869
34.20000,-10.25994,-1.48117
34.40000,-10.32009,-1.52636
34.60000,-10.38006,-1.57127
34.80000,-10.44008,-1.61614
35.00000,-10.50011,-1.65707
35.20000,-10.56008,-1.70117
35.40000,-10.62005,-1.72991
35.60000,-10.68008,-1.69567
35.80000,-10.74011,-1.66442
36.00000,-10.80008,-1.63323
36.20000,-10.85993,-1.60863
36.40000,-10.92007,-1.58323
36.60000,-10.97998,-1.57241
36.80000,-11.04001,-1.62031
37.00000,-11.10010,-1.66948
37.20000,-11.16007,-1.72195
37.40000,-11.22010,-1.76878
37.60000,-11.28001,-1.81854
37.80000,-11.34016,-1.86643
38.00000,-11.40006,-1.91012
38.20000,-11.45997,-1.94372
38.40000,-11.52000,-1.97633
38.60000,-11.57997,-2.00525
38.80000,-11.64000,-1.97035
39.00000,-11.70003,-1.93280
39.20000,-11.76000,-1.89799
39.40000,-11.82003,-1.86357
39.60000,-11.87999,-1.83432
39.80000,-11.94002,-1.83561
40.00000,-11.99999,-1.89227
40.20000,-12.05996,-1.94480
40.40000,-12.11999,-1.99826
40.60000,-12.18002,-2.05523
40.80000,-12.23999,-2.10608
41.00000,-12.30008,-2.15728
41.20000,-12.35998,-2.19872
41.40000,-12.42007,-2.22343
41.60000,-12.48010,-2.19042
41.80000,-12.54001,-2.14516
42.00000,-12.59998,-2.10936
42.20000,-12.66001,-2.07290
42.40000,-12.72004,-2.04363
42.60000,-12.78013,-2.05388
42.80000,-12.84003,-2.11242
43.00000,-12.90000,-2.16756
43.20000,-12.96009,-2.22640
43.40000,-13.02006,-2.28182
43.60000,-13.07997,-2.32696
43.80000,-13.14000,-2.35672
44.00000,-13.20009,-2.35788
44.20000,-13.26012,-2.36458
44.40000,-13.32002,-2.31928
44.60000,-13.38005,-2.27215
44.80000,-13.44002,-2.23236
45.00000,-13.50005,-2.18964
45.20000,-13.56008,-2.15233
45.40000,-13.62005,-2.11311
45.60000,-13.67996,-2.08577
45.80000,-13.73993,-2.13231
46.00000,-13.79995,-2.19521
46.20000,-13.86004,-2.26075
46.40000,-13.92013,-2.32328
46.60000,-13.98004,-2.38602
46.80000,-14.04001,-2.44649
47.00000,-14.10010,-2.49997
47.20000,-14.16019,-2.54126
47.40000,-14.22010,-2.55083
47.60000,-14.28001,-2.56514
47.80000,-14.34003,-2.50980
48.00000,-14.40006,-2.45814
48.20000,-14.46003,-2.41394
48.40000,-14.52006,-2.36237
48.60000,-14.58003,-2.30828
48.80000,-14.63988,-2.26703
49.00000,-14.69997,-2.21487
49.20000,-14.75999,-2.17216
49.40000,-14.81996,-2.13106
49.60000,-14.87999,-2.08124
49.80000,-14.94002,-2.02723
50.00000,-15.00005,-1.98421
50.20000,-15.05996,-1.93349
50.40000,-15.12005,-1.89785
50.60000,-15.18002,-1.89578
50.80000,-15.23993,-1.95985
51.00000,-15.30001,-2.02480
51.20000,-15.36004,-2.09702
51.40000,-15.42007,-2.16484
51.60000,-15.47998,-2.18243
51.80000,-15.53995,-2.13229
52.00000,-15.60004,-2.07073
52.20000,-15.66001,-2.01000
52.40000,-15.71998,-1.95478
52.60000,-15.78006,-1.91153
52.80000,-15.84009,-1.89445
53.00000,-15.89994,-1.97397
53.20000,-15.96003,-2.04711
53.40000,-16.02000,-2.10473
53.60000,-16.08015,-2.07982
53.80000,-16.14012,-2.02605
54.00000,-16.20003,-1.97119
54.20000,-16.26005,-1.92349
54.40000,-16.32002,-1.91149
54.60000,-16.37999,-1.99367
54.80000,-16.44002,-2.06915
55.00000,-16.50011,-2.14646
55.20000,-16.56002,-2.22425
55.40000,-16.62011,-2.29061
55.60000,-16.68007,-2.21845
55.80000,-16.73998,-2.15027
56.00000,-16.80001,-2.09546
56.20000,-16.86004,-2.03811
56.40000,-16.92013,-1.98650
56.60000,-16.98016,-2.03765
56.80000,-17.04007,-2.11523
57.00000,-17.10004,-2.19804
57.20000,-17.16007,-2.28318
57.40000,-17.22003,-2.36182
57.60000,-17.28000,-2.44506
57.80000,-17.34003,-2.48264
58.00000,-17.40000,-2.39079
58.20000,-17.46009,-2.32085
58.40000,-17.52006,-2.25318
58.60000,-17.58015,-2.19618
58.80000,-17.64006,-2.12788
59.00000,-17.70008,-2.06969
59.20000,-17.76011,-2.02562
59.40000,-17.82008,-1.98522
59.60000,-17.88005,-1.96572
59.80000,-17.94008,-2.00263
60.00000,-18.00005,-2.10322
60.20000,-18.06002,-2.18799
60.40000,-18.11998,-2.27671
60.60000,-18.18007,-2.36155
60.80000,-18.23998,-2.35551
61.00000,-18.29995,-2.29508
61.20000,-18.35998,-2.21719
61.40000,-18.41995,-2.14924
61.60000,-18.47998,-2.10687
61.80000,-18.54001,-2.06253
62.00000,-18.59992,-2.08018
62.20000,-18.66000,-2.19477
62.40000,-18.71991,-2.28268
62.60000,-18.78000,-2.38144
62.80000,-18.84009,-2.47226
63.00000,-18.90012,-2.56077
63.20000,-18.95997,-2.65643
63.40000,-19.02000,-2.71787
63.60000,-19.07997,-2.64367
63.80000,-19.13993,-2.56971
64.00000,-19.19996,-2.49418
64.20000,-19.25993,-2.43125
64.40000,-19.31996,-2.37496
64.60001,-19.37999,-2.40396
64.80000,-19.44008,-2.51445
65.00000,-19.49999,-2.62015
65.20000,-19.56008,-2.72496
65.40000,-19.62010,-2.82898
65.60001,-19.68001,-3.01568
65.76200,-19.72850,-3.22091
65.96201,-19.78847,-3.19870
66.16200,-19.84862,-3.14918
66.36200,-19.90871,-3.10108
66.56201,-19.96862,-3.11230
66.76200,-20.02859,-3.21643
66.96201,-20.08861,-3.31220
67.16200,-20.14870,-3.41523
67.36200,-20.20873,-3.51525
67.56201,-20.26870,-3.61414
67.76200,-20.32861,-3.70820
67.96201,-20.38858,-3.80579
68.16200,-20.44867,-3.90285
68.36200,-20.50864,-3.99559
68.56201,-20.56866,-4.08795
68.69000,-20.60705,-4.28674
68.71001,-20.61303,-4.57527
68.82401,-20.64723,-4.83643
69.02400,-20.70720,-4.92752
69.22401,-20.76729,-4.91384
69.42400,-20.82731,-4.81546
69.62400,-20.88722,-4.73686
69.82401,-20.94725,-4.65400
70.02400,-21.00722,-4.58228
70.22401,-21.06725,-4.49949
70.42400,-21.12728,-4.42044
70.62400,-21.18731,-4.34749
70.82401,-21.24727,-4.28474
71.02400,-21.30724,-4.23298
71.22401,-21.36721,-4.18326
71.42400,-21.42724,-4.27876
71.62400,-21.48727,-4.38291
71.82401,-21.54730,-4.48823
72.02400,-21.60715,-4.58933
72.22401,-21.66718,-4.69299
72.42400,-21.72727,-4.79304
72.62400,-21.78718,-4.88301
72.82401,-21.84726,-4.79959
73.02400,-21.90729,-4.70631
73.22401,-21.96726,-4.60737
73.42400,-22.02729,-4.52141
73.62400,-22.08720,-4.43553
73.82401,-22.14723,-4.35698
74.02400,-22.20732,-4.34602
74.22401,-22.26728,-4.42075
74.42400,-22.32725,-4.52726
74.62400,-22.38716,-4.63371
74.82401,-22.44725,-4.73490
75.02400,-22.50728,-4.82284
75.22401,-22.56731,-4.75354
75.42400,-22.62734,-4.67462
75.62400,-22.68731,-4.60390
75.82401,-22.74721,-4.52595
76.02400,-22.80724,-4.47531
76.22401,-22.86715,-4.51103
76.42400,-22.92712,-4.62479
76.62400,-22.98715,-4.73430
76.82401,-23.04724,-4.84464
77.02400,-23.10721,-4.94957
77.22401,-23.16718,-4.90515
77.42400,-23.22732,-4.81620
77.62400,-23.28729,-4.71520
77.82401,-23.34726,-4.62263
78.02400,-23.40717,-4.54545
78.22401,-23.46720,-4.58298
78.42400,-23.52723,-4.69796
78.62400,-23.58720,-4.81004
78.82401,-23.64717,-4.93388
79.02400,-23.70726,-5.03758
79.22401,-23.76716,-4.95252
79.42400,-23.82725,-4.83778
79.62400,-23.88722,-4.73964
79.82401,-23.94719,-4.65494
80.02400,-24.00710,-4.58205
80.22401,-24.06719,-4.65088
80.42400,-24.12722,-4.78002
80.62400,-24.18724,-4.90904
80.82401,-24.24721,-5.03078
81.02400,-24.30718,-5.15278
81.22401,-24.36721,-5.27959
81.42400,-24.42724,-5.26579
81.62400,-24.48715,-5.17426
81.82401,-24.54724,-5.09008
82.02400,-24.60733,-4.99396
82.22401,-24.66724,-4.92402
82.42400,-24.72720,-4.86375
82.62400,-24.78723,-4.88904
82.82401,-24.84720,-5.02343
83.02400,-24.90723,-5.15093
83.22401,-24.96726,-5.27758
83.42400,-25.02723,-5.39560
83.62400,-25.08726,-5.51019
83.82401,-25.14723,-5.62203
84.02400,-25.20731,-5.72241
84.22401,-25.26728,-5.68932
84.42400,-25.32731,-5.57900
84.62400,-25.38722,-5.48071
84.82401,-25.44725,-5.37962
85.02400,-25.50734,-5.28021
85.22401,-25.56737,-5.19484
85.42400,-25.62715,-5.10922
85.62400,-25.68712,-5.06007
85.82401,-25.74727,-5.13495
86.02400,-25.80730,-5.26638
86.22401,-25.86727,-5.39549
86.42400,-25.92724,-5.52332
86.62400,-25.98715,-5.63955
86.82401,-26.04706,-5.75834
87.02400,-26.10714,-5.85256
87.22401,-26.16735,-5.72716
87.42400,-26.22720,-5.62756
87.62400,-26.28729,-5.51899
87.82401,-26.34720,-5.41811
88.02400,-26.40723,-5.33388
88.22401,-26.46726,-5.29401
88.42400,-26.52723,-5.42246
88.62400,-26.58714,-5.55682
88.82401,-26.64710,-5.67708
89.02400,-26.70713,-5.80589
89.22401,-26.76722,-5.93563
89.42400,-26.82731,-6.04384
89.62400,-26.88734,-6.14889
89.82401,-26.94719,-6.25670
89.89800,-26.96937,-6.58116
89.91200,-26.97355,-6.87347
89.94200,-26.98264,-7.14370
90.14201,-27.04261,-7.15469
90.34200,-27.10264,-7.16669
90.54201,-27.16273,-7.16579
90.74201,-27.22276,-7.16342
90.94200,-27.28261,-7.17141
91.14201,-27.34264,-7.18039
91.34200,-27.40260,-7.18216
91.54201,-27.46263,-7.19057
91.74201,-27.52260,-7.20270
91.94200,-27.58257,-7.20025
92.14201,-27.64260,-7.19815
92.34200,-27.70251,-7.21667
92.54201,-27.76260,-7.22104
92.74201,-27.82269,-7.22411
92.94200,-27.88265,-7.23589
93.14201,-27.94256,-7.13010
93.34200,-28.00265,-7.02010
93.54201,-28.06256,-6.92857
93.74201,-28.12265,-6.81529
93.94200,-28.18262,-6.72283
94.14201,-28.24265,-6.66490
94.34200,-28.30267,-6.62165
94.54201,-28.36264,-6.75959
94.74201,-28.42261,-6.89296
94.94200,-28.48258,-7.03059
95.14201,-28.54237,-7.15337
95.34200,-28.60270,-7.28547
95.54201,-28.66267,-7.39270
95.74201,-28.72270,-7.41167
95.94200,-28.78278,-7.41404
96.14201,-28.84263,-7.40988
96.34200,-28.90254,-7.43194
96.54201,-28.96257,-7.43379
96.74201,-29.02266,-7.43438
96.94200,-29.08257,-7.42399
97.14201,-29.14266,-7.43996
97.34200,-29.20263,-7.43596
97.54201,-29.26254,-7.44977
97.74201,-29.32268,-7.44794
97.94200,-29.38271,-7.45465
98.14201,-29.44274,-7.46965
98.34200,-29.50265,-7.46564
98.54201,-29.56250,-7.47487
98.74201,-29.62265,-7.46918
98.94200,-29.68268,-7.47424
99.14201,-29.74265,-7.48826
99.34200,-29.80261,-7.48311
99.54201,-29.86270,-7.48240
99.74201,-29.92261,-7.49944
99.94200,-29.98264,-7.49718
100.14201,-30.04267,-7.49344
100.34200,-30.10258,-7.51288
100.54201,-30.16261,-7.51088
100.74201,-30.22257,-7.51622
100.94200,-30.28261,-7.52111
101.14201,-30.34263,-7.53866
101.34200,-30.40266,-7.53274
101.54201,-30.46263,-7.53514
101.74201,-30.52266,-7.53831
101.94200,-30.58257,-7.53390
102.14201,-30.64260,-7.53472
102.34200,-30.70257,-7.53808
102.54201,-30.76253,-7.54174
102.74201,-30.82262,-7.56617
102.94200,-30.88259,-7.55641
103.14201,-30.94268,-7.55647
103.34200,-31.00259,-7.56086
103.54201,-31.06262,-7.54788
103.74201,-31.12265,-7.55596
103.94200,-31.18262,-7.56007
104.14201,-31.24271,-7.56234
104.34200,-31.30262,-7.55711
104.54201,-31.36259,-7.55703
104.74201,-31.42255,-7.55990
104.94200,-31.48258,-7.56219
105.14201,-31.54261,-7.57244
105.34200,-31.60264,-7.57948
105.54201,-31.66255,-7.58009
105.74201,-31.72257,-7.58119
105.94200,-31.78254,-7.59829
106.14201,-31.84269,-7.59435
106.34200,-31.90266,-7.58883
106.54201,-31.96263,-7.60719
106.74201,-32.02266,-7.59007
106.94200,-32.08269,-7.59544
107.14201,-32.14272,-7.59115
107.34200,-32.20263,-7.59409
107.54201,-32.26272,-7.59275
107.74201,-32.32262,-7.60246
107.94200,-32.38265,-7.60167
108.14201,-32.44268,-7.60551
108.34200,-32.50271,-7.61284
108.54201,-32.56262,-7.61198
108.74201,-32.62265,-7.60823
108.94201,-32.68267,-7.61635
109.14201,-32.74270,-7.60049
109.34200,-32.80262,-7.60141
109.54201,-32.86258,-7.60876
109.74201,-32.92261,-7.59891
109.94201,-32.98258,-7.61920
110.14201,-33.04267,-7.60949
110.34200,-33.10270,-7.60420
110.54201,-33.16266,-7.61254
110.74201,-33.22257,-7.61113
110.94201,-33.28254,-7.61349
111.14201,-33.34257,-7.61985
111.34200,-33.40254,-7.62720
111.54201,-33.46269,-7.61928
111.74201,-33.52272,-7.64446
111.94201,-33.58263,-7.63796
112.14201,-33.64260,-7.64500
112.34200,-33.70263,-7.65646
112.54201,-33.76265,-7.66372
112.74201,-33.82262,-7.65638
112.94201,-33.88247,-7.68135
113.14201,-33.94256,-7.69866
113.29201,-33.98770,-7.86801
113.35201,-34.00570,-8.12337
113.55200,-34.06567,-8.18533
113.75201,-34.12552,-8.17184
113.95200,-34.18554,-8.18832
114.15201,-34.24569,-8.20774
114.35201,-34.30566,-8.20810
114.55200,-34.36569,-8.21033
114.75201,-34.42566,-8.20239
114.95200,-34.48563,-8.20877
115.15201,-34.54554,-8.22403
115.35201,-34.60551,-8.22184
115.55200,-34.66565,-8.25405
115.75201,-34.72574,-8.25669
115.95200,-34.78571,-8.27837
116.15201,-34.84574,-8.28368
116.35201,-34.90565,-8.29596
116.55200,-34.96562,-8.31258
116.75201,-35.02571,-8.30247
116.95200,-35.08561,-8.31708
117.15201,-35.14558,-8.31324
117.35201,-35.20555,-8.32599
117.55200,-35.26552,-8.34998
117.75201,-35.32561,-8.36173
117.95200,-35.38558,-8.38654
118.15201,-35.44567,-8.39794
118.35201,-35.50558,-8.42045
118.55200,-35.56567,-8.45050
118.75201,-35.62564,-8.44440
118.95200,-35.68572,-8.41078
119.15201,-35.74569,-8.43896
119.35201,-35.80560,-8.38958
119.55200,-35.86563,-8.23846
119.75201,-35.92572,-8.22068
119.95200,-35.98568,-8.33344
120.15201,-36.04566,-8.45493
120.35201,-36.10563,-8.43913
120.55200,-36.16565,-8.48508
120.75201,-36.22562,-8.49677
120.95200,-36.28559,-8.31279
121.15201,-36.34550,-8.15593
121.35201,-36.40565,-7.99213
121.55201,-36.46556,-8.01648
121.75201,-36.52558,-8.17576
121.95200,-36.58555,-8.23405
122.15201,-36.64564,-8.33696
122.35201,-36.70567,-8.21236
122.55201,-36.76558,-8.04673
122.75201,-36.82567,-7.94806
122.95200,-36.88570,-8.01519
123.15201,-36.94567,-8.06994
123.35201,-37.00558,-8.20984
123.55201,-37.06560,-8.38539
123.75201,-37.12557,-8.53100
123.95200,-37.18560,-8.31519
124.15201,-37.24563,-8.15452
124.35201,-37.30572,-7.99822
124.55201,-37.36569,-7.85735
124.75201,-37.42560,-7.84129
124.95200,-37.48557,-7.99711
125.15201,-37.54559,-8.14129
125.35201,-37.60568,-8.15152
125.55201,-37.66553,-7.98907
125.75201,-37.72556,-7.83442
125.95200,-37.78571,-7.67816
126.15201,-37.84574,-7.53804
126.35201,-37.90571,-7.53601
126.55201,-37.96568,-7.49880
126.75201,-38.02564,-7.51749
126.95200,-38.08561,-7.64296
127.15201,-38.14570,-7.81612
127.35201,-38.20567,-7.96970
127.55201,-38.26558,-8.12858
127.75201,-38.32561,-8.27361
127.95200,-38.38575,-8.11167
128.15201,-38.44567,-7.94234
128.35201,-38.50576,-7.77436
128.55200,-38.56560,-7.59465
128.75200,-38.62563,-7.45872
128.95201,-38.68566,-7.47241
129.15201,-38.74569,-7.60075
129.35201,-38.80554,-7.77596
129.55200,-38.86563,-7.94716
129.75200,-38.92565,-8.11933
129.95201,-38.98562,-8.28010
130.15201,-39.04559,-8.41225
130.33602,-39.10084,-8.18223
130.53601,-39.16081,-7.98741
130.73601,-39.22078,-7.83565
130.93601,-39.28087,-7.64576
131.13600,-39.34077,-7.51304
131.33602,-39.40080,-7.45380
131.53602,-39.46089,-7.44741
131.73600,-39.52086,-7.47205
131.93600,-39.58083,-7.62485
132.13600,-39.64080,-7.79348
132.33602,-39.70095,-7.97038
132.53602,-39.76092,-7.91747
132.73600,-39.82089,-7.80116
132.93600,-39.88091,-7.73425
133.13600,-39.94088,-7.87541
133.33602,-40.00073,-8.04913
133.53602,-40.06082,-8.21896
133.73600,-40.12085,-8.32287
133.93600,-40.18082,-8.36650
134.13600,-40.24079,-8.38693
134.33602,-40.30081,-8.41297
134.53602,-40.36090,-8.46154
134.73600,-40.42099,-8.50716
134.93600,-40.48084,-8.49244
135.13600,-40.54087,-8.40219
135.33602,-40.60084,-8.25583
135.53602,-40.66093,-8.09220
135.73600,-40.72084,-7.91668
135.93600,-40.78080,-7.84031
136.13600,-40.84083,-7.97864
136.33602,-40.90081,-8.14097
136.53602,-40.96077,-8.05119
136.73600,-41.02086,-7.88549
136.93600,-41.08083,-7.77301
137.13600,-41.14080,-7.87350
137.33602,-41.20071,-8.05868
137.53602,-41.26079,-8.23337
137.73600,-41.32076,-8.08767
137.93600,-41.38085,-7.90639
138.13600,-41.44088,-7.75001
138.33602,-41.50079,-7.80578
138.53602,-41.56088,-7.99241
138.73600,-41.62091,-8.17477
138.93600,-41.68088,-8.22972
139.13600,-41.74084,-8.04029
139.33602,-41.80076,-7.87391
139.53602,-41.86072,-7.95040
139.73600,-41.92069,-8.13262
139.93600,-41.98078,-8.31539
140.13600,-42.04093,-8.50411
140.33602,-42.10090,-8.59217
140.53602,-42.16093,-8.49334
140.73600,-42.22089,-8.28344
140.93600,-42.28081,-8.11092
141.13600,-42.34077,-7.92711
141.33602,-42.40080,-7.94419
141.53602,-42.46083,-8.13926
141.73600,-42.52080,-8.32410
141.93600,-42.58065,-8.51192
142.13600,-42.64092,-8.65131
142.33602,-42.70076,-8.79400
142.53602,-42.76085,-8.76306
142.73600,-42.82094,-8.55922
142.93600,-42.88085,-8.35550
143.13600,-42.94094,-8.21525
143.33602,-43.00085,-8.02234
143.53602,-43.06082,-7.84835
143.73600,-43.12085,-7.92865
143.93600,-43.18087,-8.12107
144.13600,-43.24091,-8.30212
144.33602,-43.30081,-8.17794
144.53602,-43.36084,-7.96166
144.73600,-43.42093,-7.88628
144.93600,-43.48096,-8.08588
145.13600,-43.54087,-8.27142
145.33602,-43.60077,-8.28177
145.53602,-43.66080,-8.06607
145.73600,-43.72095,-7.88088
145.93600,-43.78080,-7.76600
146.13600,-43.84089,-7.70052
146.33602,-43.90080,-7.88673
146.53602,-43.96089,-8.08771
146.71200,-44.01374,-8.04515
146.91200,-44.07365,-7.89490
147.11200,-44.13368,-7.85075
147.31202,-44.19353,-7.90836
147.51202,-44.25350,-7.95804
147.71200,-44.31353,-8.14269
147.91200,-44.37367,-8.33348
148.11200,-44.43365,-8.51791
148.25602,-44.47681,-8.27394
148.45602,-44.53690,-8.09407
148.65600,-44.59681,-7.90588
148.85600,-44.65684,-7.86643
149.05600,-44.71681,-8.01581
149.25602,-44.77690,-8.16626
149.45602,-44.83680,-8.02386
149.65600,-44.89689,-7.87124
149.85600,-44.95674,-7.69508
150.05600,-45.01689,-7.75606
150.25602,-45.07680,-7.94016
150.45602,-45.13683,-8.14228
150.65600,-45.19686,-8.25448
150.85600,-45.25683,-8.06345
151.05600,-45.31680,-8.05749
151.25602,-45.37676,-8.26451
151.45602,-45.43685,-8.46598
151.65600,-45.49682,-8.66013
151.85600,-45.55673,-8.78617
152.05600,-45.61682,-8.91098
152.25602,-45.67691,-9.01791
152.45602,-45.73687,-8.85929
152.59402,-45.77825,-8.66069
152.79400,-45.83828,-8.43449
152.99400,-45.89819,-8.34798
153.19400,-45.95822,-8.37015
153.39402,-46.01825,-8.49530
153.59402,-46.07822,-8.67127
153.79400,-46.13818,-8.60378
153.99400,-46.19815,-8.51334
154.19400,-46.25824,-8.34446
154.39402,-46.31833,-8.50184
154.59402,-46.37824,-8.70939
154.79400,-46.43821,-8.91740
154.99400,-46.49817,-9.11558
155.19400,-46.55820,-9.21652
155.39402,-46.61824,-9.14752
155.56602,-46.66978,-8.90792
155.76600,-46.72992,-8.71221
155.95202,-46.78571,-8.51794
156.15202,-46.84555,-8.67069
156.35200,-46.90558,-8.75289
156.55200,-46.96567,-8.91865
156.75202,-47.02564,-9.05957
156.95202,-47.08567,-8.89302
157.14602,-47.14384,-8.70490
157.34602,-47.20381,-8.76846
157.54600,-47.26390,-8.98810
157.74600,-47.32381,-9.19355
157.94602,-47.38383,-9.31478
158.14602,-47.44381,-9.42202
158.34602,-47.50377,-9.40590
158.54600,-47.56380,-9.28072
158.74600,-47.62383,-9.12642
158.94602,-47.68380,-9.21555
159.14602,-47.74383,-9.42116
159.34602,-47.80386,-9.55707
159.54600,-47.86371,-9.62199
159.74600,-47.92374,-9.70181
159.94602,-47.98376,-9.72839
160.14602,-48.04391,-9.81817
160.34602,-48.10382,-9.75407
160.54600,-48.16385,-9.56617
160.74600,-48.22382,-9.40042
160.94602,-48.28397,-9.57167
161.14602,-48.34388,-9.67338
161.34602,-48.40373,-9.55467
161.54600,-48.46381,-9.74596
161.74600,-48.52372,-9.92976
161.89002,-48.56695,-9.67820
162.06802,-48.62052,-9.47337
162.26800,-48.68049,-9.23671
162.46800,-48.74034,-9.04597
162.66802,-48.80049,-9.24389
162.86802,-48.86034,-9.43638
163.06802,-48.92048,-9.26168
163.25202,-48.97561,-9.02964
163.45202,-49.03558,-8.83741
163.65202,-49.09555,-8.67463
163.85200,-49.15558,-8.86123
164.05200,-49.21555,-9.08263
164.25202,-49.27563,-9.30927
164.45202,-49.33566,-9.44828
164.65202,-49.39570,-9.21547
164.85200,-49.45554,-9.01128
164.91600,-49.47486,-8.76027
165.11602,-49.53494,-8.78394
165.31602,-49.59491,-8.57651
165.51600,-49.65494,-8.41010
165.71600,-49.71479,-8.61804
165.91600,-49.77482,-8.83633
166.11602,-49.83479,-9.04243
166.31602,-49.89475,-9.25736
166.51600,-49.95479,-9.47057
166.71600,-50.01482,-9.68255
166.83602,-50.05081,-9.58431
167.03602,-50.11084,-9.40906
167.21400,-50.16429,-9.18257
167.41400,-50.22426,-9.02229
167.61402,-50.28422,-8.85191
167.81402,-50.34431,-8.82789
168.01400,-50.40416,-8.93963
168.21400,-50.46425,-8.88970
168.41400,-50.52422,-8.66392
168.61402,-50.58419,-8.55910
168.81402,-50.64422,-8.77477
169.01400,-50.70437,-8.99158
169.21400,-50.76422,-9.21693
169.41400,-50.82424,-9.43288
169.61402,-50.88421,-9.47285
169.77802,-50.93336,-9.24283
169.97802,-50.99339,-9.05765
170.17802,-51.05348,-8.90157
170.37800,-51.11345,-9.03758
170.57800,-51.17341,-9.26265
170.77802,-51.23338,-9.49506
170.91602,-51.27494,-9.47424
171.08200,-51.32468,-9.26117
171.26400,-51.37927,-9.02707
171.46400,-51.43918,-8.84922
171.66400,-51.49927,-8.66210
171.86402,-51.55918,-8.79872
172.06402,-51.61921,-9.02542
172.26400,-51.67923,-9.26407
172.40600,-51.72186,-9.23739
172.58602,-51.77591,-8.98175
172.75802,-51.82757,-8.77315
172.95800,-51.88742,-8.60058
173.14602,-51.94386,-8.36375
173.34602,-52.00383,-8.29433
173.54600,-52.06368,-8.45960
173.74600,-52.12383,-8.58818
173.94602,-52.18398,-8.41677
174.14602,-52.24389,-8.22834
174.34602,-52.30379,-8.23511
174.54600,-52.36382,-8.46457
174.74600,-52.42391,-8.67948
174.94602,-52.48382,-8.47123
175.14602,-52.54385,-8.25986
175.34602,-52.60376,-8.20351
175.54600,-52.66379,-8.39913
175.74600,-52.72388,-8.63565
175.90202,-52.77063,-8.62040
176.09602,-52.82875,-8.40730
176.29600,-52.88890,-8.21674
176.49600,-52.94892,-8.06727
176.69602,-53.00889,-8.25831
176.89602,-53.06892,-8.49293
177.09602,-53.12877,-8.53228
177.29600,-53.18874,-8.33094
177.49600,-53.24871,-8.27670
177.69602,-53.30886,-8.50756
177.89602,-53.36889,-8.74028
178.09602,-53.42891,-8.96220
178.29600,-53.48877,-8.91418
178.48402,-53.54526,-8.66222
178.68400,-53.60524,-8.47277
178.88400,-53.66526,-8.34482
179.08402,-53.72523,-8.57511
179.28202,-53.78454,-8.55635
179.48202,-53.84457,-8.36526
179.68200,-53.90466,-8.16933
179.88200,-53.96469,-8.34096
180.08202,-54.02460,-8.56254
180.28202,-54.08457,-8.78309
180.41602,-54.12475,-8.61433
180.61602,-54.18484,-8.37741
180.81602,-54.24492,-8.21904
181.01600,-54.30489,-8.36215
181.21600,-54.36492,-8.45166
181.41602,-54.42495,-8.36809
181.61602,-54.48492,-8.39216
181.81602,-54.54470,-8.63580
182.01600,-54.60479,-8.80867
182.16000,-54.64814,-8.56189
182.36002,-54.70793,-8.37012
182.56002,-54.76802,-8.26977
182.76002,-54.82817,-8.47281
182.94000,-54.88204,-8.27843
183.14002,-54.94195,-8.13942
183.34002,-55.00198,-8.30626
183.54002,-55.06207,-8.53202
183.74000,-55.12203,-8.55124
183.94000,-55.18206,-8.40331
184.14002,-55.24197,-8.56854
184.29200,-55.28765,-8.51734
184.49200,-55.34762,-8.31511
184.69000,-55.40699,-8.08299
184.89002,-55.46702,-8.30386
185.09002,-55.52711,-8.52470
185.29002,-55.58707,-8.59516
185.49000,-55.64698,-8.60389
185.69000,-55.70701,-8.45202
185.89002,-55.76704,-8.48297
186.09002,-55.82701,-8.52214
186.28602,-55.88579,-8.29773
186.48600,-55.94581,-8.38579
186.68600,-56.00572,-8.54840
186.88600,-56.06569,-8.76215
187.08000,-56.12411,-9.00556
187.28002,-56.18407,-9.11166
187.43200,-56.22969,-8.86411
187.63200,-56.28960,-8.77337
187.83202,-56.34969,-8.91541
188.01202,-56.40368,-8.65739
188.21200,-56.46359,-8.50710
188.41200,-56.52368,-8.43849
188.61202,-56.58364,-8.61742
188.81202,-56.64362,-8.49909
189.01202,-56.70364,-8.57649
189.21200,-56.76356,-8.43569
189.41200,-56.82365,-8.65457
189.61202,-56.88361,-8.87174
189.81202,-56.94370,-9.05622
190.01202,-57.00367,-8.86412
190.21200,-57.06364,-8.61682
190.28602,-57.08582,-8.35433
190.29800,-57.08941,-8.06396
190.31002,-57.09305,-7.72929
190.41602,-57.12474,-7.54661
190.61602,-57.18483,-7.66694
190.81602,-57.24486,-7.79776
191.01600,-57.30489,-7.91548
191.21600,-57.36480,-8.05992
191.41602,-57.42483,-8.19900
191.61602,-57.48485,-8.34184
191.81602,-57.54488,-8.49194
192.01600,-57.60479,-8.64369
192.21600,-57.66488,-8.75347
192.41602,-57.72485,-8.89732
192.60200,-57.78064,-8.82817
192.76800,-57.83050,-8.61796
192.96800,-57.89053,-8.49808
193.16802,-57.95038,-8.67465
193.36802,-58.01047,-8.83207
193.56802,-58.07049,-8.73252
193.76800,-58.13040,-8.69603
193.96800,-58.19043,-8.87436
194.16802,-58.25040,-8.88020
194.33802,-58.30140,-8.62466
194.53802,-58.36149,-8.40716
194.73800,-58.42140,-8.51213
194.93800,-58.48142,-8.68288
195.13802,-58.54140,-8.86647
195.33802,-58.60136,-8.98587
195.49000,-58.64698,-8.73068
195.67402,-58.70235,-8.51238
195.87402,-58.76219,-8.31712
196.07400,-58.82217,-8.39897
196.27400,-58.88219,-8.58839
196.47402,-58.94216,-8.70834
196.67002,-59.00106,-8.47996
196.87002,-59.06115,-8.27771
197.07000,-59.12105,-8.24206
197.19000,-59.15699,-7.98497
197.23002,-59.16894,-7.72810
197.25802,-59.17743,-7.45969
197.29800,-59.18945,-7.19557
197.34202,-59.20261,-6.93458
197.37402,-59.21223,-6.66822
197.40600,-59.22192,-6.41354
197.46000,-59.23800,-6.15273
197.57400,-59.27214,-5.95669