File: data/ThreePoint Raw/Fiber50-35_2.is_comp_RawData/Raw50-35-2.csv
Time,Extension,Load
(sec),(mm),(N)
0.00000,0.00000,-0.10288
0.10000,-0.01614,0.06105
0.20000,-0.05058,0.07344
0.30000,-0.08532,0.04693
0.40000,-0.11808,0.04720
0.50000,-0.14923,0.00234
0.60000,-0.17985,0.01718
0.70000,-0.21004,-0.00834
0.80000,-0.24005,0.03942
0.90000,-0.27019,0.01127
1.00000,-0.30008,0.05597
1.10000,-0.33016,0.02078
1.20000,-0.36017,0.02629
1.30000,-0.39001,0.01450
1.40000,-0.42014,0.00001
1.50000,-0.45004,0.00174
1.60000,-0.47999,0.08319
1.70000,-0.50994,0.01588
1.80000,-0.53996,0.01044
1.90000,-0.56997,0.03758
2.00000,-0.59999,0.00852
2.10000,-0.63000,0.04656
2.20000,-0.66002,-0.00104
2.30000,-0.68991,-0.00285
2.40000,-0.72004,-0.01539
2.50000,-0.74994,0.03414
2.60000,-0.78007,0.06937
2.70000,-0.80997,0.00034
2.80000,-0.84004,0.02475
2.90000,-0.86994,-0.00524
3.00000,-0.89989,-0.28751
3.10000,-0.92991,-1.75062
3.20000,-0.95992,-3.44406
3.30000,-0.98988,-5.11755
3.40000,-1.02001,-6.89015
3.50000,-1.04996,-8.61095
3.60000,-1.08004,-10.27233
3.70000,-1.10999,-11.79602
3.80000,-1.14007,-13.07413
3.90000,-1.17002,-14.81448
4.00000,-1.20004,-16.76227
4.10000,-1.23005,-18.72798
4.20000,-1.26006,-21.07803
4.30000,-1.29002,-23.37841
4.40000,-1.31997,-25.33725
4.50000,-1.34999,-26.22947
4.60000,-1.37994,-27.45083
4.70000,-1.40996,-28.67413
4.80000,-1.43991,-31.03128
4.90000,-1.46998,-32.78361
5.00000,-1.50000,-34.42860
5.10000,-1.53001,-36.43427
5.20000,-1.55997,-38.57177
5.30000,-1.58998,-40.73835
5.40000,-1.62000,-42.99718
5.50000,-1.65007,-45.34259
5.60000,-1.68008,-47.70666
5.70000,-1.71004,-50.07138
5.80000,-1.73999,-52.53122
5.90000,-1.77007,-54.94461
6.00000,-1.79996,-57.40658
6.10000,-1.82998,-59.84525
6.20000,-1.85999,-62.29816
6.30000,-1.88995,-64.68582
6.40000,-1.91984,-67.11491
6.50000,-1.94997,-69.64152
6.60000,-1.97999,-72.04479
6.70000,-2.00994,-74.53265
6.80000,-2.03996,-76.99941
6.90000,-2.06997,-79.49401
7.00000,-2.09999,-81.98346
7.10000,-2.13000,-84.38746
7.20000,-2.15996,-86.92034
7.30000,-2.19003,-89.37814
7.40000,-2.22004,-91.86117
7.50000,-2.25012,-94.35145
7.60000,-2.27995,-96.76837
7.70000,-2.31003,-99.29899
7.80000,-2.34010,-101.76147
7.90000,-2.36994,-104.20091
8.00000,-2.40007,-106.69918
8.10000,-2.43008,-109.16014
8.20000,-2.46004,-111.65502
8.30000,-2.49005,-114.12109
8.40000,-2.51995,-116.59654
8.50000,-2.55002,-119.06439
8.60000,-2.57992,-121.54835
8.70000,-2.60993,-124.03744
8.80000,-2.64001,-126.46358
8.90000,-2.66990,-128.93536
9.00000,-2.69997,-131.41958
9.10000,-2.72999,-133.95593
9.20000,-2.76000,-136.45785
9.30000,-2.79002,-138.91092
9.40000,-2.81997,-141.41210
9.50000,-2.84999,-143.91579
9.60000,-2.87994,-146.37006
9.70000,-2.91001,-148.85186
9.80000,-2.93991,-151.37026
9.90000,-2.97004,-153.86142
10.00000,-2.99994,-156.33645
10.10000,-3.03001,-158.74159
10.20000,-3.05997,-161.20052
10.30000,-3.08998,-163.69594
10.40000,-3.11994,-166.14662
10.50000,-3.15001,-168.62614
10.60000,-3.17996,-171.09048
10.70000,-3.21004,-173.62164
10.80000,-3.24011,-176.02619
10.90000,-3.27007,-178.49116
11.00000,-3.30008,-180.92319
11.10000,-3.32998,-183.51933
11.20000,-3.35999,-186.04131
11.30000,-3.38989,-188.43265
11.40000,-3.41990,-190.84616
11.50000,-3.44991,-193.38895
11.60000,-3.47999,-195.75886
11.70000,-3.51006,-198.25991
11.80000,-3.54002,-200.76305
11.90000,-3.57003,-203.17888
12.00000,-3.59999,-205.65579
12.10000,-3.63012,-208.09190
12.20000,-3.65989,-210.49690
12.30000,-3.68991,-212.92603
12.40000,-3.71998,-215.40985
12.50000,-3.75000,-217.83276
12.60000,-3.78007,-220.21629
12.70000,-3.80997,-222.61385
12.80000,-3.84004,-225.06393
12.90000,-3.86999,-227.47885
13.00000,-3.90007,-229.90242
13.10000,-3.93008,-232.36139
13.20000,-3.96010,-234.78512
13.30000,-3.98999,-237.22932
13.40000,-4.02013,-239.66946
13.50000,-4.04996,-242.06894
13.60000,-4.08004,-244.44181
13.70000,-4.10999,-246.89861
13.80000,-4.14012,-249.30703
13.90000,-4.17008,-251.65642
14.00000,-4.20009,-254.04545
14.10000,-4.23005,-256.50987
14.20000,-4.25994,-258.90283
14.30000,-4.28990,-261.21350
14.40000,-4.31997,-263.63565
14.50000,-4.34999,-265.98504
14.60000,-4.37988,-268.39940
14.70000,-4.41001,-270.75633
14.80000,-4.44003,-273.14937
14.90000,-4.46992,-275.46417
15.00000,-4.49994,-277.90921
15.10000,-4.53001,-280.20099
15.20000,-4.55997,-282.55599
15.30000,-4.59004,-284.88008
15.40000,-4.61999,-287.28997
15.50000,-4.64995,-289.62787
15.60000,-4.68002,-291.94284
15.70000,-4.70998,-294.29251
15.80000,-4.73999,-296.54818
15.90000,-4.76995,-298.93005
16.00000,-4.80002,-301.25054
16.10000,-4.82998,-303.53416
16.20000,-4.86005,-305.94613
16.30000,-4.88994,-308.22573
16.40000,-4.91996,-310.54927
16.50000,-4.95003,-312.86880
16.60000,-4.97999,-315.17845
16.70000,-5.01000,-317.50619
16.80000,-5.04002,-319.72326
16.90000,-5.07009,-322.12991
17.00000,-5.10004,-324.37585
17.10000,-5.13012,-326.64843
17.20000,-5.16007,-328.98013
17.30000,-5.19009,-331.29308
17.40000,-5.21998,-333.61927
17.50000,-5.25006,-335.87594
17.60000,-5.28001,-338.12050
17.70000,-5.31003,-340.43651
17.80000,-5.34004,-342.68454
17.90000,-5.36999,-344.99399
18.00000,-5.39995,-347.23163
18.10000,-5.42996,-349.52883
18.20000,-5.45998,-351.73450
18.30000,-5.49011,-354.01117
18.40000,-5.52001,-356.37733
18.50000,-5.55014,-358.60024
18.60000,-5.57992,-360.89770
18.70000,-5.60999,-363.13277
18.80000,-5.64000,-365.36831
18.90000,-5.66990,-367.66261
19.00000,-5.69997,-369.94219
19.10000,-5.72999,-372.18645
19.20000,-5.75994,-374.42546
19.30000,-5.79008,-376.73298
19.40000,-5.81997,-378.95925
19.50000,-5.85004,-381.21149
19.60000,-5.87994,-383.48477
19.70000,-5.90995,-385.75638
19.80000,-5.94003,-387.92241
19.90000,-5.96986,-390.19402
20.00000,-6.00006,-392.46269
20.10000,-6.02995,-394.69525
20.20000,-6.06002,-396.96418
20.30000,-6.08998,-399.18326
20.40000,-6.12005,-401.43851
20.50000,-6.15001,-403.67253
20.60000,-6.17990,-405.89422
20.70000,-6.21004,-408.11561
20.80000,-6.23993,-410.35715
20.90000,-6.26995,-412.62027
21.00000,-6.29996,-414.82434
21.10000,-6.32997,-417.07635
21.20000,-6.36005,-419.26872
21.30000,-6.39000,-421.48430
21.40000,-6.41996,-423.74071
21.50000,-6.45003,-425.94187
21.60000,-6.47999,-428.15931
21.70000,-6.51000,-430.34494
21.80000,-6.53995,-432.50203
21.90000,-6.57003,-434.79197
22.00000,-6.59992,-437.01269
22.10000,-6.63006,-439.18967
22.20000,-6.65995,-441.36174
22.30000,-6.68997,-443.56994
22.40000,-6.71998,-445.77207
22.50000,-6.74994,-447.93781
22.60000,-6.77995,-450.13316
22.70000,-6.80996,-452.23847
22.80000,-6.83998,-454.50252
22.90000,-6.86993,-456.62835
23.00000,-6.89995,-458.76957
23.10000,-6.92996,-460.94112
23.20000,-6.95992,-463.09762
23.30000,-6.98993,-465.27270
23.40000,-7.02006,-467.48947
23.50000,-7.04996,-469.54531
23.60000,-7.08003,-471.72755
23.70000,-7.10999,-473.82567
23.80000,-7.14000,-475.94998
23.90000,-7.16996,-478.00831
24.00000,-7.19985,-480.21238
24.10000,-7.22993,-482.25034
24.20000,-7.25994,-484.36079
24.30000,-7.28995,-486.46778
24.40000,-7.32003,-488.57413
24.50000,-7.34992,-490.62382
24.60000,-7.38000,-492.70242
24.70000,-7.40995,-494.72842
24.80000,-7.43991,-496.89315
24.90000,-7.46992,-498.98077
25.00000,-7.50011,-501.03519
25.10000,-7.53001,-503.01321
25.20000,-7.56002,-505.08257
25.30000,-7.58998,-507.09631
25.40000,-7.61999,-509.21179
25.50000,-7.64995,-511.22535
25.60000,-7.68008,-513.22877
25.70000,-7.70998,-515.23611
25.80000,-7.74005,-517.26568
25.90000,-7.76994,-519.32167
26.00000,-7.80002,-521.27756
26.10000,-7.82997,-523.29555
26.20000,-7.86005,-525.33038
26.30000,-7.89012,-527.32740
26.40000,-7.92014,-529.36289
26.50000,-7.94997,-531.31383
26.60000,-7.97987,-533.22606
26.70000,-8.01000,-535.21279
26.80000,-8.03995,-537.16451
26.90000,-8.06991,-539.09406
27.00000,-8.09998,-541.09987
27.10000,-8.13000,-543.08295
27.20000,-8.15989,-544.95338
27.30000,-8.19003,-546.95856
27.40000,-8.22004,-548.86822
27.50000,-8.25011,-550.82202
27.60000,-8.28007,-552.75340
27.70000,-8.31002,-554.60434
27.80000,-8.34010,-556.54626
27.90000,-8.37005,-558.51061
28.00000,-8.40007,-560.44802
28.10000,-8.42996,-562.33890
28.20000,-8.46004,-564.21414
28.30000,-8.48999,-566.08491
28.40000,-8.52000,-568.00086
28.50000,-8.55008,-569.88530
28.60000,-8.58003,-571.78870
28.70000,-8.61005,-573.60198
28.80000,-8.64006,-575.48590
28.90000,-8.66996,-577.36006
29.00000,-8.69997,-579.22535
29.10000,-8.73004,-581.10949
29.20000,-8.75994,-582.95015
29.30000,-8.79007,-584.78136
29.40000,-8.82003,-586.59591
29.50000,-8.85010,-588.45121
29.60000,-8.88000,-590.30306
29.70000,-8.91013,-592.12413
29.80000,-8.94002,-593.89692
29.90000,-8.97004,-595.73077
30.00000,-9.00005,-597.53481
30.10000,-9.03001,-599.28533
30.20000,-9.05990,-601.13408
30.30000,-9.08998,-602.41133
30.40000,-9.11999,-603.96951
30.50000,-9.15001,-605.38910
30.60000,-9.18008,-606.46966
30.70000,-9.21015,-606.70156
30.80000,-9.24005,-607.19624
30.90000,-9.27000,-606.42093
31.00000,-9.30002,-607.78875
31.10000,-9.32997,-609.04380
31.20000,-9.35993,-610.31580
31.30000,-9.39006,-611.61660
31.40000,-9.41996,-612.66359
31.50000,-9.45003,-614.05927
31.60000,-9.47998,-615.19772
31.70000,-9.51006,-616.58580
31.80000,-9.54001,-618.03464
31.90000,-9.56997,-619.50959
32.00000,-9.59998,-620.22969
32.10000,-9.63000,-620.74997
32.20000,-9.66007,-621.45967
32.30000,-9.69002,-622.43290
32.40000,-9.71998,-623.26223
32.50000,-9.74993,-623.85026
32.60000,-9.77995,-624.01321
32.70000,-9.81002,-624.33530
32.80000,-9.84004,-624.75778
32.90000,-9.87005,-625.60372
33.00000,-9.90012,-626.66297
33.10000,-9.93002,-627.36981
33.20000,-9.96003,-627.15515
33.30000,-9.98999,-627.56114
33.40000,-10.02000,-628.02210
33.50000,-10.05002,-628.83399
33.60000,-10.07997,-629.85264
33.70000,-10.11005,-630.04471
33.80000,-10.14000,-630.85333
33.90000,-10.17001,-631.33255
34.00000,-10.19997,-632.19123
34.10000,-10.22998,-631.92070
34.20000,-10.26006,-630.40957
34.30000,-10.28995,-626.77324
34.40000,-10.32003,-624.04703
34.50000,-10.34992,-622.59223
34.60000,-10.37994,-619.94445
34.70000,-10.40995,-618.49516
34.80000,-10.43997,-617.42179
34.90000,-10.46998,-616.58647
35.00000,-10.50005,-614.11265
35.10000,-10.52995,-610.49253
35.20000,-10.55996,-606.15383
35.30000,-10.58992,-603.80317
35.40000,-10.61999,-602.06175
35.50000,-10.64989,-600.72675
35.60000,-10.67996,-599.78630
35.70000,-10.71003,-598.84496
35.80000,-10.73987,-597.68826
35.90000,-10.77006,-596.71700
36.00000,-10.79996,-594.03103
36.10000,-10.83003,-590.84330
36.20000,-10.86005,-586.23735
36.30000,-10.88994,-580.41669
36.40000,-10.92007,-574.52466
36.50000,-10.94997,-569.38954
36.60000,-10.98010,-565.78822
36.70000,-11.01000,-563.30003
36.80000,-11.04001,-560.90310
36.90000,-11.06997,-558.91782
37.00000,-11.09998,-557.20925
37.10000,-11.12994,-555.66642
37.20000,-11.16007,-554.28986
37.30000,-11.19002,-553.01994
37.40000,-11.22004,-551.88838
37.50000,-11.24993,-550.70229
37.60000,-11.28001,-549.48647
37.70000,-11.30996,-548.16671
37.80000,-11.33998,-546.83123
37.90000,-11.36999,-545.67408
38.00000,-11.40006,-544.65227
38.10000,-11.43002,-543.52429
38.20000,-11.46003,-542.55113
38.30000,-11.48999,-541.54970
38.40000,-11.52006,-540.53497
38.50000,-11.55008,-539.53733
38.60000,-11.58003,-538.62795
38.70000,-11.61005,-537.80410
38.80000,-11.64000,-537.03930
38.90000,-11.67001,-536.22987
39.00000,-11.69997,-535.45818
39.10000,-11.72998,-534.78915
39.20000,-11.76006,-534.13317
39.30000,-11.79001,-533.60969
39.40000,-11.82003,-533.02661
39.50000,-11.84998,-532.47426
39.60000,-11.88005,-531.82784
39.70000,-11.91001,-531.33763
39.80000,-11.93996,-530.55771
39.90000,-11.96998,-529.99645
40.00000,-12.00005,-529.49585
40.10000,-12.02995,-528.99927
40.20000,-12.06002,-528.49419
40.30000,-12.09010,-528.02909
40.40000,-12.12005,-527.62013
40.50000,-12.15006,-527.04100
40.60000,-12.18008,-526.62421
40.70000,-12.21009,-526.13351
40.80000,-12.23999,-525.68138
40.90000,-12.27006,-525.24202
41.00000,-12.30008,-524.79893
41.10000,-12.32997,-524.42245
41.20000,-12.35986,-523.95161
41.30000,-12.39006,-523.67914
41.40000,-12.41989,-523.24589
41.50000,-12.44997,-522.84725
41.60000,-12.47998,-522.36643
41.70000,-12.51006,-521.50983
41.80000,-12.53995,-520.63081
41.90000,-12.57002,-519.84798
42.00000,-12.59998,-519.16763
42.10000,-12.62999,-518.51638
42.20000,-12.65995,-517.83781
42.30000,-12.69008,-517.19237
42.40000,-12.72004,-516.58921
42.50000,-12.75005,-515.97398
42.60000,-12.78007,-515.41518
42.70000,-12.80996,-514.90653
42.80000,-12.84003,-514.36115
42.90000,-12.86999,-513.85518
43.00000,-12.89994,-513.34195
43.10000,-12.92996,-512.88866
43.20000,-12.96003,-512.42817
43.30000,-12.98999,-511.98114
43.40000,-13.01994,-511.57258
43.50000,-13.05007,-511.10525
43.60000,-13.07997,-510.68161
43.70000,-13.11004,-510.26423
43.80000,-13.13994,-509.82982
43.90000,-13.16995,-509.42682
44.00000,-13.19991,-509.10562
44.10000,-13.22998,-508.65669
44.20000,-13.25994,-508.30252
44.30000,-13.28995,-507.94236
44.40000,-13.31996,-507.57937
44.50000,-13.34998,-507.09199
44.60000,-13.38005,-506.67025
44.70000,-13.41001,-506.28189
44.80000,-13.44002,-505.94855
44.90000,-13.47004,-505.60065
45.00000,-13.50005,-505.23728
45.10000,-13.53001,-504.89228
45.20000,-13.56002,-504.57690
45.30000,-13.59003,-504.30670
45.40000,-13.62011,-504.06907
45.50000,-13.65000,-503.79951
45.60000,-13.68008,-503.49157
45.70000,-13.70997,-503.22630
45.80000,-13.73999,-502.85053
45.90000,-13.77000,-502.48761
46.00000,-13.79995,-502.16127
46.10000,-13.83003,-501.89458
46.20000,-13.86004,-501.56519
46.30000,-13.89000,-501.25528
46.40000,-13.92007,-500.99507
46.50000,-13.95003,-500.53347
46.60000,-13.98010,-500.08234
46.70000,-14.01005,-499.65508
46.80000,-14.04001,-499.20417
46.90000,-14.07008,-498.81008
47.00000,-14.09992,-498.40108
47.10000,-14.12993,-497.94152
47.20000,-14.16001,-497.52522
47.30000,-14.18990,-497.09264
47.40000,-14.22003,-496.71948
47.50000,-14.24999,-496.37888
47.60000,-14.27989,-496.03693
47.70000,-14.30984,-495.67994
47.80000,-14.33991,-495.33695
47.90000,-14.37005,-495.16585
48.00000,-14.39994,-494.87714
48.10000,-14.43002,-494.59528
48.20000,-14.46003,-494.27006
48.30000,-14.49005,-494.11990
48.40000,-14.52000,-493.91884
48.50000,-14.55001,-493.67253
48.60000,-14.58015,-493.46469
48.70000,-14.61004,-493.30313
48.80000,-14.64006,-493.15881
48.90000,-14.67007,-493.05510
49.00000,-14.70003,-492.95641
49.10000,-14.73004,-492.85639
49.20000,-14.75999,-492.78535
49.30000,-14.78995,-492.65716
49.40000,-14.82008,-492.60244
49.50000,-14.84992,-492.47686
49.60000,-14.87999,-492.35880
49.70000,-14.90995,-492.32572
49.80000,-14.94008,-492.27547
49.90000,-14.96998,-492.21296
50.00000,-14.99999,-492.16133
50.10000,-15.02994,-492.01880
50.20000,-15.05990,-491.97078
50.30000,-15.08991,-491.92235
50.40000,-15.11993,-491.75300
50.50000,-15.15006,-491.70911
50.60000,-15.18002,-491.61155
50.70000,-15.21009,-491.50728
50.80000,-15.24005,-491.53637
50.90000,-15.27006,-491.53876
51.00000,-15.30001,-491.48738
51.10000,-15.33003,-491.42163
51.20000,-15.36004,-491.38069
51.30000,-15.39000,-491.28879
51.40000,-15.42001,-491.16209
51.50000,-15.45003,-491.09854
51.60000,-15.47998,-491.01327
51.70000,-15.50999,-490.91626
51.80000,-15.54007,-490.82562
51.90000,-15.57002,-490.72564
52.00000,-15.60004,-490.68950
52.10000,-15.62993,-490.67196
52.20000,-15.65989,-490.58359
52.30000,-15.68990,-490.62494
52.40000,-15.71986,-490.61496
52.50000,-15.74999,-490.55398
52.60000,-15.78000,-490.48610
52.70000,-15.81002,-490.42955
52.80000,-15.84009,-490.43987
52.90000,-15.87011,-490.43726
53.00000,-15.90006,-490.45220
53.10000,-15.93007,-490.52011
53.20000,-15.95997,-490.51099
53.30000,-15.99004,-490.54746
53.40000,-16.01994,-490.54094
53.50000,-16.05001,-490.57767
53.60000,-16.07997,-490.55371
53.70000,-16.10998,-490.53594
53.80000,-16.14000,-490.56467
53.90000,-16.16995,-490.62476
54.00000,-16.19997,-490.65247
54.10000,-16.22998,-490.75417
54.20000,-16.25993,-490.83684
54.30000,-16.29007,-490.89618
54.40000,-16.31996,-490.95839
54.50000,-16.35004,-490.92386
54.60000,-16.37999,-490.97881
54.70000,-16.41001,-491.02221
54.80000,-16.44008,-491.02828
54.90000,-16.47010,-491.08844
55.00000,-16.50011,-491.15099
55.10000,-16.53000,-491.25701
55.20000,-16.55996,-491.37577
55.30000,-16.59003,-491.47673
55.40000,-16.61993,-491.54114
55.50000,-16.65000,-491.59635
55.60000,-16.67995,-491.63219
55.70000,-16.71003,-491.67607
55.80000,-16.74004,-491.83890
55.90000,-16.77006,-491.86997
56.00000,-16.80001,-492.01142
56.10000,-16.83009,-492.16263
56.20000,-16.86004,-492.27066
56.30000,-16.89000,-492.42496
56.40000,-16.92007,-492.58418
56.50000,-16.95002,-492.76419
56.60000,-16.97998,-492.86641
56.70000,-17.00993,-493.06866
56.80000,-17.03995,-493.23529
56.90000,-17.07002,-493.37510
57.00000,-17.10004,-493.60726
57.10000,-17.12999,-493.73250
57.20000,-17.16007,-493.84467
57.30000,-17.19002,-494.04085
57.40000,-17.22003,-494.13431
57.50000,-17.24999,-494.24883
57.60000,-17.28000,-494.01887
57.70000,-17.30996,-494.03086
57.80000,-17.33997,-494.12675
57.90000,-17.36999,-494.21988
58.00000,-17.40000,-494.40071
58.10000,-17.43001,-494.47734
58.20000,-17.46009,-494.63343
58.30000,-17.49004,-494.77879
58.40000,-17.52006,-494.88734
58.50000,-17.55007,-495.02775
58.60000,-17.58009,-495.17728
58.70000,-17.61004,-495.30271
58.80000,-17.64006,-495.43373
58.90000,-17.67007,-495.59094
59.00000,-17.69996,-495.70050
59.10000,-17.72998,-495.91407
59.20000,-17.76005,-496.08730
59.30000,-17.79001,-496.26809
59.40000,-17.82008,-496.40786
59.50000,-17.84998,-496.47931
59.60000,-17.88005,-496.47816
59.70000,-17.90995,-496.33596
59.80000,-17.93996,-496.31853
59.90000,-17.96997,-494.72585
59.96000,-17.98797,-482.19189
59.98200,-17.99455,-468.77597
60.00800,-18.00244,-453.31914
60.01600,-18.00483,-436.12693
60.02200,-18.00656,-419.96561
60.02800,-18.00836,-403.17915
60.03200,-18.00949,-390.63897
60.03600,-18.01069,-375.40324
60.04000,-18.01195,-358.98615
60.04400,-18.01320,-342.52807
60.04800,-18.01440,-326.92276
60.05200,-18.01553,-312.66894
60.05600,-18.01673,-299.87266
60.06200,-18.01852,-283.61347
60.06800,-18.02032,-271.05173
60.07800,-18.02337,-257.24303
60.10200,-18.03060,-244.62441
60.12400,-18.03718,-231.46475
60.13600,-18.04076,-218.08356
60.14200,-18.04256,-203.24619
60.14600,-18.04370,-190.36083
60.15000,-18.04495,-176.35606
60.15400,-18.04615,-162.30304
60.15800,-18.04734,-148.81404
60.16200,-18.04860,-136.10562
60.16800,-18.05039,-118.80867
60.17400,-18.05218,-103.74042
60.18000,-18.05398,-87.70325
60.18600,-18.05577,-71.17840
60.19200,-18.05757,-56.07429
60.20000,-18.05996,-40.28212
60.21000,-18.06295,-27.39465
60.31000,-18.09302,-21.19127
60.41000,-18.12297,-19.87618
60.51000,-18.15299,-19.51796
60.61000,-18.18300,-19.49944
60.71000,-18.21314,-19.31585
60.81000,-18.24291,-19.27253
60.91000,-18.27293,-19.32147
61.01000,-18.30288,-19.22847
61.11000,-18.33296,-19.22452
61.21000,-18.36291,-19.13303
61.31000,-18.39310,-18.97090
61.41000,-18.42300,-18.86798
61.51000,-18.45307,-18.84100
61.61000,-18.48297,-18.75702
61.71000,-18.51298,-18.74367
61.81000,-18.54300,-18.73835
61.91000,-18.57301,-18.72351
62.01000,-18.60296,-18.55794
62.11000,-18.63304,-18.53811
62.21000,-18.66299,-18.40772
62.31000,-18.69313,-18.37906
62.41000,-18.72296,-18.30132
62.51000,-18.75304,-18.25262
62.61000,-18.78305,-18.13126
62.71000,-18.81301,-18.06200
62.81000,-18.84302,-17.83821
62.91000,-18.87303,-17.69365
63.01000,-18.90299,-17.56541
63.11000,-18.93306,-16.29246
63.21000,-18.96296,-16.21303
63.31000,-18.99297,-16.19597
63.41000,-19.02293,-16.14301
63.51000,-19.05306,-16.05393
63.61000,-19.08301,-16.04675
63.71000,-19.11297,-15.92574
63.81000,-19.14304,-15.86492
63.91000,-19.17300,-15.81285
64.01000,-19.20301,-15.81720
64.11000,-19.23291,-15.84019
64.21001,-19.26298,-15.79040
64.31000,-19.29306,-15.82157
64.41000,-19.32307,-15.75629
64.51000,-19.35302,-15.72851
64.61000,-19.38304,-15.70355
64.71001,-19.41305,-15.66438
64.81000,-19.44295,-15.62056
64.91000,-19.47296,-15.60570
65.01000,-19.50298,-15.64873
65.11000,-19.53299,-15.62260
65.21001,-19.56301,-15.62294
65.31000,-19.59296,-15.58507
65.41000,-19.62303,-15.63855
65.51000,-19.65305,-15.63990
65.61000,-19.68306,-15.62314
65.71001,-19.71302,-15.63409
65.81001,-19.74303,-15.63240
65.91000,-19.77304,-15.61725
66.01000,-19.80300,-15.62138
66.11000,-19.83296,-15.60609
66.21001,-19.86303,-15.62380
66.31001,-19.89298,-15.61026
66.41000,-19.92306,-15.58689
66.51000,-19.95295,-15.58122
66.61000,-19.98309,-15.59147
66.71001,-20.01298,-15.50523
66.81001,-20.04300,-15.55472
66.91000,-20.07301,-15.52372
67.01000,-20.10297,-15.53972
67.11000,-20.13304,-15.52729
67.16600,-20.14990,-15.50199