File: data/crush/Crush50-25.is_comp_RawData/Core50-25.csv
Time,Extension,Load
(sec),(mm),(N)
0.00000,-0.00006,6.17971
0.10000,-0.00108,7.32732
0.20000,-0.00478,7.64928
0.30000,-0.00909,7.67866
0.40000,-0.01279,7.17614
0.50000,-0.01644,7.13227
0.60000,-0.01985,6.74411
0.70000,-0.02320,7.41467
0.80000,-0.02661,7.58426
0.90000,-0.03007,7.00811
1.00000,-0.03336,6.92468
1.10000,-0.03671,7.30931
1.20000,-0.04006,6.52947
1.30000,-0.04323,7.59641
1.40000,-0.04664,6.61917
1.50000,-0.05004,6.60076
1.60000,-0.05327,7.04688
1.70000,-0.05668,7.21178
1.80000,-0.06009,6.96110
1.90000,-0.06326,6.50793
2.00000,-0.06661,7.19337
2.10000,-0.07001,7.21256
2.20000,-0.07324,6.72727
2.30000,-0.07665,6.95954
2.40000,-0.08012,6.61799
2.50000,-0.08335,7.50358
2.60000,-0.08663,6.69594
2.70000,-0.09004,5.95175
2.80000,-0.09333,6.95366
2.90000,-0.09656,6.02970
3.00000,-0.10009,6.42255
3.10000,-0.10338,6.51616
3.20000,-0.10660,6.55650
3.30000,-0.11001,6.17266
3.40000,-0.11336,6.32580
3.50000,-0.11653,6.43234
3.60000,-0.12000,6.25648
3.70000,-0.12341,6.32698
3.80000,-0.12663,6.07748
3.90000,-0.13004,5.51973
4.00000,-0.13339,5.84835
4.10000,-0.13656,5.47547
4.20000,-0.14003,5.83581
4.30000,-0.14344,5.58553
4.40000,-0.14666,6.13271
4.50000,-0.15007,5.46294
4.60000,-0.15348,5.14842
4.70000,-0.15665,6.16717
4.80000,-0.15994,5.24477
4.90000,-0.16334,5.75905
5.00000,-0.16663,5.12100
5.10000,-0.16992,5.37599
5.20000,-0.17339,4.69447
5.30000,-0.17674,4.93535
5.40000,-0.17991,4.13241
5.50000,-0.18325,4.82803
5.60000,-0.18666,5.02778
5.70000,-0.18989,4.32864
5.80000,-0.19330,3.16144
5.90000,-0.19683,3.31106
6.00000,-0.19994,2.57666
6.10000,-0.20334,2.82068
6.20000,-0.20675,1.53049
6.30000,-0.20998,0.72912
6.40000,-0.21333,-0.59671
6.50000,-0.21674,-1.74942
6.60000,-0.22003,-3.47358
6.70000,-0.22337,-6.43741
6.80000,-0.22672,-9.46351
6.90000,-0.22995,-13.06303
7.00000,-0.23324,-17.84815
7.10000,-0.23665,-23.16283
7.20000,-0.23994,-29.75829
7.30000,-0.24334,-35.73020
7.40000,-0.24669,-43.51832
7.50000,-0.25010,-51.34992
7.60000,-0.25327,-56.96031
7.70000,-0.25668,-68.84264
7.80000,-0.26002,-83.54191
7.90000,-0.26325,-98.42723
8.00000,-0.26666,-118.15603
8.10000,-0.27007,-139.33954
8.20000,-0.27324,-162.00984
8.30000,-0.27665,-188.87423
8.40000,-0.27999,-219.66873
8.50000,-0.28322,-249.94072
8.60000,-0.28663,-283.68805
8.70000,-0.29004,-322.63414
8.80000,-0.29327,-359.33552
8.90000,-0.29668,-402.07733
9.00000,-0.30008,-449.07201
9.10000,-0.30325,-493.88506
9.20000,-0.30660,-543.42640
9.30000,-0.31001,-594.83880
9.40000,-0.31330,-648.54720
9.50000,-0.31659,-703.49411
9.60000,-0.32005,-764.43837
9.70000,-0.32328,-822.46466
9.80000,-0.32651,-883.99881
9.90000,-0.32998,-950.85660
10.00000,-0.33333,-1018.09828
10.10000,-0.33650,-1084.33841
10.20000,-0.34002,-1156.43768
10.30000,-0.34337,-1230.46599
10.40000,-0.34648,-1300.39100
10.50000,-0.34995,-1373.52347
10.60000,-0.35336,-1443.49085
10.70000,-0.35652,-1516.69262
10.80000,-0.35999,-1599.89558
10.90000,-0.36340,-1682.58194
11.00000,-0.36663,-1762.09807
11.10000,-0.36998,-1846.92293
11.20000,-0.37339,-1936.83561
11.30000,-0.37655,-2019.22022
11.40000,-0.37990,-2105.48099
11.50000,-0.38337,-2200.69941
11.60000,-0.38660,-2288.63116
11.70000,-0.38995,-2379.96168
11.80000,-0.39341,-2481.18062
11.90000,-0.39658,-2576.29491
12.00000,-0.39987,-2668.30791
12.10000,-0.40328,-2772.20197
12.20000,-0.40657,-2871.44203
12.30000,-0.40980,-2966.94022
12.40000,-0.41332,-3071.64807
12.50000,-0.41673,-3181.96416
12.60000,-0.41984,-3273.79704
12.70000,-0.42331,-3381.82561
12.80000,-0.42666,-3487.49235
12.90000,-0.42989,-3591.83997
13.00000,-0.43329,-3697.07048
13.10000,-0.43670,-3810.59982
13.20000,-0.43993,-3917.39160
13.30000,-0.44328,-4027.96678
13.40000,-0.44663,-4143.87919
13.50000,-0.44992,-4255.39054
13.60000,-0.45320,-4367.26958
13.70000,-0.45667,-4484.15242
13.80000,-0.45990,-4600.69701
13.90000,-0.46331,-4719.87575
14.00000,-0.46666,-4838.00583
14.10000,-0.46995,-4959.10719
14.20000,-0.47317,-5072.88240
14.30000,-0.47664,-5200.53245
14.40000,-0.47993,-5323.02409
14.50000,-0.48322,-5440.50336
14.60000,-0.48669,-5570.95073
14.70000,-0.48992,-5695.96179
14.80000,-0.49314,-5816.85379
14.90000,-0.49661,-5947.81674
15.00000,-0.49996,-6078.77336
15.10000,-0.50319,-6203.76579
15.20000,-0.50666,-6336.54520
15.30000,-0.51000,-6469.96498
15.40000,-0.51323,-6594.06856
15.50000,-0.51664,-6731.76348
15.60000,-0.51999,-6867.37150
15.70000,-0.52322,-6993.77060
15.80000,-0.52663,-7135.37931
15.90000,-0.53003,-7275.35635
16.00000,-0.53332,-7408.58987
16.10000,-0.53661,-7545.99199
16.20000,-0.54002,-7691.32152
16.30000,-0.54325,-7823.85916
16.40000,-0.54654,-7959.34051
16.50000,-0.55000,-8104.72369
16.60000,-0.55329,-8241.88665
16.70000,-0.55658,-8377.46859
16.80000,-0.56005,-8527.89581
16.90000,-0.56322,-8667.74991
17.00000,-0.56645,-8802.81627
17.10000,-0.56997,-8941.71745
17.20000,-0.57326,-9087.45155
17.30000,-0.57649,-9217.49324
17.40000,-0.58008,-9375.08568
17.50000,-0.58337,-9520.14402
17.60000,-0.58654,-9658.32770
17.70000,-0.58994,-9805.20546
17.80000,-0.59335,-9954.11798
17.90000,-0.59652,-10088.68814
18.00000,-0.59993,-10232.15130
18.10000,-0.60334,-10383.60670
18.20000,-0.60656,-10525.51642
18.30000,-0.60991,-10669.35658
18.40000,-0.61338,-10824.05970
18.50000,-0.61661,-10965.57751
18.60000,-0.61984,-11108.92966
18.70000,-0.62331,-11259.09165
18.80000,-0.62659,-11406.89477
18.90000,-0.62982,-11547.19815
19.00000,-0.63341,-11704.06416
19.10000,-0.63658,-11848.42661
19.20000,-0.63981,-11987.66232
19.30000,-0.64334,-12145.18994
19.40000,-0.64656,-12287.17193
19.50000,-0.64991,-12429.30815
19.60000,-0.65332,-12583.85479
19.70000,-0.65661,-12733.25980
19.80000,-0.65984,-12869.53092
19.90000,-0.66324,-13025.97523
20.00000,-0.66659,-13175.02409
20.10000,-0.66988,-13315.37813
20.20000,-0.67323,-13459.45597
20.30000,-0.67664,-13617.92535
20.40000,-0.67993,-13760.51903
20.50000,-0.68321,-13906.42077
20.60000,-0.68662,-14054.77524
20.70000,-0.68991,-14203.38154
20.80000,-0.69326,-14341.63153
20.90000,-0.69673,-14496.35923
21.00000,-0.69990,-14640.88857
21.10000,-0.70330,-14792.87595
21.20000,-0.70665,-14940.12028
21.30000,-0.70988,-15081.35200
21.40000,-0.71323,-15231.27705
21.50000,-0.71670,-15385.31929
21.60000,-0.71987,-15522.19838
21.70000,-0.72327,-15675.99028
21.80000,-0.72668,-15834.00220
21.90000,-0.72985,-15969.22129
22.00000,-0.73314,-16110.91346
22.10000,-0.73661,-16273.70864
22.20000,-0.73984,-16414.37411
22.30000,-0.74324,-16555.56411
22.40000,-0.74659,-16706.98076
22.50000,-0.75000,-16863.41166
22.60000,-0.75323,-17006.47026
22.70000,-0.75664,-17150.74629
22.80000,-0.75998,-17302.85436
22.90000,-0.76321,-17441.81067
23.00000,-0.76662,-17585.96301
23.10000,-0.76997,-17735.95959
23.20000,-0.77326,-17881.04475
23.30000,-0.77661,-18027.91655
23.40000,-0.78001,-18177.49590
23.50000,-0.78318,-18312.71350
23.60000,-0.78653,-18457.04764
23.70000,-0.79006,-18617.08164
23.80000,-0.79323,-18757.16299
23.90000,-0.79658,-18896.48885
24.00000,-0.80004,-19060.98127
24.10000,-0.80327,-19200.62751
24.20000,-0.80656,-19341.54481
24.30000,-0.80997,-19493.92557
24.40000,-0.81332,-19640.88380
24.50000,-0.81649,-19772.63540
24.60000,-0.81995,-19927.22899
24.70000,-0.82330,-20081.58267
24.80000,-0.82653,-20217.15492
24.90000,-0.82994,-20364.76284
25.00000,-0.83335,-20520.93893
25.10000,-0.83657,-20654.97041
25.20000,-0.83992,-20797.93215
25.30000,-0.84333,-20950.52600
25.40000,-0.84656,-21094.83778
25.50000,-0.84991,-21231.08655
25.60000,-0.85344,-21382.10833
25.70000,-0.85648,-21508.87698
25.80000,-0.85989,-21650.03866
25.90000,-0.86342,-21803.97362
26.00000,-0.86665,-21939.93032
26.10000,-0.86994,-22085.46102
26.20000,-0.87329,-22233.78569
26.30000,-0.87651,-22368.33721
26.40000,-0.87980,-22509.64493
26.50000,-0.88327,-22660.97367
26.60000,-0.88662,-22803.91753
26.70000,-0.88985,-22942.42382
26.80000,-0.89326,-23088.71448
26.90000,-0.89654,-23234.39717
27.00000,-0.89989,-23368.95168
27.10000,-0.90318,-23508.34459
27.20000,-0.90665,-23655.89738
27.30000,-0.90988,-23788.69504
27.40000,-0.91322,-23923.83963
27.50000,-0.91675,-24083.57263
27.60000,-0.91992,-24209.09107
27.70000,-0.92327,-24346.10575
27.80000,-0.92662,-24486.56559
27.90000,-0.92985,-24619.13079
28.00000,-0.93325,-24753.30681
28.10000,-0.93672,-24896.68876
28.20000,-0.93989,-25032.73785
28.30000,-0.94330,-25173.30945
28.40000,-0.94665,-25310.72199
28.50000,-0.94982,-25438.57694
28.60000,-0.95316,-25576.36499
28.70000,-0.95669,-25727.17965
28.80000,-0.95986,-25857.54395
28.90000,-0.96327,-26002.10607
29.00000,-0.96662,-26146.35825
29.10000,-0.96991,-26285.14469
29.20000,-0.97319,-26419.73794
29.30000,-0.97666,-26561.43904
29.40000,-0.97995,-26701.59340
29.50000,-0.98318,-26827.94929
29.60000,-0.98659,-26970.23451
29.70000,-0.98999,-27117.63978
29.80000,-0.99316,-27240.70251
29.90000,-0.99657,-27375.94545
30.00000,-1.00004,-27522.75467
30.10000,-1.00321,-27642.66431
30.20000,-1.00656,-27772.87960
30.30000,-1.01008,-27922.64521
30.40000,-1.01319,-28050.89653
30.50000,-1.01666,-28184.36623
30.60000,-1.02001,-28327.74520
30.70000,-1.02324,-28449.77379
30.80000,-1.02665,-28585.54721
30.90000,-1.03005,-28720.26861
31.00000,-1.03328,-28849.75970
31.10000,-1.03657,-28974.01452
31.20000,-1.04004,-29117.76900
31.30000,-1.04327,-29244.19045
31.40000,-1.04650,-29371.31822
31.50000,-1.05002,-29513.09979
31.60000,-1.05331,-29647.26388
31.70000,-1.05648,-29768.13316
31.80000,-1.05989,-29905.56657
31.90000,-1.06330,-30045.95339
32.00000,-1.06647,-30165.91072
32.10000,-1.06987,-30293.38717
32.20000,-1.07340,-30450.04010
32.30000,-1.07651,-30554.49128
32.40000,-1.07998,-30689.29315
32.50000,-1.08333,-30831.77507
32.60000,-1.08661,-30952.44765
32.70000,-1.08990,-31080.91354
32.80000,-1.09331,-31219.93840
32.90000,-1.09660,-31341.04908
33.00000,-1.09989,-31463.79292
33.10000,-1.10330,-31601.64952
33.20000,-1.10658,-31732.06747
33.30000,-1.10993,-31858.23560
33.40000,-1.11328,-31984.79116
33.50000,-1.11657,-32112.86068
33.60000,-1.11998,-32241.57095
33.70000,-1.12321,-32358.61063
33.80000,-1.12661,-32502.36809
33.90000,-1.12978,-32625.27883
34.00000,-1.13331,-32757.90811
34.10000,-1.13666,-32899.96982
34.20000,-1.13983,-33018.13304
34.30000,-1.14324,-33149.70732
34.40000,-1.14658,-33276.40593
34.50000,-1.14975,-33400.39849
34.60000,-1.15322,-33534.00528
34.70000,-1.15669,-33671.28670
34.80000,-1.15992,-33790.99965
34.90000,-1.16332,-33926.99361
35.00000,-1.16661,-34051.32294
35.10000,-1.16984,-34167.01257
35.20000,-1.17325,-34299.96073
35.30000,-1.17660,-34436.51199
35.40000,-1.17989,-34554.32951
35.50000,-1.18329,-34689.93902
35.60000,-1.18664,-34819.86821
35.70000,-1.18999,-34945.77706
35.80000,-1.19328,-35062.98959
35.90000,-1.19669,-35198.25935
36.00000,-1.19992,-35321.60819
36.10000,-1.20320,-35442.46554
36.20000,-1.20667,-35579.06151
36.30000,-1.20990,-35700.58048
36.40000,-1.21319,-35816.58006
36.50000,-1.21666,-35951.85876
36.60000,-1.21989,-36077.69310
36.70000,-1.22311,-36187.96468
36.80000,-1.22658,-36328.01175
36.90000,-1.23005,-36471.20297
37.00000,-1.23310,-36571.58017
37.10000,-1.23669,-36712.40509
37.20000,-1.23997,-36847.24867
37.30000,-1.24320,-36963.00685
37.40000,-1.24661,-37090.10780
37.50000,-1.25008,-37232.24699
37.60000,-1.25319,-37345.95776
37.70000,-1.25660,-37466.03131
37.80000,-1.26000,-37597.08107
37.90000,-1.26317,-37713.44125
38.00000,-1.26658,-37834.65028
38.10000,-1.27005,-37967.73851
38.20000,-1.27328,-38086.55739
38.30000,-1.27657,-38205.13785
38.40000,-1.27997,-38335.47831
38.50000,-1.28332,-38457.41451
38.60000,-1.28643,-38570.72890
38.70000,-1.29002,-38704.79465
38.80000,-1.29325,-38834.20229
38.90000,-1.29642,-38932.62148
39.00000,-1.29994,-39081.50196
39.10000,-1.30323,-39208.49860
39.20000,-1.30658,-39322.60573
39.30000,-1.30993,-39451.57826
39.40000,-1.31334,-39580.92928
39.50000,-1.31656,-39693.84134
39.60000,-1.31991,-39817.57462
39.70000,-1.32332,-39956.31933
39.80000,-1.32661,-40076.72071
39.90000,-1.32990,-40194.70811
40.00000,-1.33331,-40322.19648
40.10000,-1.33659,-40446.03109
40.20000,-1.34000,-40574.84567
40.30000,-1.34323,-40685.27818
40.40000,-1.34664,-40828.78828
40.50000,-1.34981,-40938.11810
40.60000,-1.35334,-41067.47806
40.70000,-1.35662,-41198.63510
40.80000,-1.35997,-41317.13808
40.90000,-1.36332,-41443.08269
41.00000,-1.36655,-41560.42933
41.10000,-1.36984,-41680.63104
41.20000,-1.37331,-41815.34350
41.30000,-1.37659,-41938.45689
41.40000,-1.37988,-42049.52121
41.50000,-1.38335,-42181.29516
41.60000,-1.38658,-42298.27523
41.70000,-1.38981,-42412.85622
41.80000,-1.39333,-42546.55838
41.90000,-1.39656,-42676.02563
42.00000,-1.39985,-42792.15336
42.10000,-1.40326,-42925.64392
42.20000,-1.40667,-43046.08405
42.30000,-1.40996,-43169.39116
42.40000,-1.41324,-43286.75270
42.50000,-1.41671,-43421.36085
42.60000,-1.41994,-43536.52894
42.70000,-1.42323,-43661.01921
42.80000,-1.42670,-43793.16568
42.90000,-1.42993,-43908.26225
43.00000,-1.43321,-44016.74271
43.10000,-1.43668,-44160.12764
43.20000,-1.43985,-44274.13642
43.30000,-1.44308,-44381.49333
43.40000,-1.44661,-44526.59190
43.50000,-1.45001,-44666.92507
43.60000,-1.45312,-44758.46887
43.70000,-1.45677,-44906.27646
43.80000,-1.45994,-45026.27254
43.90000,-1.46317,-45133.82018
44.00000,-1.46670,-45269.56975
44.10000,-1.47010,-45404.39248
44.20000,-1.47315,-45502.76101
44.30000,-1.47662,-45626.28269
44.40000,-1.48003,-45757.25496
44.50000,-1.48320,-45868.07787
44.60000,-1.48655,-45988.95609
44.70000,-1.49007,-46130.41580
44.80000,-1.49324,-46252.51591
44.90000,-1.49653,-46371.51361
45.00000,-1.50000,-46498.62051
45.10000,-1.50329,-46622.36273
45.20000,-1.50646,-46736.55331
45.30000,-1.51004,-46876.29640
45.40000,-1.51321,-47008.96740
45.50000,-1.51650,-47117.13791
45.60000,-1.52003,-47264.61172
45.70000,-1.52326,-47389.53114
45.80000,-1.52655,-47508.19504
45.90000,-1.52995,-47635.18274
46.00000,-1.53324,-47761.07669
46.10000,-1.53647,-47878.36671
46.20000,-1.53994,-48009.54461
46.30000,-1.54329,-48134.50575
46.40000,-1.54663,-48251.74510
46.50000,-1.54992,-48365.12506
46.60000,-1.55327,-48486.32514
46.70000,-1.55662,-48600.40247
46.80000,-1.55985,-48729.96807
46.90000,-1.56332,-48849.59757
47.00000,-1.56666,-48982.17022
47.10000,-1.56989,-49085.09851
47.20000,-1.57342,-49234.59291
47.30000,-1.57665,-49347.43345
47.40000,-1.57994,-49464.03503
47.50000,-1.58329,-49597.30506
47.60000,-1.58657,-49728.18792
47.70000,-1.58986,-49847.65351
47.80000,-1.59333,-49982.67293
47.90000,-1.59662,-50114.92372
48.00000,-1.59997,-50238.47818
48.10000,-1.60326,-50365.68046
48.20000,-1.60648,-50487.68520
48.30000,-1.60977,-50613.17682
48.40000,-1.61330,-50756.68693
48.50000,-1.61653,-50875.63992
48.60000,-1.61994,-51002.77066
48.70000,-1.62328,-51138.09705
48.80000,-1.62663,-51259.20773
48.90000,-1.62992,-51385.15830
49.00000,-1.63327,-51507.75313
49.10000,-1.63668,-51648.64063
49.20000,-1.63991,-51751.20831
49.30000,-1.64325,-51876.14560
49.40000,-1.64672,-52018.12983
49.50000,-1.64995,-52125.43607
49.60000,-1.65324,-52235.72254
49.70000,-1.65671,-52387.49385
49.80000,-1.65988,-52503.59774
49.90000,-1.66316,-52616.53662
50.00000,-1.66669,-52762.70509
50.10000,-1.66992,-52892.04121
50.20000,-1.67321,-53001.92237
50.30000,-1.67668,-53148.37098
50.40000,-1.67985,-53262.29930
50.50000,-1.68325,-53388.11278
50.60000,-1.68672,-53527.59361
50.70000,-1.69007,-53657.03702
50.80000,-1.69318,-53760.39743
50.90000,-1.69665,-53899.84250
51.00000,-1.69994,-54023.85592
51.10000,-1.70304,-54132.44367
51.20000,-1.70663,-54276.52597
51.30000,-1.71010,-54422.08648
51.40000,-1.71321,-54528.95164
51.50000,-1.71656,-54653.19753
51.60000,-1.72002,-54790.59815
51.70000,-1.72319,-54904.52647
51.80000,-1.72648,-55019.08064
51.90000,-1.73019,-55181.74767
52.00000,-1.73318,-55290.69901
52.10000,-1.73659,-55409.04403
52.20000,-1.74011,-55563.47966
52.30000,-1.74334,-55677.32453
52.40000,-1.74651,-55795.84837
52.50000,-1.74992,-55932.84369
52.60000,-1.75315,-56058.00748
52.70000,-1.75644,-56181.87189
52.80000,-1.75990,-56325.29855
52.90000,-1.76325,-56459.54609
53.00000,-1.76666,-56585.96754
53.10000,-1.76989,-56710.11209
53.20000,-1.77324,-56848.10281
53.30000,-1.77659,-56977.85616
53.40000,-1.77981,-57101.21989
53.50000,-1.78328,-57241.62459
53.60000,-1.78657,-57377.49338
53.70000,-1.78992,-57491.92834
53.80000,-1.79339,-57640.23662
53.90000,-1.79655,-57753.36623
54.00000,-1.79996,-57887.36343
54.10000,-1.80331,-58020.55001
54.20000,-1.80660,-58149.79672
54.30000,-1.80995,-58275.74134
54.40000,-1.81336,-58413.35654
54.50000,-1.81664,-58534.67584
54.60000,-1.81999,-58668.05911
54.70000,-1.82328,-58802.22917
54.80000,-1.82651,-58922.48154
54.90000,-1.82992,-59052.64616
55.00000,-1.83333,-59202.84390
55.10000,-1.83655,-59320.47367
55.20000,-1.83996,-59456.56300
55.30000,-1.84319,-59576.50542
55.40000,-1.84654,-59723.74082
55.50000,-1.84989,-59859.49039
55.60000,-1.85335,-59995.80622
55.70000,-1.85664,-60129.46367
55.80000,-1.85987,-60257.20835
55.90000,-1.86328,-60388.50546
56.00000,-1.86657,-60522.15695
56.10000,-1.86974,-60644.81735
56.20000,-1.87332,-60793.02430
56.30000,-1.87673,-60949.15271
56.40000,-1.87984,-61052.26874
56.50000,-1.88325,-61188.03024
56.60000,-1.88684,-61351.69864
56.70000,-1.88977,-61452.89540
56.80000,-1.89323,-61580.86061
56.90000,-1.89664,-61739.91561
57.00000,-1.89987,-61859.95936
57.10000,-1.90334,-61998.82627
57.20000,-1.90681,-62139.18924
57.30000,-1.90992,-62271.11220
57.40000,-1.91314,-62376.41573
57.50000,-1.91661,-62528.02610
57.60000,-1.91984,-62660.16364
57.70000,-1.92319,-62787.70566
57.80000,-1.92672,-62937.26563
57.90000,-1.92995,-63074.77355
58.00000,-1.93317,-63193.75634
58.10000,-1.93652,-63331.62189
58.20000,-1.93987,-63472.02063
58.30000,-1.94304,-63600.54016
58.40000,-1.94657,-63742.49458
58.50000,-1.95009,-63913.51223
58.60000,-1.95320,-64008.43263
58.70000,-1.95667,-64160.94303
58.80000,-1.96002,-64304.41141
58.90000,-1.96325,-64416.68272
59.00000,-1.96654,-64552.27137
59.10000,-1.97000,-64706.46262
59.20000,-1.97329,-64829.73695
59.30000,-1.97658,-64957.63063
59.40000,-1.98005,-65108.47807
59.50000,-1.98334,-65239.91227
59.60000,-1.98663,-65369.41528
59.70000,-1.98991,-65492.86246
59.80000,-1.99326,-65640.98001
59.90000,-1.99667,-65782.71389
60.00000,-1.99984,-65895.31898
60.10000,-2.00343,-66057.98602
60.20000,-2.00648,-66186.97047
60.30000,-2.00994,-66314.41116
60.40000,-2.01329,-66472.23830
60.50000,-2.01652,-66606.76003
60.60000,-2.01999,-66753.36361
60.70000,-2.02328,-66889.98938
60.80000,-2.02651,-67017.42411
60.90000,-2.02985,-67164.87408
61.00000,-2.03320,-67305.58872
61.10000,-2.03649,-67434.03077
61.20000,-2.04002,-67595.87526
61.30000,-2.04331,-67741.06622
61.40000,-2.04653,-67859.90596
61.50000,-2.05000,-68001.30606
61.60000,-2.05329,-68156.20065
61.70000,-2.05646,-68272.33434
61.80000,-2.05993,-68421.41151
61.90000,-2.06328,-68564.36729
62.00000,-2.06662,-68715.21473
62.10000,-2.06997,-68852.41270
62.20000,-2.07344,-69001.49584
62.30000,-2.07661,-69130.65314
62.40000,-2.07984,-69261.30652
62.50000,-2.08325,-69404.67358
62.60000,-2.08659,-69545.84718
62.70000,-2.08982,-69678.52712
62.80000,-2.09341,-69838.83977
62.90000,-2.09664,-69981.39620
63.00000,-2.09981,-70095.82520
63.10000,-2.10322,-70244.13943
63.20000,-2.10668,-70402.02022
63.30000,-2.10973,-70510.67948
63.40000,-2.11338,-70668.79272
63.50000,-2.11661,-70822.65019
63.60000,-2.11984,-70945.16158
63.70000,-2.12336,-71098.40512
63.80000,-2.12677,-71258.39591
63.90000,-2.12976,-71375.67997
64.00000,-2.13311,-71503.21007
64.10001,-2.13670,-71679.59213
64.20000,-2.13981,-71819.80610
64.30000,-2.14321,-71954.36954
64.40000,-2.14674,-72117.85913
64.50000,-2.15003,-72271.41261
64.60001,-2.15320,-72392.84515
64.70000,-2.15655,-72538.25068
64.80000,-2.15996,-72695.07647
64.90000,-2.16306,-72831.08830
65.00000,-2.16659,-72972.10097
65.10001,-2.17006,-73155.21836
65.20000,-2.17311,-73267.62676
65.30000,-2.17658,-73420.66169
65.40000,-2.17993,-73570.63293
65.50000,-2.18321,-73707.36003
65.60001,-2.18656,-73853.62983
65.70001,-2.18997,-74009.01914
65.80000,-2.19326,-74147.66550
65.90000,-2.19661,-74295.85457
66.00000,-2.19995,-74450.43921
66.10001,-2.20324,-74587.50010
66.20001,-2.20659,-74743.39604
66.30000,-2.20994,-74888.09228
66.40000,-2.21323,-75031.76332
66.50000,-2.21670,-75191.15210
66.60001,-2.21992,-75320.45245
66.70001,-2.22333,-75489.39586
66.80000,-2.22638,-75613.58809
66.90000,-2.22997,-75772.20201
67.00000,-2.23326,-75935.75120
67.10001,-2.23661,-76066.90526
67.20001,-2.24001,-76226.96757
67.30000,-2.24330,-76379.14419
67.40000,-2.24647,-76510.66184
67.50000,-2.24982,-76659.06549
67.60001,-2.25323,-76824.25976
67.70001,-2.25658,-76969.55204
67.80000,-2.26004,-77134.63902
67.90000,-2.26333,-77283.16188
68.00000,-2.26656,-77418.63728
68.10001,-2.26997,-77574.80741
68.20001,-2.27314,-77719.79570
68.30000,-2.27643,-77858.50167
68.40000,-2.27995,-78036.43942
68.50000,-2.28330,-78184.81326
68.60001,-2.28665,-78333.47321
68.70001,-2.28994,-78488.40356
68.80000,-2.29341,-78656.52442
68.90000,-2.29651,-78781.89683
69.00000,-2.29980,-78926.96261
69.10001,-2.30333,-79104.27451
69.20001,-2.30662,-79259.01413
69.30000,-2.30985,-79386.55615
69.40000,-2.31344,-79567.40260
69.50000,-2.31654,-79716.74800
69.60001,-2.31965,-79838.34147
69.70001,-2.32318,-80004.51326
69.80000,-2.32659,-80184.03649
69.90000,-2.32970,-80300.73643
70.00000,-2.33340,-80485.56447
70.10001,-2.33657,-80628.04341
70.20001,-2.33986,-80774.25957
70.30000,-2.34333,-80944.83018
70.40000,-2.34680,-81106.84752
70.50000,-2.34979,-81234.51471
70.60001,-2.35331,-81402.48656
70.70001,-2.35672,-81570.65511
70.80000,-2.35983,-81703.31717
70.90000,-2.36324,-81858.72436
71.00000,-2.36671,-82027.75121
71.10001,-2.36982,-82168.25724
71.20001,-2.37311,-82320.25504
71.30000,-2.37663,-82494.24696
71.40000,-2.37992,-82650.68531
71.50000,-2.38303,-82792.01388
71.60001,-2.38674,-82969.16485
71.70001,-2.38979,-83135.55717
71.80000,-2.39296,-83259.64212
71.90000,-2.39660,-83453.05324
72.00000,-2.39989,-83615.73219
72.10001,-2.40318,-83765.78093
72.20001,-2.40665,-83927.97112
72.30000,-2.40988,-84091.29381
72.40000,-2.41316,-84239.73918
72.50000,-2.41651,-84394.01388
72.60001,-2.41992,-84561.18107
72.70001,-2.42327,-84724.15805
72.80000,-2.42650,-84880.19705
72.90000,-2.42996,-85038.29837
73.00000,-2.43337,-85199.09978
73.10001,-2.43660,-85364.77685
73.20001,-2.43989,-85502.88081
73.30000,-2.44336,-85688.29894
73.40000,-2.44653,-85821.88487
73.50000,-2.45005,-86005.32413
73.60001,-2.45328,-86168.20574
73.70001,-2.45675,-86329.31113
73.80000,-2.45998,-86493.59345
73.90000,-2.46315,-86641.26992
74.00000,-2.46644,-86791.08620
74.10001,-2.46984,-86967.14640
74.20001,-2.47319,-87142.06219
74.30000,-2.47660,-87308.85983
74.40000,-2.48001,-87488.71684
74.50000,-2.48318,-87642.25245
74.60001,-2.48647,-87795.29333
74.70001,-2.48993,-87969.76805
74.80000,-2.49310,-88124.03679
74.90000,-2.49657,-88295.16172
75.00000,-2.49992,-88473.15907
75.10001,-2.50333,-88635.01549
75.20001,-2.50668,-88804.54302
75.30000,-2.50996,-88952.73209
75.40000,-2.51331,-89120.79930
75.50000,-2.51648,-89263.99350
75.60001,-2.51983,-89429.83747
75.70001,-2.52336,-89610.04615
75.80000,-2.52658,-89761.41810
75.90000,-2.52993,-89922.57118
76.00000,-2.53340,-90109.97415
76.10001,-2.53639,-90247.80393
76.20001,-2.53968,-90391.78491
76.30000,-2.54333,-90593.60623
76.40000,-2.54643,-90771.72875
76.50000,-2.54984,-90910.92348
76.60001,-2.55343,-91122.55573
76.70001,-2.55648,-91267.99107
76.80000,-2.55983,-91422.95718
76.90000,-2.56336,-91615.46230
77.00000,-2.56664,-91794.35372
77.10001,-2.56975,-91926.33629
77.20001,-2.57346,-92125.89264
77.30000,-2.57675,-92298.56730
77.40000,-2.57980,-92428.70212
77.50000,-2.58327,-92618.51907
77.60001,-2.58673,-92809.61752
77.70001,-2.58990,-92951.67923
77.80000,-2.59325,-93119.45438
77.90000,-2.59666,-93303.02477
78.00000,-2.60001,-93463.93347
78.10001,-2.60312,-93599.95723
78.20001,-2.60682,-93807.05357
78.30000,-2.60975,-93949.52059
78.40000,-2.61310,-94099.02096
78.50000,-2.61675,-94310.02736
78.60001,-2.61998,-94470.45326
78.70001,-2.62326,-94632.27391
78.80000,-2.62667,-94805.12738
78.90000,-2.62984,-94968.17589
79.00000,-2.63307,-95135.31923
79.10001,-2.63654,-95308.70914
79.20001,-2.63989,-95489.83574
79.30000,-2.64329,-95669.54970
79.40000,-2.64652,-95838.13548
79.50000,-2.64987,-96012.26449
79.60001,-2.65328,-96185.19545
79.70001,-2.65639,-96362.27489
79.80000,-2.65992,-96529.41227
79.90000,-2.66326,-96721.26770
80.00000,-2.66649,-96869.20047
80.10001,-2.67014,-97078.96113
80.20001,-2.67337,-97246.03891
80.30000,-2.67666,-97417.59896
80.40000,-2.67989,-97585.35028
80.50001,-2.68317,-97753.73340
80.60001,-2.68658,-97925.65703
80.70001,-2.69005,-98125.18954
80.80000,-2.69328,-98300.86231
80.90000,-2.69675,-98483.83665
81.00001,-2.69997,-98666.50105
81.10001,-2.70308,-98814.49938
81.20001,-2.70637,-98984.22360
81.30000,-2.70996,-99195.58167
81.40000,-2.71313,-99358.13546
81.50001,-2.71666,-99552.78635
81.60001,-2.72000,-99740.60059
81.70001,-2.72323,-99910.75397
81.75401,-2.72509,-100003.08752