File: data/crush/Crush25-15.is_comp_RawData/Core25-15.csv
Time,Extension,Load
(sec),(mm),(N)
0.00000,-0.00018,-0.32845
0.10000,-0.00096,0.23165
0.20000,-0.00472,1.66871
0.30000,-0.00915,1.25706
0.40000,-0.01297,1.00600
0.50000,-0.01662,0.96526
0.60000,-0.02009,0.62646
0.70000,-0.02350,1.35772
0.80000,-0.02685,0.99621
0.90000,-0.03025,0.50034
1.00000,-0.03354,1.16658
1.10000,-0.03695,0.81917
1.20000,-0.04024,0.99464
1.30000,-0.04347,1.07572
1.40000,-0.04687,1.28095
1.50000,-0.05028,1.09216
1.60000,-0.05351,0.24105
1.70000,-0.05692,1.03381
1.80000,-0.06033,0.55008
1.90000,-0.06350,0.50152
2.00000,-0.06690,0.96095
2.10000,-0.07031,0.86656
2.20000,-0.07354,0.72203
2.30000,-0.07695,1.50774
2.40000,-0.08042,1.10979
2.50000,-0.08359,1.17089
2.60000,-0.08687,0.52580
2.70000,-0.09028,1.33892
2.80000,-0.09357,0.13804
2.90000,-0.09686,0.77961
3.00000,-0.10033,0.10396
3.10000,-0.10362,0.85168
3.20000,-0.10684,1.19243
3.30000,-0.11025,0.52110
3.40000,-0.11354,0.70245
3.50000,-0.11683,0.38793
3.60000,-0.12024,0.82230
3.70000,-0.12364,0.59513
3.80000,-0.12687,1.33148
3.90000,-0.13028,1.47562
4.00000,-0.13369,0.84854
4.10000,-0.13680,0.62333
4.20000,-0.14027,1.38318
4.30000,-0.14361,1.08942
4.40000,-0.14684,0.83953
4.50000,-0.15031,0.98289
4.60000,-0.15378,0.83640
4.70000,-0.15689,0.86382
4.80000,-0.16018,1.11527
4.90000,-0.16358,1.12624
5.00000,-0.16681,0.62176
5.10000,-0.17016,1.18147
5.20000,-0.17363,0.11806
5.30000,-0.17692,1.00365
5.40000,-0.18015,0.15606
5.50000,-0.18355,0.30920
5.60000,-0.18684,0.68835
5.70000,-0.19013,0.38989
5.80000,-0.19360,0.29588
5.90000,-0.19695,-0.07582
6.00000,-0.20018,0.30450
6.10000,-0.20358,0.11846
6.20000,-0.20693,-0.09227
6.30000,-0.21022,-0.55836
6.40000,-0.21357,-0.27401
6.50000,-0.21698,-0.23836
6.60000,-0.22020,-0.26970
6.70000,-0.22361,-0.78005
6.80000,-0.22702,-0.99587
6.90000,-0.23025,-1.34955
7.00000,-0.23354,-1.50662
7.10000,-0.23695,-2.58020
7.20000,-0.24023,-3.60679
7.30000,-0.24358,-4.32200
7.40000,-0.24699,-6.02344
7.50000,-0.25034,-8.18276
7.60000,-0.25351,-9.95550
7.70000,-0.25698,-12.07761
7.80000,-0.26026,-15.75820
7.90000,-0.26349,-18.67346
8.00000,-0.26690,-21.82020
8.10000,-0.27025,-25.03039
8.20000,-0.27348,-30.24205
8.30000,-0.27689,-36.59154
8.40000,-0.28023,-44.30485
8.50000,-0.28346,-53.90565
8.60000,-0.28693,-66.14637
8.70000,-0.29028,-83.06449
8.80000,-0.29351,-101.81332
8.90000,-0.29691,-123.96505
9.00000,-0.30032,-151.65549
9.10000,-0.30349,-178.73569
9.20000,-0.30690,-209.88309
9.30000,-0.31031,-242.85570
9.40000,-0.31354,-276.22390
9.50000,-0.31688,-312.19439
9.60000,-0.32035,-353.03973
9.70000,-0.32352,-393.76519
9.80000,-0.32681,-435.55959
9.90000,-0.33028,-482.59576
10.00000,-0.33357,-529.54657
10.10000,-0.33679,-576.80011
10.20000,-0.34032,-630.23125
10.30000,-0.34355,-684.46095
10.40000,-0.34672,-734.63176
10.50000,-0.35019,-793.08692
10.60000,-0.35360,-851.08615
10.70000,-0.35670,-905.94217
10.80000,-0.36029,-968.82256
10.90000,-0.36364,-1033.22333
11.00000,-0.36687,-1094.09401
11.10000,-0.37028,-1161.42966
11.20000,-0.37362,-1231.16476
11.30000,-0.37679,-1295.22439
11.40000,-0.38014,-1367.19011
11.50000,-0.38361,-1443.00563
11.60000,-0.38684,-1512.32826
11.70000,-0.39019,-1587.75635
11.80000,-0.39365,-1669.50002
11.90000,-0.39682,-1745.60677
12.00000,-0.40011,-1824.69524
12.10000,-0.40352,-1907.98081
12.20000,-0.40687,-1992.73676
12.30000,-0.41010,-2071.64884
12.40000,-0.41362,-2160.64584
12.50000,-0.41691,-2251.22757
12.60000,-0.42008,-2331.37812
12.70000,-0.42355,-2421.16544
12.80000,-0.42690,-2512.66602
12.90000,-0.43013,-2600.24834
13.00000,-0.43353,-2691.22887
13.10000,-0.43694,-2784.48723
13.20000,-0.44017,-2876.89194
13.30000,-0.44352,-2970.93373
13.40000,-0.44687,-3068.64250
13.50000,-0.45010,-3162.83964
13.60000,-0.45350,-3258.83105
13.70000,-0.45691,-3356.90416
13.80000,-0.46020,-3454.40917
13.90000,-0.46361,-3554.97226
14.00000,-0.46690,-3654.70275
14.10000,-0.47018,-3755.29118
14.20000,-0.47341,-3851.15035
14.30000,-0.47694,-3959.81036
14.40000,-0.48017,-4061.17663
14.50000,-0.48352,-4160.48579
14.60000,-0.48693,-4271.31094
14.70000,-0.49015,-4376.72399
14.80000,-0.49344,-4478.83904
14.90000,-0.49691,-4589.74577
15.00000,-0.50014,-4696.48242
15.10000,-0.50349,-4802.02101
15.20000,-0.50696,-4909.35482
15.30000,-0.51024,-5011.50265
15.40000,-0.51341,-5117.65890
15.50000,-0.51688,-5231.85655
15.60000,-0.52017,-5345.15269
15.70000,-0.52346,-5452.18401
15.80000,-0.52687,-5572.08993
15.90000,-0.53027,-5687.71847
16.00000,-0.53356,-5800.72924
16.10000,-0.53685,-5918.31878
16.20000,-0.54026,-6040.82793
16.30000,-0.54343,-6153.88229
16.40000,-0.54677,-6270.35126
16.50000,-0.55018,-6392.74269
16.60000,-0.55347,-6509.67807
16.70000,-0.55682,-6627.56637
16.80000,-0.56029,-6754.83122
16.90000,-0.56346,-6872.27845
17.00000,-0.56674,-6988.04632
17.10000,-0.57021,-7113.93952
17.20000,-0.57350,-7235.83922
17.30000,-0.57679,-7346.55932
17.40000,-0.58032,-7481.48561
17.50000,-0.58355,-7602.78106
17.60000,-0.58683,-7718.34925
17.70000,-0.59024,-7842.59588
17.80000,-0.59359,-7969.16932
17.90000,-0.59670,-8082.25200
18.00000,-0.60017,-8204.44301
18.10000,-0.60358,-8332.46186
18.20000,-0.60680,-8451.54002
18.30000,-0.61027,-8547.17642
18.40000,-0.61362,-8668.51881
18.50000,-0.61679,-8788.81365
18.60000,-0.62008,-8910.89216
18.70000,-0.62354,-9039.12261
18.80000,-0.62683,-9161.00293
18.90000,-0.63012,-9283.78329
19.00000,-0.63365,-9418.08745
19.10000,-0.63682,-9535.22921
19.20000,-0.64017,-9657.23023
19.30000,-0.64363,-9790.29313
19.40000,-0.64686,-9909.55681
19.50000,-0.65015,-10027.88767
19.60000,-0.65362,-10160.26661
19.70000,-0.65685,-10282.95010
19.80000,-0.66002,-10396.96857
19.90000,-0.66348,-10527.29413
20.00000,-0.66683,-10652.87814
20.10000,-0.67012,-10769.58925
20.20000,-0.67353,-10894.98699
20.30000,-0.67694,-11026.02333
20.40000,-0.68017,-11145.56789
20.50000,-0.68351,-11266.02516
20.60000,-0.68686,-11390.46997
20.70000,-0.69015,-11510.33491
20.80000,-0.69350,-11628.81851
20.90000,-0.69697,-11758.52343
21.00000,-0.70019,-11877.21565
21.10000,-0.70360,-12005.45281
21.20000,-0.70689,-12125.34085
21.30000,-0.71012,-12240.67435
21.40000,-0.71353,-12364.94705
21.50000,-0.71694,-12494.11330
21.60000,-0.72016,-12602.52595
21.70000,-0.72357,-12729.72971
21.80000,-0.72692,-12858.78718
21.90000,-0.73009,-12969.14220
22.00000,-0.73344,-13083.78577
22.10000,-0.73691,-13214.92046
22.20000,-0.74007,-13328.18419
22.30000,-0.74348,-13443.47447
22.40000,-0.74689,-13568.39538
22.50000,-0.75024,-13695.59914
22.60000,-0.75353,-13811.20384
22.70000,-0.75688,-13926.30786
22.80000,-0.76022,-14049.15005
22.90000,-0.76345,-14160.05492
23.00000,-0.76686,-14275.81161
23.10000,-0.77021,-14395.19227
23.20000,-0.77344,-14511.14267
23.30000,-0.77684,-14632.29805
23.40000,-0.78025,-14752.22558
23.50000,-0.78342,-14858.66010
23.60000,-0.78683,-14975.86668
23.70000,-0.79030,-15099.91139
23.80000,-0.79347,-15208.48870
23.90000,-0.79687,-15324.10085
24.00000,-0.80028,-15454.30720
24.10000,-0.80351,-15563.20339
24.20000,-0.80680,-15671.86862
24.30000,-0.81027,-15796.79102
24.40000,-0.81350,-15911.89951
24.50000,-0.81678,-16013.32128
24.60000,-0.82019,-16136.79826
24.70000,-0.82348,-16256.21617
24.80000,-0.82677,-16363.78467
24.90000,-0.83024,-16483.41566
25.00000,-0.83359,-16602.51468
25.10000,-0.83675,-16705.51896
25.20000,-0.84022,-16819.34297
25.30000,-0.84357,-16935.44090
25.40000,-0.84686,-17049.09354
25.50000,-0.85015,-17152.67301
25.60000,-0.85367,-17272.40235
25.70000,-0.85672,-17370.84836
25.80000,-0.86019,-17481.96483
25.90000,-0.86366,-17601.24117
26.00000,-0.86689,-17704.73868
26.10000,-0.87018,-17817.37357
26.20000,-0.87358,-17933.51769
26.30000,-0.87675,-18037.75281
26.40000,-0.88004,-18145.82646
26.50000,-0.88351,-18268.13519
26.60000,-0.88686,-18378.21603
26.70000,-0.89021,-18490.21316
26.80000,-0.89355,-18604.28005
26.90000,-0.89678,-18714.36387
27.00000,-0.90019,-18818.89552
27.10000,-0.90342,-18925.49098
27.20000,-0.90689,-19042.64987
27.30000,-0.91012,-19144.27876
27.40000,-0.91352,-19250.96512
27.50000,-0.91693,-19373.00414
27.60000,-0.92010,-19469.37591
27.70000,-0.92351,-19575.93411
27.80000,-0.92686,-19688.13539
27.90000,-0.93009,-19789.73895
28.00000,-0.93355,-19895.89632
28.10000,-0.93696,-20009.07809
28.20000,-0.94019,-20115.21161
28.30000,-0.94360,-20223.16605
28.40000,-0.94689,-20329.60206
28.50000,-0.95006,-20429.01218
28.60000,-0.95346,-20537.62227
28.70000,-0.95693,-20654.71113
28.80000,-0.96016,-20754.53848
28.90000,-0.96357,-20868.56961
29.00000,-0.96692,-20984.06553
29.10000,-0.97014,-21088.57781
29.20000,-0.97343,-21194.10038
29.30000,-0.97690,-21306.42831
29.40000,-0.98019,-21410.56955
29.50000,-0.98342,-21507.85178
29.60000,-0.98689,-21622.47896
29.70000,-0.99023,-21737.02419
29.80000,-0.99340,-21831.06840
29.90000,-0.99687,-21939.27169
30.00000,-1.00022,-22050.51333
30.10000,-1.00339,-22141.88725
30.20000,-1.00686,-22241.12004
30.30000,-1.01032,-22362.51831
30.40000,-1.01343,-22457.39549
30.50000,-1.01696,-22564.36944
30.60000,-1.02031,-22673.64115
30.70000,-1.02348,-22769.52416
30.80000,-1.02688,-22872.92778
30.90000,-1.03035,-22977.80365
31.00000,-1.03352,-23075.71024
31.10000,-1.03681,-23172.94627
31.20000,-1.04028,-23284.73032
31.30000,-1.04345,-23379.01592
31.40000,-1.04679,-23479.23517
31.50000,-1.05026,-23594.24680
31.60000,-1.05355,-23694.23211
31.70000,-1.05678,-23787.04399
31.80000,-1.06019,-23897.85945
31.90000,-1.06354,-24006.29222
32.00000,-1.06670,-24095.33411
32.10000,-1.07011,-24198.15809
32.20000,-1.07364,-24318.41493
32.30000,-1.07675,-24400.57695
32.40000,-1.08022,-24510.18989
32.50000,-1.08362,-24617.27113
32.60000,-1.08685,-24711.77578
32.70000,-1.09014,-24808.35170
32.80000,-1.09355,-24915.06338
32.90000,-1.09678,-25006.53863
33.00000,-1.10013,-25103.47962
33.10000,-1.10359,-25213.30416
33.20000,-1.10688,-25314.89730
33.30000,-1.11017,-25411.93664
33.40000,-1.11352,-25507.67660
33.50000,-1.11681,-25606.77230
33.60000,-1.12022,-25705.87993
33.70000,-1.12350,-25798.56217
33.80000,-1.12691,-25908.68771
33.90000,-1.13008,-26001.70672
34.00000,-1.13355,-26105.13270
34.10000,-1.13684,-26213.59527
34.20000,-1.14013,-26301.26476
34.30000,-1.14353,-26404.40166
34.40000,-1.14682,-26503.24404
34.50000,-1.15005,-26598.85585
34.60000,-1.15352,-26704.13852
34.70000,-1.15693,-26810.39870
34.80000,-1.16016,-26903.51307
34.90000,-1.16356,-27008.87620
35.00000,-1.16685,-27105.38208
35.10000,-1.17008,-27194.95595
35.20000,-1.17355,-27300.87042
35.30000,-1.17690,-27405.73883
35.40000,-1.18013,-27496.09351
35.50000,-1.18353,-27604.23124
35.60000,-1.18688,-27704.44155
35.70000,-1.19023,-27803.53129
35.80000,-1.19352,-27893.00978
35.90000,-1.19699,-27998.37887
36.00000,-1.20015,-28093.80293
36.10000,-1.20344,-28186.21099
36.20000,-1.20691,-28292.25659
36.30000,-1.21020,-28386.83128
36.40000,-1.21349,-28476.50051
36.50000,-1.21696,-28583.19879
36.60000,-1.22018,-28682.35111
36.70000,-1.22341,-28766.00325
36.80000,-1.22688,-28874.82941
36.90000,-1.23023,-28983.00588
37.00000,-1.23334,-29058.62629
37.10000,-1.23693,-29171.74697
37.20000,-1.24021,-29275.40243
37.30000,-1.24344,-29361.22715
37.40000,-1.24691,-29464.54585
37.50000,-1.25032,-29577.29399
37.60000,-1.25343,-29662.86540
37.70000,-1.25689,-29757.36856
37.80000,-1.26024,-29858.98852
37.90000,-1.26347,-29947.27790
38.00000,-1.26688,-30044.29340
38.10000,-1.27035,-30149.21546
38.20000,-1.27352,-30234.63190
38.30000,-1.27680,-30328.68505
38.40000,-1.28021,-30430.33183
38.50000,-1.28350,-30520.09344
38.60000,-1.28673,-30606.83012
38.70000,-1.29032,-30716.10928
38.80000,-1.29349,-30814.14998
38.90000,-1.29665,-30891.49296
39.00000,-1.30024,-31005.13816
39.10000,-1.30353,-31104.13551
39.20000,-1.30682,-31192.93451
39.30000,-1.31023,-31294.85548
39.40000,-1.31358,-31395.98966
39.50000,-1.31680,-31481.86207
39.60000,-1.32015,-31583.54163
39.70000,-1.32356,-31692.39461
39.80000,-1.32685,-31786.75175
39.90000,-1.33014,-31876.39415
40.00000,-1.33355,-31978.17504
40.10000,-1.33683,-32073.06266
40.20000,-1.34018,-32175.25780
40.30000,-1.34353,-32264.36675
40.40000,-1.34688,-32376.29235
40.50000,-1.35011,-32458.04310
40.60000,-1.35357,-32565.09304
40.70000,-1.35686,-32666.63849
40.80000,-1.36021,-32759.35054
40.90000,-1.36362,-32858.04093
41.00000,-1.36685,-32948.91119
41.10000,-1.37014,-33041.19110
41.20000,-1.37360,-33152.84848
41.30000,-1.37683,-33248.09670
41.40000,-1.38012,-33332.44026
41.50000,-1.38359,-33439.72266
41.60000,-1.38682,-33529.41275
41.70000,-1.39005,-33619.56179
41.80000,-1.39357,-33727.06771
41.90000,-1.39680,-33828.41945
42.00000,-1.40009,-33918.66684
42.10000,-1.40350,-34026.10719
42.20000,-1.40691,-34119.40038
42.30000,-1.41020,-34215.93606
42.40000,-1.41348,-34308.29942
42.50000,-1.41695,-34413.85627
42.60000,-1.42018,-34503.97253
42.70000,-1.42347,-34603.70600
42.80000,-1.42694,-34708.14824
42.90000,-1.43016,-34794.08026
43.00000,-1.43345,-34879.90201
43.10000,-1.43692,-34993.78562
43.20000,-1.44009,-35081.44319
43.30000,-1.44338,-35166.10861
43.40000,-1.44685,-35284.86192
43.50000,-1.45019,-35391.42311
43.60000,-1.45336,-35463.68480
43.70000,-1.45695,-35580.56653
43.80000,-1.46018,-35675.38857
43.90000,-1.46341,-35758.94535
44.00000,-1.46694,-35867.30659
44.10000,-1.47034,-35973.91546
44.20000,-1.47339,-36049.90542
44.30000,-1.47686,-36147.83287
44.40000,-1.48027,-36253.14236
44.50000,-1.48344,-36339.60783
44.60000,-1.48685,-36437.72006
44.70000,-1.49031,-36554.11005
44.80000,-1.49348,-36647.16184
44.90000,-1.49677,-36740.18383
45.00000,-1.50024,-36842.30745
45.10000,-1.50353,-36941.66243
45.20000,-1.50670,-37033.34033
45.30000,-1.51028,-37151.52740
45.40000,-1.51345,-37252.37250
45.50000,-1.51674,-37340.58142
45.60000,-1.52027,-37457.63004
45.70000,-1.52350,-37555.56345
45.80000,-1.52678,-37648.50199
45.90000,-1.53025,-37753.77870
46.00000,-1.53348,-37851.33660
46.10000,-1.53677,-37948.55475
46.20000,-1.54024,-38054.58248
46.30000,-1.54353,-38154.52456
46.40000,-1.54687,-38245.70477
46.50000,-1.55016,-38336.95948
46.60000,-1.55357,-38433.00641
46.70000,-1.55686,-38524.28198
46.80000,-1.56015,-38630.18453
46.90000,-1.56356,-38725.98112
47.00000,-1.56690,-38827.73221
47.10000,-1.57013,-38911.79860
47.20000,-1.57366,-39032.42052
47.30000,-1.57689,-39120.24498
47.40000,-1.58024,-39219.06650
47.50000,-1.58353,-39325.31476
47.60000,-1.58681,-39428.97916
47.70000,-1.59016,-39523.89956
47.80000,-1.59357,-39634.69863
47.90000,-1.59680,-39733.10590
48.00000,-1.60021,-39835.05666
48.10000,-1.60355,-39938.09223
48.20000,-1.60672,-40036.21638
48.30000,-1.61007,-40139.02247
48.40000,-1.61354,-40254.66442
48.50000,-1.61677,-40348.61922
48.60000,-1.62018,-40450.65641
48.70000,-1.62352,-40557.89411
48.80000,-1.62687,-40658.26237
48.90000,-1.63016,-40757.74252
49.00000,-1.63357,-40859.82144
49.10000,-1.63692,-40972.72754
49.20000,-1.64015,-41055.36342
49.30000,-1.64349,-41157.48107
49.40000,-1.64696,-41269.27853
49.50000,-1.65019,-41352.60284
49.60000,-1.65354,-41447.88980
49.70000,-1.65701,-41571.23566
49.80000,-1.66012,-41658.70249
49.90000,-1.66340,-41750.18370
50.00000,-1.66693,-41868.74926
50.10000,-1.67010,-41971.42124
50.20000,-1.67351,-42062.53290
50.30000,-1.67692,-42181.73325
50.40000,-1.68008,-42272.53795
50.50000,-1.68349,-42375.41556
50.60000,-1.68696,-42489.65085
50.70000,-1.69025,-42595.02888
50.80000,-1.69342,-42676.04351
50.90000,-1.69695,-42793.00272
51.00000,-1.70017,-42893.66901
51.10000,-1.70334,-42980.94511
51.20000,-1.70693,-43101.55213
51.30000,-1.71034,-43219.19084
51.40000,-1.71345,-43298.81370
51.50000,-1.71686,-43404.34372
51.60000,-1.72026,-43518.12005
51.70000,-1.72349,-43611.21356
51.80000,-1.72672,-43702.87359
51.90000,-1.73037,-43836.42077
52.00000,-1.73342,-43919.87622
52.10000,-1.73683,-44022.70317
52.20000,-1.74029,-44141.72769
52.30000,-1.74352,-44235.35466
52.40000,-1.74681,-44333.56225
52.50000,-1.75022,-44447.07036
52.60000,-1.75345,-44544.72959
52.70000,-1.75674,-44645.15746
52.80000,-1.76020,-44765.54394
52.90000,-1.76349,-44872.14088
53.00000,-1.76684,-44973.60587
53.10000,-1.77013,-45078.77827
53.20000,-1.77342,-45188.67731
53.30000,-1.77682,-45294.90769
53.40000,-1.78011,-45400.08903
53.50000,-1.78352,-45515.44487
53.60000,-1.78681,-45621.81234
53.70000,-1.79016,-45717.47184
53.80000,-1.79363,-45840.13224
53.90000,-1.79679,-45932.39427
54.00000,-1.80020,-46045.00830
54.10000,-1.80355,-46154.79708
54.20000,-1.80684,-46258.69691
54.30000,-1.81019,-46362.43582
54.40000,-1.81359,-46474.31374
54.50000,-1.81682,-46569.77654
54.60000,-1.82023,-46680.70972
54.70000,-1.82352,-46793.64562
54.80000,-1.82681,-46891.88898
54.90000,-1.83022,-47002.47943
55.00000,-1.83356,-47125.18156
55.10000,-1.83679,-47216.52269
55.20000,-1.84020,-47333.07064
55.30000,-1.84343,-47430.87888
55.40000,-1.84684,-47553.23827
55.50000,-1.85019,-47664.59167
55.60000,-1.85359,-47778.69284
55.70000,-1.85682,-47884.89044
55.80000,-1.86011,-47988.10482
55.90000,-1.86352,-48101.24040
56.00000,-1.86687,-48210.35266
56.10000,-1.87004,-48311.50472
56.20000,-1.87356,-48440.34016
56.30000,-1.87697,-48563.51912
56.40000,-1.88008,-48644.85860
56.50000,-1.88349,-48758.43823
56.60000,-1.88702,-48891.65163
56.70000,-1.89001,-48973.45901
56.80000,-1.89353,-49081.59971
56.90000,-1.89688,-49211.76136
57.00000,-1.90011,-49310.43983
57.10000,-1.90358,-49427.16062
57.20000,-1.90705,-49544.79039
57.30000,-1.91021,-49649.99557
57.40000,-1.91350,-49744.90702
57.50000,-1.91691,-49867.79988
57.60000,-1.92008,-49971.96794
57.70000,-1.92343,-50076.71118
57.80000,-1.92702,-50207.98445
57.90000,-1.93024,-50315.90462
58.00000,-1.93347,-50412.44030
58.10000,-1.93682,-50532.82380
58.20000,-1.94011,-50646.06667
58.30000,-1.94328,-50748.53897
58.40000,-1.94681,-50872.44511
58.50000,-1.95033,-51013.20148
58.60000,-1.95338,-51089.53118
58.70000,-1.95691,-51222.67008
58.80000,-1.96026,-51341.73632
58.90000,-1.96349,-51434.38578
59.00000,-1.96684,-51548.48695
59.10000,-1.97024,-51676.72634
59.20000,-1.97347,-51777.01116
59.30000,-1.97682,-51885.38432
59.40000,-1.98029,-52012.24089
59.50000,-1.98358,-52121.31739
59.60000,-1.98686,-52230.60250
59.70000,-1.99015,-52333.73642
59.80000,-1.99350,-52453.95899
59.90000,-1.99691,-52573.75836
60.00000,-2.00014,-52665.12632
60.10000,-2.00361,-52803.39122
60.20000,-2.00677,-52909.34443
60.30000,-2.01024,-53021.25216
60.40000,-2.01353,-53145.45631
60.50000,-2.01682,-53255.43284
60.60000,-2.02023,-53378.46279
60.70000,-2.02352,-53492.78450
60.80000,-2.02674,-53595.75748
60.90000,-2.03015,-53723.85979
61.00000,-2.03344,-53845.02411
61.10000,-2.03673,-53951.50185
61.20000,-2.04020,-54084.14602
61.30000,-2.04349,-54204.98252
61.40000,-2.04671,-54304.55804
61.50000,-2.05024,-54431.65898
61.60000,-2.05353,-54558.22349
61.70000,-2.05676,-54658.12087
61.80000,-2.06023,-54784.98936
61.90000,-2.06357,-54904.40726
62.00000,-2.06686,-55026.92461
62.10000,-2.07021,-55140.19132
62.20000,-2.07362,-55265.66505
62.30000,-2.07685,-55375.12898
62.40000,-2.08014,-55485.31413
62.50000,-2.08354,-55605.54266
62.60000,-2.08683,-55722.90421
62.70000,-2.09006,-55830.44291
62.80000,-2.09365,-55969.06543
62.90000,-2.09688,-56087.08858
63.00000,-2.10005,-56180.10759
63.10000,-2.10351,-56310.34970
63.20000,-2.10698,-56443.75682
63.30000,-2.10997,-56527.29869
63.40000,-2.11362,-56666.17155
63.50000,-2.11685,-56789.98232
63.60000,-2.12008,-56892.65132
63.70000,-2.12360,-57018.97740
63.80000,-2.12701,-57155.19786
63.90000,-2.13006,-57253.37863
64.00000,-2.13341,-57363.55782
64.10001,-2.13694,-57510.65612
64.20000,-2.14011,-57626.02687
64.30000,-2.14351,-57736.56964
64.40000,-2.14704,-57881.08110
64.50000,-2.15027,-58000.71955
64.60001,-2.15344,-58100.99244
64.70000,-2.15685,-58223.15812
64.80000,-2.16019,-58355.86786
64.90000,-2.16330,-58465.11722
65.00000,-2.16683,-58585.50072
65.10001,-2.17024,-58737.14089
65.20000,-2.17341,-58828.38368
65.30000,-2.17688,-58963.02462
65.40000,-2.18010,-59082.25775
65.50000,-2.18345,-59197.14570
65.60001,-2.18686,-59322.65520
65.70001,-2.19027,-59454.35166
65.80000,-2.19350,-59569.34690
65.90000,-2.19685,-59689.15820
66.00000,-2.20025,-59822.21365
66.10001,-2.20348,-59936.04660
66.20001,-2.20683,-60063.67207
66.30000,-2.21018,-60188.28750
66.40000,-2.21347,-60306.54907
66.50000,-2.21693,-60445.35637
66.60001,-2.22016,-60552.00100
66.70001,-2.22363,-60696.08331
66.80000,-2.22668,-60795.67075
66.90000,-2.23021,-60933.60186
67.00000,-2.23356,-61069.54813
67.10001,-2.23684,-61174.18408
67.20001,-2.24025,-61311.41782
67.30000,-2.24348,-61437.73794
67.40000,-2.24671,-61543.88189
67.50000,-2.25012,-61676.21017
67.60001,-2.25347,-61815.95325
67.70001,-2.25681,-61939.29315
67.80000,-2.26028,-62077.01564
67.90000,-2.26357,-62198.54951
68.00000,-2.26680,-62313.87258
68.10001,-2.27027,-62444.70477
68.20001,-2.27338,-62562.57892
68.30000,-2.27666,-62678.32518
68.40000,-2.28013,-62824.97644
68.50000,-2.28354,-62954.10991
68.60001,-2.28689,-63079.56576
68.70001,-2.29018,-63205.60575
68.80000,-2.29364,-63347.14293
68.90000,-2.29681,-63451.21861
69.00000,-2.30010,-63576.07841
69.10001,-2.30357,-63726.37749
69.20001,-2.30686,-63852.88835
69.30000,-2.31015,-63958.33492
69.40000,-2.31367,-64111.69767
69.50000,-2.31678,-64236.27734
69.60001,-2.31995,-64338.99403
69.70001,-2.32348,-64479.10666
69.80000,-2.32677,-64625.56720
69.90000,-2.33000,-64726.53747
70.00000,-2.33364,-64880.85985
70.10001,-2.33687,-65002.12550
70.20001,-2.34010,-65121.09637
70.30000,-2.34363,-65267.29465
70.40000,-2.34698,-65402.10843
70.50000,-2.35003,-65505.65362
70.60001,-2.35355,-65647.00603
70.70001,-2.35696,-65786.05175
70.80000,-2.36007,-65894.66333
70.90000,-2.36354,-66029.69170
71.00000,-2.36701,-66180.40204
71.10001,-2.37006,-66289.61563
71.20001,-2.37340,-66414.68406
71.30000,-2.37687,-66565.17386
71.40000,-2.38016,-66696.25640
71.50000,-2.38333,-66811.64503
71.60001,-2.38704,-66967.23104
71.70001,-2.39009,-67103.30844
71.80000,-2.39331,-67207.74174
71.90000,-2.39690,-67369.37165
72.00000,-2.40013,-67503.69072
72.10001,-2.40342,-67626.86372
72.20001,-2.40689,-67769.37246
72.30000,-2.41017,-67906.71945
72.40000,-2.41346,-68030.06530
72.50000,-2.41681,-68160.95710
72.60001,-2.42016,-68300.46177
72.70001,-2.42351,-68431.47278
72.80000,-2.42680,-68561.07116
72.90000,-2.43014,-68699.98574
73.00000,-2.43355,-68831.53915
73.10001,-2.43684,-68974.06578
73.20001,-2.44019,-69091.60018
73.30000,-2.44354,-69242.26284
73.40000,-2.44671,-69352.81754
73.50000,-2.45029,-69512.04538
73.60001,-2.45358,-69645.01143
73.70001,-2.45699,-69785.83336
73.80000,-2.46028,-69923.83599
73.90000,-2.46345,-70044.08240
74.00000,-2.46674,-70168.70975
74.10001,-2.47014,-70326.06602
74.20001,-2.47343,-70465.61241
74.30000,-2.47684,-70603.61505
74.40000,-2.48025,-70756.61421
74.50000,-2.48348,-70886.44505
74.60001,-2.48671,-71012.76517
74.70001,-2.49017,-71162.39071
74.80000,-2.49334,-71293.39576
74.90000,-2.49681,-71438.71784
75.00000,-2.50016,-71582.73458
75.10001,-2.50351,-71719.66434
75.20001,-2.50691,-71865.13543
75.30000,-2.51026,-71993.84570
75.40000,-2.51355,-72136.52134
75.50000,-2.51678,-72255.71871
75.60001,-2.52013,-72398.52548
75.70001,-2.52360,-72551.24450
75.80000,-2.52682,-72677.61230
75.90000,-2.53023,-72817.03949
76.00000,-2.53370,-72977.05412
76.10001,-2.53669,-73086.52997
76.20001,-2.53998,-73212.96334
76.30000,-2.54362,-73388.21888
76.40000,-2.54679,-73532.51576
76.50000,-2.55014,-73653.45955
76.60001,-2.55367,-73833.31656
76.70001,-2.55678,-73954.73719
76.80000,-2.56013,-74083.42957
76.90000,-2.56359,-74243.13426
77.00000,-2.56688,-74393.17107
77.10001,-2.57005,-74506.81329
77.20001,-2.57364,-74670.81547
77.30000,-2.57687,-74813.74741
77.40000,-2.58004,-74928.81417
77.50000,-2.58356,-75086.14063
77.60001,-2.58691,-75247.37716
77.70001,-2.59008,-75361.56774
77.80000,-2.59349,-75506.50239
77.90000,-2.59690,-75661.30757
78.00000,-2.60019,-75794.22593
78.10001,-2.60341,-75910.84838
78.20001,-2.60706,-76091.19415
78.30000,-2.60999,-76202.99459
78.40000,-2.61340,-76335.96659
78.50000,-2.61699,-76508.64124
78.60001,-2.62021,-76639.15157
78.70001,-2.62356,-76780.05695
78.80000,-2.62697,-76926.27311
78.90000,-2.63008,-77058.63714
79.00000,-2.63331,-77197.20006
79.10001,-2.63678,-77343.15395
79.20001,-2.64013,-77498.08431
79.30000,-2.64353,-77651.29209
79.40000,-2.64676,-77788.46622
79.50000,-2.65011,-77933.80022
79.60001,-2.65352,-78081.28595
79.70001,-2.65669,-78229.24256
79.80000,-2.66015,-78372.16854
79.90000,-2.66344,-78526.74723
80.00000,-2.66673,-78655.30252
80.10001,-2.67032,-78831.05278
80.20001,-2.67355,-78963.83405
80.30000,-2.67690,-79114.52651
80.40000,-2.68018,-79256.25443
80.50001,-2.68341,-79387.22372
80.60001,-2.68676,-79531.25238
80.70001,-2.69023,-79698.97389
80.80000,-2.69352,-79845.10660
80.90000,-2.69699,-79996.23418
81.00001,-2.70027,-80158.10847
81.10001,-2.70338,-80284.48820
81.20001,-2.70673,-80427.46782
81.30000,-2.71020,-80601.84121
81.40000,-2.71337,-80735.78477
81.50001,-2.71689,-80896.78288
81.60001,-2.72024,-81050.03834
81.70001,-2.72347,-81196.96975
81.80000,-2.72676,-81346.72046
81.90000,-2.73023,-81501.16801
82.00001,-2.73346,-81659.09052
82.10001,-2.73674,-81803.53642
82.20001,-2.74021,-81958.35352
82.30000,-2.74362,-82117.61117
82.40000,-2.74673,-82245.15319
82.50001,-2.75020,-82390.67793
82.60001,-2.75361,-82560.99820
82.70001,-2.75665,-82678.61605
82.80000,-2.76012,-82824.06926
82.90000,-2.76371,-83008.79002
83.00001,-2.76676,-83136.34992
83.10001,-2.77023,-83281.45146
83.20001,-2.77352,-83462.39924
83.30000,-2.77668,-83581.63238
83.40000,-2.78015,-83737.85019
83.50001,-2.78368,-83921.50998
83.60001,-2.78685,-84069.47255
83.70001,-2.79014,-84191.32829
83.80000,-2.79366,-84373.43240
83.90000,-2.79677,-84518.43858
84.00001,-2.80000,-84640.55061
84.10001,-2.80359,-84826.17736
84.20001,-2.80688,-85000.90241
84.30000,-2.81011,-85127.59805
84.40000,-2.81351,-85280.04289
84.50001,-2.81680,-85445.90473
84.60001,-2.81997,-85585.85644
84.70001,-2.82332,-85727.38171
84.80000,-2.82691,-85927.49238
84.90000,-2.82996,-86043.85853
85.00001,-2.83354,-86211.06148
85.10001,-2.83701,-86391.04366
85.20001,-2.84024,-86530.74503
85.30000,-2.84347,-86672.43123
85.40000,-2.84682,-86839.86664
85.50001,-2.85011,-86984.24101
85.60001,-2.85345,-87140.57803
85.70001,-2.85692,-87316.73360
85.80000,-2.86027,-87470.98446
85.90000,-2.86362,-87629.26459
86.00001,-2.86679,-87764.01877
86.10001,-2.87008,-87918.60938
86.20001,-2.87354,-88085.08515
86.30000,-2.87671,-88220.92414
86.40000,-2.88030,-88402.71831
86.50001,-2.88341,-88556.09298
86.60001,-2.88694,-88707.69739
86.70001,-2.89028,-88879.38857
86.80000,-2.89339,-89008.97503
86.90000,-2.89674,-89171.37980
87.00001,-2.90015,-89332.47328
87.10001,-2.90338,-89487.95795
87.20001,-2.90679,-89654.97017
87.30000,-2.91025,-89820.71877
87.40000,-2.91348,-89965.74283
87.50001,-2.91683,-90131.88481
87.60001,-2.92012,-90286.55291
87.70001,-2.92335,-90433.12073
87.80000,-2.92682,-90601.18794
87.90000,-2.93016,-90772.84932
88.00001,-2.93339,-90908.90288
88.10001,-2.93692,-91094.26737
88.20001,-2.94015,-91239.32123
88.30000,-2.94344,-91391.64090
88.40000,-2.94679,-91558.78425
88.50001,-2.95031,-91738.76643
88.60001,-2.95348,-91891.49737
88.70001,-2.95683,-92041.09311
88.80000,-2.96030,-92216.16387
88.90000,-2.96347,-92379.48060
89.00001,-2.96664,-92514.15730
89.10001,-2.97028,-92697.12567
89.20001,-2.97357,-92874.98593
89.30000,-2.97668,-93004.50683
89.40000,-2.98015,-93168.62226
89.50001,-2.98368,-93359.94720
89.60001,-2.98661,-93475.56233
89.70001,-2.99019,-93653.11265
89.80000,-2.99336,-93814.62932
89.90000,-2.99665,-93960.56533
90.00001,-3.00024,-94151.92008
90.10001,-3.00371,-94325.61398
90.20001,-3.00675,-94464.10537
90.30000,-3.01010,-94616.12105
90.40000,-3.01357,-94801.57495
90.50001,-3.01668,-94947.12949
90.60001,-3.02009,-95108.26468
90.70001,-3.02373,-95305.72891
90.80000,-3.02690,-95461.60698
90.90000,-3.03013,-95606.87542
91.00001,-3.03348,-95776.36123
91.10001,-3.03671,-95931.06508
91.20001,-3.03982,-96081.54893
91.30000,-3.04346,-96256.95348
91.40000,-3.04687,-96462.02326
91.50001,-3.04998,-96582.78227
91.60001,-3.05363,-96770.41769
91.70001,-3.05686,-96944.19503
91.80000,-3.06009,-97087.33559
91.90000,-3.06343,-97238.75523
92.00001,-3.06684,-97425.71712
92.10001,-3.07019,-97584.37276
92.20001,-3.07354,-97744.29798
92.30000,-3.07689,-97920.15553
92.40000,-3.08018,-98083.53782
92.50001,-3.08340,-98247.58768
92.60001,-3.08669,-98388.86857
92.70001,-3.09004,-98561.63859
92.80000,-3.09357,-98759.48429
92.90000,-3.09686,-98905.44415
93.00001,-3.10032,-99095.25514
93.10001,-3.10343,-99238.04998
93.20001,-3.10690,-99417.03081
93.30000,-3.11007,-99580.83034
93.40000,-3.11342,-99729.00152
93.50001,-3.11689,-99920.92848
93.54401,-3.11838,-100003.39746