File: data/RAW Test Data/Three Point Bend Test Results/Test50-35.is_comp_RawData/CoreEdge50-35.csv
Time,Extension,Load
(sec),(mm),(N)
0.00000,-0.00006,-1.01914
0.10000,-0.01895,0.80960
0.20000,-0.05698,0.10928
0.30000,-0.09524,0.08108
0.40000,-0.13130,-0.30315
0.50000,-0.16586,-0.31373
0.60000,-0.19982,-0.32744
0.70000,-0.23336,-1.89532
0.80000,-0.26672,-1.32543
0.90000,-0.30014,-1.39946
1.00000,-0.33339,-1.46996
1.10000,-0.36681,-1.83931
1.20000,-0.40005,-2.24979
1.30000,-0.43341,-1.64112
1.40000,-0.46666,-2.41469
1.50000,-0.50002,-2.55569
1.60000,-0.53338,-2.74800
1.70000,-0.56663,-2.85337
1.80000,-0.59993,-2.94189
1.90000,-0.63335,-2.78090
2.00000,-0.66665,-3.64299
2.10000,-0.70008,-3.30184
2.20000,-0.73332,-3.66845
2.30000,-0.76662,-3.87094
2.40000,-0.80004,-4.18703
2.50000,-0.83347,-4.10869
2.60000,-0.86671,-4.76749
2.70000,-0.90007,-4.30140
2.80000,-0.93337,-5.06125
2.90000,-0.96668,-4.95589
3.00000,-0.99992,-5.20030
3.10000,-1.03334,-5.59393
3.20000,-1.06670,-5.72671
3.30000,-1.09995,-6.31893
3.40000,-1.13337,-6.05925
3.50000,-1.16667,-6.35614
3.60000,-1.19992,-6.53200
3.70000,-1.23346,-6.39413
3.80000,-1.26670,-7.18454
3.90000,-1.29994,-7.07291
4.00000,-1.33331,-7.16065
4.10000,-1.36667,-7.67413
4.20000,-1.40009,-7.26679
4.30000,-1.43333,-8.05719
4.40000,-1.46676,-7.96554
4.50000,-1.50006,-7.89661
4.60000,-1.53342,-8.24285
4.70000,-1.56672,-8.48804
4.80000,-1.60003,-9.12922
4.90000,-1.63333,-9.10454
5.00000,-1.66669,-8.91654
5.10000,-1.69999,-9.12413
5.20000,-1.73336,-9.07477
5.30000,-1.76672,-9.76844
5.40000,-1.80002,-9.75825
5.50000,-1.83333,-10.26822
5.60000,-1.86651,-9.92746
5.70000,-1.90005,-10.93054
5.80000,-1.93329,-10.19027
5.90000,-1.96666,-10.53221
6.00000,-2.00002,-11.32418
6.10000,-2.03332,-11.55958
6.20000,-2.06668,-11.11306
6.30000,-2.10005,-11.87174
6.40000,-2.13329,-12.08834
6.50000,-2.16665,-12.15924
6.60000,-2.19995,-12.19292
6.70000,-2.23332,-12.38014
6.80000,-2.26668,-12.88423
6.90000,-2.29992,-12.68722
7.00000,-2.33329,-12.83958
7.10000,-2.36665,-13.61001
7.20000,-2.39995,-13.12394
7.30000,-2.43325,-12.74558
7.40000,-2.46656,-13.67425
7.50000,-2.49992,-13.98485
7.60000,-2.53328,-13.56340
7.70000,-2.56658,-14.76154
7.80000,-2.60007,-14.89393
7.90000,-2.63325,-14.39258
8.00000,-2.66667,-14.63307
8.10000,-2.70003,-14.71180
8.20000,-2.73334,-15.47048
8.30000,-2.76658,-15.81672
8.40000,-2.80000,-15.68708
8.50000,-2.83336,-15.58798
8.60000,-2.86673,-16.71327
8.70000,-2.90003,-15.50886
8.80000,-2.93345,-16.40776
8.90000,-2.96664,-16.47082
9.00000,-3.00006,-16.82098
9.10000,-3.03306,-16.70113
9.20000,-3.06660,-16.89893
9.30000,-3.10009,-17.47039
9.40000,-3.13339,-17.68189
9.50000,-3.16681,-18.04419
9.60000,-3.20005,-17.80723
9.70000,-3.23330,-17.10730
9.80000,-3.26666,-19.23842
9.90000,-3.30002,-18.19656
10.00000,-3.33338,-18.27959
10.10000,-3.36669,-17.87891
10.20000,-3.39987,-17.91220
10.30000,-3.43329,-18.90275
10.40000,-3.46671,-18.95406
10.50000,-3.50014,-19.44131
10.60000,-3.53344,-20.41619
10.70000,-3.56668,-20.39700
10.80000,-3.59993,-20.16944
10.90000,-3.63323,-20.23446
11.00000,-3.66659,-20.59441
11.10000,-3.69995,-21.22814
11.20000,-3.73332,-20.68567
11.30000,-3.76668,-21.11965
11.40000,-3.80010,-21.08205
11.50000,-3.83334,-21.13257
11.60000,-3.86671,-21.43299
11.70000,-3.90001,-22.14623
11.80000,-3.93337,-21.85208
11.90000,-3.96661,-21.73576
12.00000,-3.99998,-21.76944
12.10000,-4.03328,-22.66521
12.20000,-4.06658,-22.39848
12.30000,-4.10001,-22.43451
12.40000,-4.13337,-22.52773
12.50000,-4.16673,-23.37924
12.60000,-4.19997,-23.33458
12.70000,-4.23328,-22.99774
12.80000,-4.26664,-23.04553
12.90000,-4.29994,-23.52886
13.00000,-4.33330,-23.56254
13.10000,-4.36661,-23.87980
13.20000,-4.39997,-23.40783
13.30000,-4.43333,-24.09444
13.40000,-4.46681,-24.27657
13.50000,-4.50006,-24.71368
13.60000,-4.53336,-24.12851
13.70000,-4.56660,-23.96205
13.80000,-4.59997,-25.34742
13.90000,-4.63333,-24.56954
14.00000,-4.66663,-24.86174
14.10000,-4.69999,-25.21425
14.20000,-4.73336,-25.52289
14.30000,-4.76666,-25.58477
14.40000,-4.80002,-25.65684
14.50000,-4.83332,-26.11080
14.60000,-4.86675,-26.71790
14.70000,-4.89999,-26.28353
14.80000,-4.93329,-26.50012
14.90000,-4.96665,-27.13268
15.00000,-4.99990,-27.43193
15.10000,-5.03332,-27.27604
15.20000,-5.06674,-27.06453
15.30000,-5.10010,-27.48558
15.40000,-5.13341,-28.46596
15.50000,-5.16665,-27.91721
15.60000,-5.19995,-28.68490
15.70000,-5.23332,-27.45817
15.80000,-5.26662,-28.85920
15.90000,-5.29998,-28.18473
16.00000,-5.33328,-29.01626
16.10000,-5.36677,-27.87256
16.20000,-5.40007,-29.51095
16.30000,-5.43331,-29.37856
16.40000,-5.46667,-29.51369
16.50000,-5.50004,-30.02170
16.60000,-5.53340,-30.46900
16.70000,-5.56664,-29.16862
16.80000,-5.59988,-30.83286
16.90000,-5.63325,-29.91085
17.00000,-5.66661,-30.92452
17.10000,-5.69997,-30.19952
17.20000,-5.73339,-30.72006
17.30000,-5.76664,-30.57553
17.40000,-5.80000,-31.28564
17.50000,-5.83336,-31.17088
17.60000,-5.86667,-31.47639
17.70000,-5.89997,-31.12505
17.80000,-5.93321,-32.11287
17.90000,-5.96651,-31.66909
18.00000,-6.00006,-32.34552
18.10000,-6.03342,-33.13514
18.20000,-6.06672,-32.93656
18.30000,-6.10008,-33.00589
18.40000,-6.13339,-33.30944
18.50000,-6.16669,-33.96472
18.60000,-6.19987,-32.35414
18.70000,-6.23317,-33.86758
18.80000,-6.26654,-33.92751
18.90000,-6.29996,-33.50215
19.00000,-6.33326,-34.48095
19.10000,-6.36668,-34.77510
19.20000,-6.40005,-35.05672
19.30000,-6.43341,-34.10925
19.40000,-6.46671,-35.02303
19.50000,-6.50008,-34.67365
19.60000,-6.53332,-35.18009
19.70000,-6.56668,-34.87654
19.80000,-6.60010,-35.15268
19.90000,-6.63335,-35.23532
20.00000,-6.66653,-35.71983
20.10000,-6.69989,-36.18005
20.20000,-6.73331,-36.10328
20.30000,-6.76668,-36.23331
20.40000,-6.79998,-36.72761
20.50000,-6.83328,-36.32653
20.60000,-6.86658,-36.83219
20.70000,-6.89995,-36.68805
20.80000,-6.93325,-37.25755
20.90000,-6.96661,-37.51998
21.00000,-6.99998,-37.77065
21.10000,-7.03328,-37.44164
21.20000,-7.06664,-37.48708
21.30000,-7.10006,-37.77378
21.40000,-7.13331,-38.00918
21.50000,-7.16661,-38.41614
21.60000,-7.19991,-38.14353
21.70000,-7.23333,-38.97310
21.80000,-7.26664,-38.60218
21.90000,-7.30000,-38.75298
22.00000,-7.33336,-39.32679
22.10000,-7.36666,-39.33266
22.20000,-7.39997,-39.28057
22.30000,-7.43339,-39.52576
22.40000,-7.46675,-39.35655
22.50000,-7.49999,-39.13212
22.60000,-7.53330,-39.73844
22.70000,-7.56660,-39.87200
22.80000,-7.59990,-40.49085
22.90000,-7.63327,-40.92757
23.00000,-7.66663,-40.98750
23.10000,-7.69999,-41.44576
23.20000,-7.73341,-41.05604
23.30000,-7.76672,-41.22486
23.40000,-7.79990,-41.70309
23.50000,-7.83326,-41.92792
23.60000,-7.86674,-41.29928
23.70000,-7.89999,-41.64591
23.80000,-7.93335,-42.45590
23.90000,-7.96659,-42.78295
24.00000,-7.99995,-42.50016
24.10000,-8.03332,-42.11475
24.20000,-8.06662,-42.92474
24.30000,-8.09998,-42.56283
24.40000,-8.13329,-42.97096
24.50000,-8.16671,-42.58006
24.60000,-8.20001,-43.53771
24.70000,-8.23337,-43.05007
24.80000,-8.26674,-43.19029
24.90000,-8.29998,-43.69869
25.00000,-8.33346,-41.04586
25.10000,-8.36676,-41.87073
25.20000,-8.40007,-41.98315
25.30000,-8.43343,-41.63259
25.40000,-8.46673,-41.89502
25.50000,-8.49997,-42.50447
25.60000,-8.53328,-42.68268
25.70000,-8.56664,-42.94393
25.80000,-8.59994,-42.50290
25.90000,-8.63336,-42.85384
26.00000,-8.66673,-43.40689
26.10000,-8.70003,-44.23686
26.20000,-8.73333,-43.42608
26.30000,-8.76664,-43.34109
26.40000,-8.80006,-43.67441
26.50000,-8.83342,-44.15539
26.60000,-8.86672,-43.68107
26.70000,-8.89997,-44.24783
26.80000,-8.93327,-43.98031
26.90000,-8.96669,-43.73199
27.00000,-9.00005,-44.77385
27.10000,-9.03330,-45.16357
27.20000,-9.06672,-44.50007
27.30000,-9.09996,-44.95245
27.40000,-9.13338,-44.60112
27.50000,-9.16663,-45.19529
27.60000,-9.20005,-45.14516
27.70000,-9.23329,-45.78868
27.80000,-9.26665,-46.00097
27.90000,-9.29996,-45.00768
28.00000,-9.33332,-46.07970
28.10000,-9.36668,-46.25831
28.20000,-9.39999,-45.99745
28.30000,-9.43329,-44.17341
28.40000,-9.46665,-45.54624
28.50000,-9.49995,-45.60499
28.60000,-9.53332,-44.58232
28.70000,-9.56662,-45.92695
28.80000,-9.60004,-46.17762
28.90000,-9.63340,-46.43730
29.00000,-9.66665,-45.63632
29.10000,-9.70007,-45.96964
29.20000,-9.73331,-46.05972
29.30000,-9.76674,-46.43417
29.40000,-9.80010,-46.39344
29.50000,-9.83340,-47.21282
29.60000,-9.86670,-46.70952
29.70000,-9.90006,-46.12631
29.80000,-9.93331,-47.33307
29.90000,-9.96661,-46.66526
30.00000,-9.99991,-46.90614
30.10000,-10.03322,-47.71182
30.20000,-10.06664,-47.32367
30.30000,-10.10000,-47.69459
30.40000,-10.13330,-48.01302
30.50000,-10.16661,-47.87280
30.60000,-10.19997,-48.06864
30.70000,-10.23339,-47.82462
30.80000,-10.26663,-48.14110
30.90000,-10.29994,-47.77880
31.00000,-10.33330,-48.76544
31.10000,-10.36660,-48.57547
31.20000,-10.40003,-49.26052
31.30000,-10.43333,-49.45440
31.40000,-10.46657,-48.41332
31.50000,-10.49993,-48.96990
31.60000,-10.53342,-49.17631
31.70000,-10.56678,-49.56328
31.80000,-10.60002,-49.19354
31.90000,-10.63332,-49.54723
32.00000,-10.66663,-49.93577
32.10000,-10.70011,-49.96515
32.20000,-10.73341,-50.27496
32.30000,-10.76665,-49.89739
32.40000,-10.80008,-49.99687
32.50000,-10.83332,-50.16490
32.60000,-10.86650,-49.91266
32.70000,-10.89999,-50.06424
32.80000,-10.93329,-50.47629
32.90000,-10.96677,-50.23305
33.00000,-11.00001,-50.87501
33.10000,-11.03338,-50.68113
33.20000,-11.06668,-50.32118
33.30000,-11.10004,-50.71246
33.40000,-11.13334,-51.85147
33.50000,-11.16671,-51.39320
33.60000,-11.20007,-50.97841
33.70000,-11.23331,-51.97367
33.80000,-11.26661,-51.55536
33.90000,-11.29992,-51.24084
34.00000,-11.33334,-51.96466
34.10000,-11.36664,-52.52476
34.20000,-11.39994,-52.31208
34.30000,-11.43331,-51.79546
34.40000,-11.46679,-51.84442
34.50000,-11.50009,-52.14366
34.60000,-11.53333,-53.09700
34.70000,-11.56658,-52.94385
34.80000,-11.59994,-53.61910
34.90000,-11.63342,-52.63130
35.00000,-11.66667,-52.57254
35.10000,-11.70009,-53.42953
35.20000,-11.73339,-53.25132
35.30000,-11.76669,-53.17064
35.40000,-11.80000,-53.30185
35.50000,-11.83330,-53.09739
35.60000,-11.86660,-53.79106
35.70000,-11.89990,-53.64417
35.80000,-11.93327,-54.29123
35.90000,-11.96669,-53.91169
36.00000,-11.99999,-54.23091
36.10000,-12.03341,-54.89950
36.20000,-12.06684,-54.31238
36.30000,-12.10008,-53.98690
36.40000,-12.13338,-54.96530
36.50000,-12.16669,-54.89402
36.60000,-12.19999,-53.92187
36.70000,-12.23329,-55.59708
36.80000,-12.26665,-55.24653
36.90000,-12.30002,-55.17211
37.00000,-12.33332,-55.64212
37.10000,-12.36662,-55.53206
37.20000,-12.39998,-54.63865
37.30000,-12.43341,-55.69030
37.40000,-12.46671,-54.90616
37.50000,-12.49995,-55.81485
37.60000,-12.53325,-56.22925
37.70000,-12.56668,-55.77020
37.80000,-12.60010,-56.37691
37.90000,-12.63340,-55.83091
38.00000,-12.66671,-56.67772
38.10000,-12.70007,-56.90685
38.20000,-12.73343,-56.82068
38.30000,-12.76667,-56.39062
38.40000,-12.79998,-57.24644
38.50000,-12.83322,-56.72864
38.60000,-12.86652,-57.69451
38.70000,-12.90000,-57.47831
38.80000,-12.93337,-56.68830
38.90000,-12.96673,-57.60365
39.00000,-13.00009,-57.23507
39.10000,-13.03333,-57.22528
39.20000,-13.06676,-56.98244
39.30000,-13.10000,-57.68590
39.40000,-13.13330,-58.10068
39.50000,-13.16660,-58.02744
39.60000,-13.20003,-58.19116
39.70000,-13.23333,-58.32080
39.80000,-13.26663,-55.61940
39.90000,-13.30000,-56.65187
40.00000,-13.33336,-57.29931
40.10000,-13.36672,-57.21079
40.20000,-13.40014,-57.76658
40.30000,-13.43339,-57.51787
40.40000,-13.46669,-57.41838
40.50000,-13.49999,-57.95224
40.60000,-13.53335,-58.24561
40.70000,-13.56666,-57.88800
40.80000,-13.59996,-58.11282
40.90000,-13.63326,-57.85040
41.00000,-13.66662,-58.70779
41.10000,-13.70005,-58.43087
41.20000,-13.73335,-59.02975
41.30000,-13.76665,-58.44301
41.40000,-13.80007,-58.05446
41.50000,-13.83344,-58.77163
41.60000,-13.86668,-58.89892
41.70000,-13.89998,-58.63689
41.80000,-13.93329,-59.52404
41.90000,-13.96671,-59.37990
42.00000,-14.00007,-59.24321
42.10000,-14.03331,-59.56869
42.20000,-14.06668,-60.30074
42.30000,-14.09998,-59.86049
42.40000,-14.13334,-59.13354
42.50000,-14.16664,-59.50132
42.60000,-14.19995,-60.27998
42.70000,-14.23331,-55.86733
42.80000,-14.26667,-57.74857
42.90000,-14.30009,-57.63654
43.00000,-14.33346,-57.76815
43.10000,-14.36664,-58.00825
43.20000,-14.40006,-57.75758
43.30000,-14.43342,-58.18959
43.40000,-14.46661,-58.45790
43.50000,-14.50003,-57.95772
43.60000,-14.53339,-58.54641
43.70000,-14.56664,-59.04149
43.80000,-14.60000,-58.96041
43.90000,-14.63336,-58.80649
44.00000,-14.66672,-59.80213
44.10000,-14.70009,-59.13902
44.20000,-14.73333,-59.49035
44.30000,-14.76657,-59.19934
44.40000,-14.80005,-60.07357
44.50000,-14.83336,-59.55498
44.60000,-14.86654,-59.61374
44.70000,-14.89996,-59.65486
44.80000,-14.93344,-60.05202
44.90000,-14.96675,-59.39518
45.00000,-14.99999,-59.82563
45.10000,-15.03335,-59.86833
45.20000,-15.06671,-60.32228
45.30000,-15.10008,-60.15151
45.40000,-15.13332,-60.22279
45.50000,-15.16662,-60.11704
45.60000,-15.19993,-60.82284
45.70000,-15.23335,-60.34265
45.80000,-15.26671,-60.79269
45.90000,-15.29995,-60.27920
46.00000,-15.33326,-60.90118
46.10000,-15.36668,-61.26701
46.20000,-15.39992,-61.11190
46.30000,-15.43340,-61.31166
46.40000,-15.46653,-61.63557
46.50000,-15.49995,-61.28894
46.60000,-15.53319,-61.58426
46.70000,-15.56662,-61.67200
46.80000,-15.59980,-61.30030
46.90000,-15.63304,-61.75817
47.00000,-15.66664,-62.02295
47.10000,-15.70007,-61.40174
47.20000,-15.73331,-62.40209
47.30000,-15.76673,-62.28380
47.40000,-15.80009,-62.13575
47.50000,-15.83340,-61.47890
47.60000,-15.86676,-62.01119
47.70000,-15.90006,-62.43224
47.80000,-15.93336,-62.79181
47.90000,-15.96673,-62.25834
48.00000,-16.00021,-62.52507
48.10000,-16.03339,-62.99235
48.20000,-16.06681,-63.11259
48.30000,-16.10006,-62.33159
48.40000,-16.13318,-63.00214
48.50000,-16.16672,-62.68684
48.60000,-16.20003,-63.37776
48.70000,-16.23333,-63.80900
48.80000,-16.26675,-63.56654
48.90000,-16.29999,-62.87954
49.00000,-16.33342,-62.93359
49.10000,-16.36672,-64.41649
49.20000,-16.39990,-63.38089
49.30000,-16.43338,-63.94765
49.40000,-16.46663,-63.64214
49.50000,-16.50005,-63.95313
49.60000,-16.53341,-64.33815
49.70000,-16.56665,-64.72826
49.80000,-16.59996,-63.81487
49.90000,-16.63332,-64.19793
50.00000,-16.66662,-64.23240
50.10000,-16.69998,-64.20498
50.20000,-16.73329,-64.60018
50.30000,-16.76677,-63.71460
50.40000,-16.80007,-64.62486
50.50000,-16.83326,-64.78584
50.60000,-16.86662,-64.72591
50.70000,-16.89998,-64.15054
50.80000,-16.93334,-65.25037
50.90000,-16.96665,-64.57081
51.00000,-17.00001,-64.56493
51.10000,-17.03331,-64.39103
51.20000,-17.06661,-64.59157
51.30000,-17.09998,-63.93629
51.40000,-17.13334,-65.05179
51.50000,-17.16676,-65.00596
51.60000,-17.20006,-65.19279
51.70000,-17.23337,-64.85634
51.80000,-17.26655,-65.26721
51.90000,-17.30003,-64.28958
52.00000,-17.33340,-65.06706
52.10000,-17.36664,-65.75172
52.20000,-17.40006,-66.24601
52.30000,-17.43336,-65.47950
52.40000,-17.46673,-65.62755
52.50000,-17.50003,-65.34006
52.60000,-17.53327,-65.77483
52.70000,-17.56669,-64.87201
52.80000,-17.60000,-65.14462
52.90000,-17.63330,-64.59783
53.00000,-17.66654,-65.20689
53.10000,-17.69990,-65.26838
53.20000,-17.73327,-65.76464
53.30000,-17.76657,-65.84611
53.40000,-17.80011,-64.93115
53.50000,-17.83323,-65.45717
53.60000,-17.86660,-65.64479
53.70000,-17.90008,-65.23705
53.80000,-17.93338,-65.36357
53.90000,-17.96663,-64.82187
54.00000,-18.00005,-64.80895
54.10000,-18.03335,-65.06980
54.20000,-18.06671,-65.56332
54.30000,-18.09996,-65.12973
54.40000,-18.13326,-65.11563
54.50000,-18.16674,-65.25507
54.60000,-18.19998,-65.58408
54.70000,-18.23347,-64.88533
54.80000,-18.26671,-64.92606
54.90000,-18.30001,-64.71220
55.00000,-18.33337,-63.06794
55.10000,-18.36662,-0.47745
55.20000,-18.39998,-1.75941
55.30000,-18.43340,-2.23412
55.40000,-18.46665,-1.94898
55.50000,-18.49995,-0.93336
55.60000,-18.53331,-2.11544
55.70000,-18.56667,-1.92352
55.80000,-18.59992,-2.01361
55.90000,-18.63334,-1.82560
56.00000,-18.66676,-2.12719
56.10000,-18.70006,-2.36729
56.20000,-18.73343,-1.89571
56.30000,-18.76667,-2.31481
56.40000,-18.79997,-2.37787
56.50000,-18.83339,-2.23295
56.60000,-18.86670,-1.69870
56.70000,-18.90006,-1.40494
56.80000,-18.93318,-1.67246
56.90000,-18.96655,-2.58820
57.00000,-18.99985,-2.13072
57.10000,-19.03327,-2.54786
57.20000,-19.06663,-2.60661
57.30000,-19.10005,-2.12915
57.40000,-19.13330,-2.07118
57.50000,-19.16672,-2.09312
57.60000,-19.19990,-2.20866
57.70000,-19.23321,-2.02771
57.80000,-19.26663,-1.84558
57.90000,-19.29999,-2.46051
58.00000,-19.33341,-1.47388
58.10000,-19.36672,-2.10761
58.20000,-19.39996,-2.94110
58.30000,-19.43338,-1.91451
58.40000,-19.46668,-2.85885
58.50000,-19.49999,-2.42252
58.60000,-19.53347,-2.68142
58.70000,-19.56671,-2.55491
58.80000,-19.60007,-1.99128
58.90000,-19.63338,-2.14991
59.00000,-19.66680,-1.90433
59.10000,-19.70010,-1.62976
59.20000,-19.73329,-2.61209
59.30000,-19.76677,-2.42409
59.40000,-19.80001,-2.22276
59.50000,-19.83337,-1.69909
59.60000,-19.86668,-1.85850
59.70000,-19.89992,-2.51691
59.80000,-19.93328,-2.38648
59.90000,-19.96676,-2.83261
60.00000,-20.00013,-2.07745
60.10000,-20.03337,-3.26188
60.20000,-20.06667,-2.32656
60.30000,-20.09998,-2.84397
60.40000,-20.13322,-2.57018
60.50000,-20.16664,-2.54159
60.60000,-20.20000,-2.36181
60.70000,-20.23330,-2.61052
60.74400,-20.24801,-2.42409