File: data/crush/Crushfull.is_comp_RawData/CoreFull.csv
Time,Extension,Load
(sec),(mm),(N)
0.00000,-0.00006,-10.84143
0.10000,-0.00102,-8.92769
0.20000,-0.00466,-9.17993
0.30000,-0.00897,-9.28255
0.40000,-0.01279,-10.13289
0.50000,-0.01638,-9.83051
0.60000,-0.01985,-10.54963
0.70000,-0.02326,-9.72358
0.80000,-0.02661,-9.32525
0.90000,-0.03007,-9.60804
1.00000,-0.03330,-9.83404
1.10000,-0.03665,-9.87986
1.20000,-0.04006,-9.97896
1.30000,-0.04323,-9.42473
1.40000,-0.04664,-9.29195
1.50000,-0.05004,-10.57822
1.60000,-0.05333,-10.42429
1.70000,-0.05668,-10.00167
1.80000,-0.06009,-10.13406
1.90000,-0.06326,-9.88182
2.00000,-0.06667,-10.08549
2.10000,-0.07001,-9.84422
2.20000,-0.07324,-9.57122
2.30000,-0.07665,-9.89436
2.40000,-0.08012,-10.83751
2.50000,-0.08329,-10.25196
2.60000,-0.08663,-10.70082
2.70000,-0.09004,-10.28956
2.80000,-0.09333,-10.45994
2.90000,-0.09656,-9.85949
3.00000,-0.10009,-10.95619
3.10000,-0.10338,-10.80070
3.20000,-0.10660,-10.26527
3.30000,-0.11001,-10.23864
3.40000,-0.11336,-10.93818
3.50000,-0.11659,-10.80618
3.60000,-0.12000,-11.37685
3.70000,-0.12341,-11.20687
3.80000,-0.12663,-11.72976
3.90000,-0.13004,-11.41681
4.00000,-0.13339,-11.64163
4.10000,-0.13656,-11.66160
4.20000,-0.14003,-12.18841
4.30000,-0.14344,-12.82528
4.40000,-0.14666,-12.44574
4.50000,-0.15007,-12.08422
4.60000,-0.15348,-13.09279
4.70000,-0.15665,-13.43825
4.80000,-0.15994,-13.13392
4.90000,-0.16334,-14.22474
5.00000,-0.16663,-14.15385
5.10000,-0.16992,-14.82558
5.20000,-0.17345,-16.09148
5.30000,-0.17674,-15.69588
5.40000,-0.17991,-16.00100
5.50000,-0.18325,-17.13883
5.60000,-0.18666,-17.21599
5.70000,-0.18989,-18.60018
5.80000,-0.19330,-19.07606
5.90000,-0.19683,-20.05565
6.00000,-0.19994,-20.53937
6.10000,-0.20334,-22.03558
6.20000,-0.20675,-22.30310
6.30000,-0.20998,-23.38099
6.40000,-0.21327,-24.42638
6.50000,-0.21674,-25.78159
6.60000,-0.22003,-27.22374
6.70000,-0.22337,-28.60323
6.80000,-0.22678,-30.04696
6.90000,-0.23001,-32.11384
7.00000,-0.23330,-33.24696
7.10000,-0.23665,-35.10313
7.20000,-0.23994,-35.95072
7.30000,-0.24334,-38.68698
7.40000,-0.24669,-41.64962
7.50000,-0.25010,-43.60802
7.60000,-0.25327,-45.85546
7.70000,-0.25668,-49.92068
7.80000,-0.26002,-53.00945
7.90000,-0.26325,-54.72697
8.00000,-0.26666,-55.04187
8.10000,-0.27007,-55.46293
8.20000,-0.27330,-59.15958
8.30000,-0.27665,-63.82093
8.40000,-0.28005,-70.33963
8.50000,-0.28328,-75.56617
8.60000,-0.28663,-82.20903
8.70000,-0.29004,-91.37272
8.80000,-0.29327,-102.01304
8.90000,-0.29668,-114.86751
9.00000,-0.30008,-130.66152
9.10000,-0.30325,-147.41436
9.20000,-0.30666,-167.66997
9.30000,-0.31007,-191.74601
9.40000,-0.31330,-218.46588
9.50000,-0.31665,-248.80525
9.60000,-0.32011,-284.30063
9.70000,-0.32328,-322.46688
9.80000,-0.32651,-361.85752
9.90000,-0.32998,-409.48200
10.00000,-0.33333,-459.17416
10.10000,-0.33650,-511.11653
10.20000,-0.34002,-570.72868
10.30000,-0.34337,-635.26621
10.40000,-0.34654,-698.20019
10.50000,-0.34995,-767.82485
10.60000,-0.35336,-844.64066
10.70000,-0.35647,-918.85850
10.80000,-0.35999,-1001.53545
10.90000,-0.36340,-1090.19522
11.00000,-0.36663,-1176.40896
11.10000,-0.36998,-1269.32822
11.20000,-0.37339,-1367.68119
11.30000,-0.37655,-1461.89267
11.40000,-0.37990,-1562.24910
11.50000,-0.38337,-1669.50617
11.60000,-0.38660,-1771.59701
11.70000,-0.38995,-1881.80171
11.80000,-0.39341,-1998.43012
11.90000,-0.39664,-2113.19719
12.00000,-0.39987,-2227.12588
12.10000,-0.40328,-2349.54488
12.20000,-0.40663,-2475.45820
12.30000,-0.40980,-2594.47191
12.40000,-0.41338,-2727.98315
12.50000,-0.41667,-2865.72129
12.60000,-0.41984,-2986.25771
12.70000,-0.42331,-3121.72733
12.80000,-0.42660,-3260.31223
12.90000,-0.42989,-3395.71200
13.00000,-0.43323,-3530.62004
13.10000,-0.43670,-3679.53926
13.20000,-0.43993,-3823.78064
13.30000,-0.44328,-3971.05478
13.40000,-0.44663,-4125.27844
13.50000,-0.44986,-4273.85904
13.60000,-0.45320,-4428.46045
13.70000,-0.45661,-4586.84340
13.80000,-0.45990,-4743.84017
13.90000,-0.46331,-4910.05257
14.00000,-0.46660,-5074.17098
14.10000,-0.46995,-5244.73824
14.20000,-0.47317,-5403.41996
14.30000,-0.47664,-5583.86892
14.40000,-0.47987,-5755.33845
14.50000,-0.48328,-5928.42475
14.60000,-0.48669,-6113.32320
14.70000,-0.48992,-6293.30650
14.80000,-0.49314,-6468.89880
14.90000,-0.49661,-6655.97171
15.00000,-0.49990,-6842.98128
15.10000,-0.50319,-7027.61263
15.20000,-0.50666,-7222.10407
15.30000,-0.50994,-7414.14353
15.40000,-0.51317,-7602.12094
15.50000,-0.51658,-7805.25208
15.60000,-0.51999,-8007.17101
15.70000,-0.52322,-8179.40608
15.80000,-0.52663,-8391.00480
15.90000,-0.53003,-8598.60629
16.00000,-0.53326,-8801.46101
16.10000,-0.53661,-9010.01394
16.20000,-0.54002,-9230.74633
16.30000,-0.54319,-9432.32030
16.40000,-0.54654,-9643.79832
16.50000,-0.54994,-9865.98581
16.60000,-0.55323,-10080.93879
16.70000,-0.55658,-10293.01360
16.80000,-0.55999,-10523.47496
16.90000,-0.56322,-10739.36820
17.00000,-0.56645,-10949.76142
17.10000,-0.56991,-11180.89855
17.20000,-0.57326,-11409.01893
17.30000,-0.57649,-11612.02863
17.40000,-0.58002,-11858.00582
17.50000,-0.58331,-12086.39443
17.60000,-0.58648,-12302.72576
17.70000,-0.58994,-12533.95528
17.80000,-0.59329,-12772.35448
17.90000,-0.59646,-12987.19049
18.00000,-0.59987,-13214.18434
18.10000,-0.60334,-13457.06135
18.20000,-0.60650,-13683.50685
18.30000,-0.60985,-13920.47107
18.40000,-0.61332,-14166.75299
18.50000,-0.61649,-14395.15054
18.60000,-0.61984,-14628.54147
18.70000,-0.62331,-14872.81919
18.80000,-0.62653,-15112.36578
18.90000,-0.62982,-15346.90857
18.99800,-0.63329,-15597.99016
19.09800,-0.63646,-15835.69646
19.19800,-0.63969,-16066.33663
19.29400,-0.64310,-16316.38855
19.39400,-0.64638,-16557.39695
19.49400,-0.64967,-16794.11829
19.59200,-0.65302,-17047.96106
19.69200,-0.65625,-17300.39418
19.79200,-0.65948,-17532.71967
19.88800,-0.66283,-17783.67162
19.98400,-0.66606,-18034.45816
20.08400,-0.66934,-18277.05950
20.18400,-0.67269,-18531.24946
20.28000,-0.67592,-18786.07869
20.38000,-0.67921,-19039.07210
20.47600,-0.68244,-19290.15964
20.57400,-0.68573,-19540.27861
20.66600,-0.68878,-19791.33040
20.76600,-0.69200,-20039.84004
20.85800,-0.69523,-20289.93517
20.94800,-0.69816,-20540.84390
21.04600,-0.70133,-20796.19467
21.13800,-0.70450,-21050.73184
21.23400,-0.70767,-21304.14844
21.33000,-0.71078,-21555.10783
21.42400,-0.71401,-21809.14730
21.51600,-0.71718,-22062.94239
21.61400,-0.72028,-22314.14765
21.70400,-0.72333,-22568.34656
21.79200,-0.72632,-22820.50848
21.89000,-0.72949,-23074.46003
21.98600,-0.73260,-23325.41645
22.07200,-0.73565,-23578.50224
22.16400,-0.73870,-23832.74585
22.26200,-0.74193,-24085.60961
22.35200,-0.74498,-24339.42556
22.44200,-0.74797,-24591.07339
22.53200,-0.75096,-24843.47373
22.62600,-0.75407,-25094.69688
22.71600,-0.75711,-25345.03937
22.80400,-0.76004,-25596.70210
22.90000,-0.76315,-25848.81783
22.99400,-0.76632,-26100.87693
23.08400,-0.76937,-26352.45323
23.17400,-0.77230,-26603.08480
23.26600,-0.77535,-26856.17208
23.35200,-0.77834,-27108.34146
23.44400,-0.78133,-27362.34069
23.54000,-0.78438,-27614.94219
23.62800,-0.78743,-27866.44399
23.71400,-0.79048,-28116.96529
23.81000,-0.79341,-28367.49554
23.90200,-0.79652,-28620.85700
23.98200,-0.79939,-28872.50483
24.07400,-0.80232,-29122.85030
24.16800,-0.80536,-29374.84682
24.25400,-0.80835,-29627.10559
24.34000,-0.81134,-29878.07393
24.43400,-0.81427,-30129.01545
24.53000,-0.81744,-30384.43625
24.61200,-0.82031,-30634.92775
24.69800,-0.82312,-30889.09984
24.79200,-0.82617,-31139.43934
24.88200,-0.82928,-31393.05413
24.96600,-0.83221,-31646.68083
25.05800,-0.83514,-31899.35982
25.15200,-0.83819,-32150.25067
25.24000,-0.84118,-32404.93536
25.32600,-0.84411,-32660.04324
25.41600,-0.84698,-32911.18741
25.51000,-0.85015,-33166.50987
25.59600,-0.85326,-33422.74129
25.69200,-0.85619,-33676.69880
25.78400,-0.85929,-33928.12312
25.86600,-0.86216,-34179.72326
25.95600,-0.86503,-34433.74336
26.04600,-0.86802,-34684.35109
26.13400,-0.87101,-34938.87484
26.22200,-0.87400,-35192.91282
26.31600,-0.87699,-35444.41164
26.40400,-0.87992,-35696.58995
26.48800,-0.88279,-35947.36457
26.57400,-0.88560,-36197.87097
26.66600,-0.88865,-36450.51420
26.75400,-0.89158,-36704.93364
26.84200,-0.89463,-36960.30378
26.93200,-0.89756,-37210.62243
27.02000,-0.90055,-37463.32526
27.11000,-0.90348,-37714.11180
27.19600,-0.90647,-37969.48493
27.28600,-0.90940,-38224.35141
27.38200,-0.91251,-38475.30484
27.46400,-0.91544,-38731.25315
27.55200,-0.91825,-38985.52358
27.64600,-0.92136,-39238.15489
27.73400,-0.92435,-39489.55536
27.82000,-0.92722,-39740.50581
27.91000,-0.93015,-39991.85562
28.00200,-0.93325,-40247.10059
28.09000,-0.93624,-40497.84541
28.18000,-0.93911,-40752.84600
28.26600,-0.94204,-41005.51605
28.35200,-0.94497,-41259.86099
28.44400,-0.94796,-41514.93907
28.53400,-0.95089,-41765.74647
28.62200,-0.95388,-42021.17920
28.70400,-0.95669,-42271.79587
28.79800,-0.95962,-42526.85905
28.88200,-0.96255,-42777.04656
28.96200,-0.96524,-43028.95069
29.05000,-0.96829,-43284.70528
29.14000,-0.97122,-43539.44659
29.22800,-0.97409,-43790.54904
29.31200,-0.97702,-44043.41877
29.40000,-0.97989,-44298.16306
29.49400,-0.98288,-44553.59280
29.58200,-0.98587,-44809.33845
29.66400,-0.98874,-45065.03940
29.75200,-0.99161,-45316.73193
29.84600,-0.99472,-45568.45129
29.92800,-0.99759,-45822.45648
30.01200,-1.00040,-46073.20428
30.10800,-1.00339,-46326.42865
30.20000,-1.00644,-46578.18973
30.28200,-1.00937,-46830.17731
30.36600,-1.01200,-47080.86252
30.46200,-1.01517,-47336.08067
30.54200,-1.01804,-47588.60767
30.63400,-1.02097,-47843.36090
30.72600,-1.02401,-48097.29457
30.81000,-1.02694,-48347.29731
30.89800,-1.02993,-48599.86305
30.98800,-1.03274,-48851.27544
31.08400,-1.03585,-49105.33428
31.16400,-1.03872,-49358.72853
31.25000,-1.04159,-49609.36308
31.34600,-1.04464,-49864.88223
31.43200,-1.04757,-50116.02640
31.51400,-1.05044,-50368.31498
31.60200,-1.05325,-50620.44859
31.69600,-1.05624,-50871.58680
31.78200,-1.05917,-51127.44570
31.86600,-1.06210,-51381.00386
31.95600,-1.06503,-51631.98709
32.05200,-1.06808,-51885.56910
32.13400,-1.07107,-52141.50548
32.21200,-1.07370,-52393.60332
32.31200,-1.07675,-52637.37440
32.39800,-1.07974,-52889.85968
32.48000,-1.08261,-53144.10329
32.57200,-1.08560,-53399.49131
32.66200,-1.08853,-53653.07331
32.74800,-1.09152,-53907.59706
32.83200,-1.09427,-54158.78892
32.92600,-1.09738,-54411.38148
33.01800,-1.10043,-54666.44168
33.10400,-1.10336,-54922.33634
33.19200,-1.10623,-55176.96738
33.28000,-1.10921,-55430.94277
33.37000,-1.11214,-55680.99022
33.45600,-1.11507,-55933.80332
33.54600,-1.11812,-56187.03961
33.63200,-1.12093,-56439.60238
33.72800,-1.12410,-56693.16649
33.81000,-1.12685,-56945.33587
33.90000,-1.12966,-57197.08204
33.98800,-1.13277,-57449.40639
34.06800,-1.13558,-57702.74401
34.16000,-1.13851,-57956.90417
34.25000,-1.14162,-58211.24911
34.33800,-1.14455,-58463.08470
34.42600,-1.14736,-58713.18579
34.51600,-1.15023,-58964.95581
34.60200,-1.15322,-59219.90275
34.68800,-1.15621,-59474.65897
34.78000,-1.15920,-59726.89986
34.86600,-1.16213,-59981.06599
34.95200,-1.16500,-60235.84604
35.04600,-1.16799,-60489.96449
35.13800,-1.17098,-60742.46764
35.22200,-1.17397,-60993.24226
35.30800,-1.17672,-61245.06593
35.40200,-1.17983,-61497.86115
35.48600,-1.18276,-61752.94518
35.57400,-1.18569,-62008.31532
35.66000,-1.18856,-62260.19859
35.75000,-1.19155,-62514.03093
35.84200,-1.19465,-62768.52489
35.92600,-1.19746,-63018.97168
36.02000,-1.20045,-63269.64498
36.11000,-1.20344,-63520.15734
36.19400,-1.20637,-63770.87831
36.28200,-1.20924,-64023.23842
36.37400,-1.21223,-64275.46144
36.46200,-1.21534,-64528.42951
36.54600,-1.21821,-64779.58560
36.64600,-1.22126,-65034.21664
36.73800,-1.22425,-65285.83765
36.82000,-1.22718,-65540.27796
36.90200,-1.22999,-65793.06126
37.00200,-1.23304,-66035.55083
37.08600,-1.23615,-66291.28456
37.16800,-1.23890,-66546.57722
37.26400,-1.24189,-66797.51277
37.35800,-1.24512,-67053.03788
37.44200,-1.24799,-67307.41858
37.52600,-1.25086,-67561.76949
37.62600,-1.25391,-67814.23688
37.71400,-1.25707,-68068.70699
37.80200,-1.26006,-68324.54205
37.89600,-1.26299,-68577.26574
37.98800,-1.26604,-68827.37875
38.07400,-1.26909,-69078.11165
38.16000,-1.27190,-69331.22873
38.25800,-1.27501,-69585.66308
38.34600,-1.27806,-69837.34965
38.43400,-1.28111,-70090.06143
38.52600,-1.28410,-70341.09831
38.62200,-1.28709,-70591.86697
38.70800,-1.29014,-70843.88137
38.79200,-1.29289,-71098.38724
38.89200,-1.29600,-71339.16020
38.97400,-1.29899,-71589.93483
39.05600,-1.30186,-71842.95058
39.15200,-1.30491,-72096.16899
39.24200,-1.30790,-72347.42641
39.32800,-1.31088,-72603.05882
39.41800,-1.31369,-72855.71694
39.51400,-1.31680,-73109.71022
39.60400,-1.31991,-73361.39679
39.68800,-1.32284,-73615.55696
39.77800,-1.32589,-73870.84365
39.87000,-1.32894,-74123.00110
39.96400,-1.33199,-74376.34468
40.05000,-1.33486,-74627.93589
40.14000,-1.33791,-74877.94161
40.23400,-1.34078,-75129.77123
40.32600,-1.34401,-75382.33995
40.40800,-1.34688,-75636.86967
40.50800,-1.35005,-75888.97943
40.59400,-1.35310,-76139.02688
40.67800,-1.35591,-76392.54332
40.77200,-1.35890,-76644.45639
40.86000,-1.36183,-76895.00451
40.95400,-1.36499,-77145.98179
41.04800,-1.36804,-77398.09155
41.13800,-1.37115,-77650.05827
41.22600,-1.37414,-77904.55222
41.31800,-1.37713,-78157.29976
41.41200,-1.38030,-78411.19766
41.49800,-1.38323,-78663.36107
41.59600,-1.38628,-78916.38279
41.69200,-1.38939,-79171.27609
41.78000,-1.39250,-79423.66600
41.86400,-1.39531,-79678.69043
41.96200,-1.39848,-79930.98497
42.04800,-1.40153,-80183.90536
42.14000,-1.40458,-80438.08341
42.23200,-1.40756,-80692.75022
42.32400,-1.41061,-80945.78385
42.41800,-1.41372,-81197.20221
42.50400,-1.41671,-81449.21064
42.60000,-1.41988,-81704.32448
42.69000,-1.42287,-81958.24623
42.77800,-1.42592,-82213.47332
42.87200,-1.42897,-82467.97323
42.97200,-1.43208,-82715.61265
43.06000,-1.43519,-82971.59672
43.14600,-1.43812,-83226.55559
43.24600,-1.44123,-83471.01212
43.34000,-1.44445,-83726.09019
43.42000,-1.44732,-83977.73504
43.50600,-1.45007,-84231.25148
43.60600,-1.45330,-84462.57114
43.68600,-1.45623,-84713.25040
43.78000,-1.45916,-84966.71915
43.88000,-1.46233,-85221.27271
43.96800,-1.46550,-85475.15869
44.05400,-1.46849,-85727.82278
44.14400,-1.47136,-85980.15904
44.24400,-1.47465,-86219.65647
44.32800,-1.47764,-86471.15827
44.41800,-1.48051,-86722.81504
44.51800,-1.48356,-86962.24689
44.60600,-1.48667,-87213.23609
44.69000,-1.48966,-87465.42335
44.78000,-1.49253,-87718.72520
44.87600,-1.49569,-87971.14491
44.96600,-1.49880,-88222.98050
45.05800,-1.50185,-88476.37773
45.15200,-1.50478,-88730.11470
45.25000,-1.50801,-88981.77147
45.33000,-1.51106,-89237.41579
45.43000,-1.51405,-89483.94656
45.52400,-1.51728,-89736.75966
45.60200,-1.52015,-89990.21053
45.69400,-1.52308,-90244.01903
45.79000,-1.52625,-90498.13151
45.88600,-1.52942,-90751.95789
45.97800,-1.53246,-91006.55317
46.07400,-1.53563,-91259.04441
46.16600,-1.53874,-91512.29858
46.25600,-1.54179,-91767.65084
46.35200,-1.54502,-92021.21496
46.44600,-1.54819,-92275.63739
46.54600,-1.55136,-92526.79348
46.64000,-1.55441,-92778.07474
46.73200,-1.55752,-93030.08318
46.82400,-1.56045,-93282.23467
46.91600,-1.56373,-93533.70070
47.00200,-1.56672,-93787.46748
47.10200,-1.56989,-94025.46287
47.18600,-1.57288,-94275.76065
47.27800,-1.57575,-94526.32666
47.37800,-1.57904,-94774.81842
47.46800,-1.58203,-95029.31237
47.55800,-1.58508,-95284.58714
47.65000,-1.58807,-95536.49426
47.74400,-1.59130,-95790.84516
47.83200,-1.59441,-96042.87744
47.93000,-1.59752,-96296.63825
48.02200,-1.60068,-96552.19316
48.11400,-1.60367,-96802.37174
48.21200,-1.60678,-97057.42598
48.30400,-1.60989,-97312.00933
48.38600,-1.61288,-97563.30252
48.48400,-1.61593,-97816.12158
48.58000,-1.61922,-98070.66917
48.66600,-1.62209,-98323.96507
48.76600,-1.62538,-98575.75297
48.86000,-1.62855,-98827.54087
48.95000,-1.63154,-99077.65388
49.03600,-1.63459,-99329.69809
49.13200,-1.63763,-99582.17740
49.23200,-1.64092,-99832.96990
49.29400,-1.64302,-100002.22921