File: data/RAW Test Data/ThreePoint Raw/FiberSolid.is_comp_RawData/Raw-Full.csv
Time,Extension,Load
(sec),(mm),(N)
0.00000,-0.00006,-0.01401
0.10000,-0.01704,-0.00125
0.20000,-0.05118,0.05963
0.30000,-0.08562,0.06300
0.40000,-0.11814,0.03010
0.50000,-0.14923,0.02592
0.60000,-0.17991,-0.00454
0.70000,-0.20998,0.00180
0.80000,-0.24005,0.01046
0.90000,-0.27013,0.01357
1.00000,-0.30002,-0.00293
1.10000,-0.33010,0.00937
1.20000,-0.36017,0.00288
1.30000,-0.39001,-0.01942
1.40000,-0.42020,-0.02771
1.50000,-0.45004,-0.02731
1.60000,-0.47999,0.02115
1.70000,-0.50994,-0.02365
1.80000,-0.53996,-1.44599
1.90000,-0.57003,-4.88074
2.00000,-0.59999,-8.62729
2.10000,-0.63000,-12.31395
2.20000,-0.66002,-15.95035
2.30000,-0.68991,-19.55001
2.40000,-0.72004,-23.11607
2.50000,-0.74994,-23.97979
2.60000,-0.78007,-24.02490
2.70000,-0.80997,-25.08767
2.80000,-0.84004,-27.48221
2.90000,-0.87000,-30.93333
3.00000,-0.89995,-34.90916
3.10000,-0.92997,-39.01373
3.20000,-0.95998,-42.81543
3.30000,-0.98999,-46.53882
3.40000,-1.02001,-50.37771
3.50000,-1.04996,-54.50346
3.60000,-1.07998,-58.57482
3.70000,-1.10993,-62.80870
3.80000,-1.14001,-66.98557
3.90000,-1.16996,-71.14826
4.00000,-1.19998,-75.35101
4.10000,-1.23005,-79.57873
4.20000,-1.26000,-83.78868
4.30000,-1.29002,-87.94902
4.40000,-1.31991,-92.15350
4.50000,-1.34993,-96.38966
4.60000,-1.37988,-100.51573
4.70000,-1.40996,-104.79767
4.80000,-1.43991,-108.99713
4.90000,-1.46992,-113.19340
5.00000,-1.50000,-117.41945
5.10000,-1.53001,-121.70372
5.20000,-1.56003,-125.87151
5.30000,-1.59004,-130.11303
5.40000,-1.62000,-134.40005
5.50000,-1.65007,-138.63874
5.60000,-1.68008,-142.84713
5.70000,-1.71004,-147.14140
5.80000,-1.73999,-151.32330
5.90000,-1.77007,-155.58000
6.00000,-1.79996,-159.87352
6.10000,-1.82998,-164.10816
6.20000,-1.85999,-168.33857
6.30000,-1.88995,-172.52369
6.40000,-1.91984,-176.80967
6.50000,-1.95003,-181.09197
6.60000,-1.97999,-185.32410
6.70000,-2.00994,-189.66125
6.80000,-2.03996,-193.91626
6.90000,-2.06997,-198.16617
7.00000,-2.09999,-202.44980
7.10000,-2.13000,-206.73821
7.20000,-2.15996,-210.93009
7.30000,-2.19003,-215.19728
7.40000,-2.22004,-219.49325
7.50000,-2.25012,-223.70430
7.60000,-2.27995,-227.97955
7.70000,-2.31003,-232.22942
7.80000,-2.34010,-236.49346
7.90000,-2.36994,-240.67493
8.00000,-2.40007,-244.95590
8.10000,-2.43002,-249.21063
8.20000,-2.45998,-253.46266
8.30000,-2.49005,-257.64348
8.40000,-2.51995,-261.96185
8.50000,-2.54996,-266.11960
8.60000,-2.57992,-270.42512
8.70000,-2.60999,-274.65641
8.80000,-2.64001,-278.81023
8.90000,-2.66996,-283.06972
9.00000,-2.69997,-287.24359
9.10000,-2.72999,-291.44062
9.20000,-2.76000,-295.65943
9.30000,-2.79002,-299.83163
9.40000,-2.82003,-304.08936
9.50000,-2.85005,-308.26731
9.60000,-2.88000,-312.52500
9.70000,-2.91007,-316.73554
9.80000,-2.93991,-320.88686
9.90000,-2.97004,-325.10895
10.00000,-2.99994,-329.30445
10.10000,-3.03001,-333.50956
10.20000,-3.05997,-337.60026
10.30000,-3.08998,-341.80023
10.40000,-3.11994,-346.05317
10.50000,-3.14995,-350.20411
10.60000,-3.17996,-354.43004
10.70000,-3.21004,-358.66607
10.80000,-3.24005,-362.87166
10.90000,-3.27007,-367.05576
11.00000,-3.30008,-371.21702
11.10000,-3.32998,-375.45253
11.20000,-3.35999,-379.56711
11.30000,-3.38989,-383.86099
11.40000,-3.41990,-388.01230
11.50000,-3.44991,-392.18076
11.60000,-3.47999,-396.37387
11.70000,-3.51006,-400.51948
11.80000,-3.54002,-404.69505
11.90000,-3.57009,-408.87512
12.00000,-3.60005,-413.09640
12.10000,-3.63012,-417.28366
12.20000,-3.65995,-421.41348
12.30000,-3.68991,-425.60175
12.40000,-3.72004,-429.76096
12.50000,-3.75000,-433.98883
12.60000,-3.78007,-438.21700
12.70000,-3.80997,-442.36135
12.80000,-3.84004,-446.54861
12.90000,-3.86999,-450.67824
13.00000,-3.90007,-454.84453
13.10000,-3.93002,-459.05385
13.20000,-3.96010,-463.16165
13.30000,-3.98999,-467.42789
13.40000,-4.02007,-471.66198
13.50000,-4.04996,-475.77050
13.60000,-4.08010,-480.02362
13.70000,-4.10999,-484.18108
13.80000,-4.14006,-488.34141
13.90000,-4.17002,-492.57021
14.00000,-4.20003,-496.77104
14.10000,-4.23005,-500.93915
14.20000,-4.26000,-505.01838
14.30000,-4.28990,-509.22405
14.40000,-4.31997,-513.39157
14.50000,-4.34999,-517.62793
14.60000,-4.37988,-521.79407
14.70000,-4.41001,-526.03394
14.80000,-4.43997,-530.17687
14.90000,-4.46992,-534.35747
15.00000,-4.49994,-538.54432
15.10000,-4.53001,-542.64583
15.20000,-4.55997,-546.85976
15.30000,-4.59004,-551.02833
15.40000,-4.61999,-555.14459
15.50000,-4.64995,-559.37778
15.60000,-4.68002,-563.58494
15.70000,-4.70992,-567.71930
15.80000,-4.73999,-571.88947
15.90000,-4.76995,-576.01482
16.00000,-4.80008,-580.20726
16.10000,-4.83004,-584.39262
16.20000,-4.86005,-588.48932
16.30000,-4.88994,-592.66493
16.40000,-4.91996,-596.81952
16.50000,-4.94997,-601.01632
16.60000,-4.97993,-605.14003
16.70000,-5.01000,-609.29704
16.80000,-5.04002,-613.41569
16.90000,-5.07009,-617.56067
17.00000,-5.09998,-621.74968
17.10000,-5.13012,-625.87820
17.20000,-5.16007,-630.07273
17.30000,-5.19003,-634.20139
17.40000,-5.21998,-638.34429
17.50000,-5.25006,-642.51795
17.60000,-5.28001,-646.67381
17.70000,-5.30997,-650.82788
17.80000,-5.34004,-654.95111
17.90000,-5.36999,-659.05064
18.00000,-5.39995,-663.19138
18.10000,-5.43002,-667.31200
18.20000,-5.45998,-671.35006
18.30000,-5.48993,-675.47835
18.40000,-5.51995,-679.67705
18.50000,-5.55020,-683.88358
18.60000,-5.57997,-687.94996
18.70000,-5.61005,-692.10038
18.80000,-5.64000,-696.23917
18.90000,-5.66996,-700.34958
19.00000,-5.69997,-704.47944
19.10000,-5.73005,-708.59566
19.20000,-5.75994,-712.69028
19.30000,-5.79008,-716.87989
19.40000,-5.81997,-720.98069
19.50000,-5.85004,-725.08946
19.60000,-5.87994,-729.24085
19.70000,-5.91001,-733.32228
19.80000,-5.93997,-737.45750
19.90000,-5.96992,-741.62029
20.00000,-6.00006,-745.73711
20.10000,-6.02995,-749.86272
20.20000,-6.06002,-753.97968
20.30000,-6.08998,-758.09874
20.40000,-6.11999,-762.24141
20.50000,-6.14995,-766.33923
20.60000,-6.17990,-770.48235
20.70000,-6.21004,-774.57450
20.80000,-6.23993,-778.71457
20.90000,-6.26989,-782.85217
21.00000,-6.29996,-786.93047
21.10000,-6.32997,-791.00229
21.20000,-6.36011,-795.14213
21.30000,-6.39000,-799.26476
21.40000,-6.42002,-803.39715
21.50000,-6.45009,-807.53125
21.60000,-6.48005,-811.63436
21.70000,-6.51000,-815.71802
21.80000,-6.54001,-819.80526
21.90000,-6.57003,-823.94995
22.00000,-6.59998,-828.07720
22.10000,-6.63006,-832.14916
22.20000,-6.65995,-836.20667
22.30000,-6.68997,-840.27857
22.40000,-6.71998,-844.40731
22.50000,-6.74994,-848.42317
22.60000,-6.77995,-852.57888
22.70000,-6.80996,-856.69465
22.80000,-6.84004,-860.72646
22.90000,-6.86993,-864.79537
23.00000,-6.89995,-868.85832
23.10000,-6.92996,-872.95562
23.20000,-6.95992,-876.96224
23.30000,-6.98987,-880.97192
23.40000,-7.02006,-885.03212
23.50000,-7.04996,-889.07346
23.60000,-7.08003,-893.15459
23.70000,-7.10999,-897.12247
23.80000,-7.13994,-901.05377
23.90000,-7.16996,-905.04833
24.00000,-7.19997,-909.09846
24.10000,-7.22999,-913.06128
24.20000,-7.26000,-917.08720
24.30000,-7.29001,-921.01395
24.40000,-7.32003,-925.01737
24.50000,-7.34998,-929.00619
24.60000,-7.38000,-932.88720
24.70000,-7.41001,-936.84383
24.80000,-7.43991,-940.72372
24.90000,-7.46986,-944.60860
25.00000,-7.49993,-948.58125
25.10000,-7.52989,-952.42985
25.20000,-7.55996,-956.26585
25.30000,-7.58992,-960.15222
25.40000,-7.61993,-964.04605
25.50000,-7.64995,-968.01877
25.60000,-7.68002,-971.82967
25.70000,-7.70998,-975.77825
25.80000,-7.73999,-979.65799
25.90000,-7.76994,-983.48573
26.00000,-7.80008,-987.32777
26.10000,-7.82997,-991.21504
26.20000,-7.86005,-995.11355
26.30000,-7.89006,-999.00171
26.40000,-7.92014,-1002.81991
26.50000,-7.95003,-1006.71038
26.60000,-7.97999,-1010.55987
26.70000,-8.01000,-1014.37256
26.80000,-8.03989,-1018.21415
26.90000,-8.06991,-1022.01648
27.00000,-8.09992,-1025.87178
27.10000,-8.13000,-1029.71576
27.20000,-8.15995,-1033.37251
27.30000,-8.18997,-1037.20151
27.40000,-8.22004,-1041.03439
27.50000,-8.24999,-1044.77927
27.60000,-8.28001,-1048.63159
27.70000,-8.31002,-1052.33602
27.80000,-8.34004,-1056.14513
27.90000,-8.37005,-1059.96534
28.00000,-8.40007,-1063.74934
28.10000,-8.42996,-1067.43276
28.20000,-8.46009,-1071.25580
28.30000,-8.48999,-1075.04994
28.40000,-8.52000,-1078.83461
28.50000,-8.55008,-1082.64744
28.60000,-8.58009,-1086.33764
28.70000,-8.61005,-1090.11337
28.80000,-8.64000,-1093.86571
28.90000,-8.66996,-1097.54443
29.00000,-8.69997,-1101.33782
29.10000,-8.73004,-1105.03927
29.20000,-8.75994,-1108.76955
29.30000,-8.79007,-1112.52800
29.40000,-8.82003,-1116.25873
29.50000,-8.85004,-1119.95377
29.60000,-8.88000,-1123.71750
29.70000,-8.91007,-1127.35674
29.80000,-8.94002,-1131.13478
29.90000,-8.97010,-1134.93651
30.00000,-9.00005,-1138.47911
30.10000,-9.03001,-1142.24091
30.20000,-9.05990,-1145.87426
30.30000,-9.08998,-1149.58838
30.40000,-9.11999,-1153.32030
30.50000,-9.15001,-1157.01102
30.60000,-9.18008,-1160.66739
30.70000,-9.21015,-1164.38895
30.80000,-9.24005,-1168.03706
30.90000,-9.27000,-1171.54203
31.00000,-9.30002,-1175.18596
31.10000,-9.32997,-1178.81849
31.20000,-9.35987,-1182.46011
31.30000,-9.39006,-1186.11574
31.40000,-9.41996,-1189.79454
31.50000,-9.45003,-1193.32470
31.60000,-9.47992,-1196.94799
31.70000,-9.51000,-1200.51622
31.80000,-9.54001,-1204.08021
31.90000,-9.56997,-1207.73174
32.00000,-9.59998,-1211.36874
32.10000,-9.63000,-1214.94614
32.20000,-9.66007,-1218.52137
32.30000,-9.69002,-1222.13684
32.40000,-9.71998,-1225.77585
32.50000,-9.74993,-1229.28791
32.60000,-9.78001,-1232.84049
32.70000,-9.80984,-1236.45633
32.80000,-9.83992,-1239.99774
32.90000,-9.86999,-1243.58751
33.00000,-9.90006,-1247.12579
33.10000,-9.93002,-1250.66936
33.20000,-9.96003,-1254.22597
33.30000,-9.98999,-1257.78690
33.40000,-10.02006,-1261.31058
33.50000,-10.05008,-1264.90429
33.60000,-10.08009,-1268.41933
33.70000,-10.11011,-1271.71963
33.80000,-10.14006,-1275.27475
33.90000,-10.17001,-1278.77891
34.00000,-10.19997,-1282.21303
34.10000,-10.22998,-1285.76308
34.20000,-10.26000,-1289.10214
34.30000,-10.29001,-1292.41258
34.40000,-10.32003,-1295.27047
34.50000,-10.34992,-1298.10989
34.60000,-10.38000,-1301.31781
34.70000,-10.40995,-1304.55628
34.80000,-10.43997,-1307.79952
34.90000,-10.46998,-1310.78631
35.00000,-10.50005,-1314.07842
35.10000,-10.52995,-1317.50405
35.20000,-10.55996,-1320.77232
35.30000,-10.58992,-1324.01586
35.40000,-10.61999,-1327.30290
35.50000,-10.64989,-1330.63078
35.60000,-10.67990,-1333.95210
35.70000,-10.71003,-1337.32438
35.80000,-10.73993,-1339.88053
35.90000,-10.77006,-1343.21347
36.00000,-10.79996,-1346.43495
36.10000,-10.83003,-1349.72662
36.20000,-10.86005,-1353.10009
36.30000,-10.88994,-1356.38624
36.40000,-10.92007,-1359.51847
36.50000,-10.94997,-1362.60465
36.60000,-10.98010,-1365.93014
36.70000,-11.01000,-1369.11631
36.80000,-11.03995,-1372.05362
36.90000,-11.06997,-1375.25544
37.00000,-11.09998,-1378.53473
37.10000,-11.12994,-1381.80971
37.20000,-11.16007,-1384.92331
37.30000,-11.18996,-1387.82859
37.40000,-11.21998,-1390.72075
37.50000,-11.24993,-1393.91437
37.60000,-11.28001,-1397.09353
37.70000,-11.30996,-1399.76069
37.80000,-11.34004,-1402.39373
37.90000,-11.36999,-1405.17846
38.00000,-11.40012,-1408.09789
38.10000,-11.42996,-1411.08334
38.20000,-11.46003,-1414.14121
38.30000,-11.48999,-1416.70436
38.40000,-11.52006,-1419.44915
38.50000,-11.55002,-1422.08517
38.60000,-11.58003,-1424.75501
38.70000,-11.61005,-1427.56939
38.80000,-11.64000,-1430.56005
38.90000,-11.67001,-1433.60093
39.00000,-11.69991,-1436.02759
39.10000,-11.72998,-1438.85329
39.20000,-11.76000,-1441.89030
39.30000,-11.79001,-1444.68486
39.40000,-11.82003,-1447.34532
39.50000,-11.84998,-1449.71833
39.60000,-11.88005,-1452.11890
39.70000,-11.91001,-1454.42292
39.80000,-11.93996,-1457.19901
39.90000,-11.96998,-1459.81014
40.00000,-11.99999,-1461.70959
40.10000,-12.02995,-1463.87085
40.20000,-12.06002,-1465.98876
40.30000,-12.09010,-1468.30559
40.40000,-12.12005,-1469.49872
40.50000,-12.15006,-1471.59114
40.60000,-12.18008,-1473.95715
40.70000,-12.21009,-1476.01530
40.80000,-12.24005,-1478.48129
40.90000,-12.27006,-1480.10239
41.00000,-12.30002,-1481.62276
41.10000,-12.32997,-1483.09052
41.20000,-12.35992,-1484.50792
41.30000,-12.39006,-1486.49365
41.40000,-12.41995,-1488.12994
41.50000,-12.45003,-1490.12223
41.60000,-12.48004,-1492.23968
41.70000,-12.51006,-1494.17028
41.80000,-12.53995,-1496.39845
41.90000,-12.57002,-1498.28836
42.00000,-12.59992,-1500.25144
42.10000,-12.62999,-1501.56245
42.20000,-12.65989,-1503.10025
42.30000,-12.69008,-1505.11310
42.40000,-12.72004,-1506.76951
42.50000,-12.75005,-1508.53306
42.60000,-12.78007,-1510.58361
42.70000,-12.81002,-1511.12646
42.80000,-12.84003,-1512.11843
42.90000,-12.86993,-1513.28161
43.00000,-12.89994,-1514.39548
43.10000,-12.92996,-1515.70424
43.20000,-12.96003,-1517.34412
43.30000,-12.98999,-1518.90442
43.40000,-13.02000,-1520.50272
43.50000,-13.05007,-1521.66575
43.60000,-13.07997,-1523.25362
43.70000,-13.11004,-1524.22398
43.80000,-13.13994,-1525.34336
43.90000,-13.16995,-1525.99961
44.00000,-13.19997,-1526.64125
44.10000,-13.22992,-1527.24236
44.20000,-13.25988,-1528.35786
44.30000,-13.28995,-1529.28993
44.40000,-13.31996,-1530.48888
44.50000,-13.34998,-1531.70258
44.60000,-13.38005,-1531.83207
44.70000,-13.41001,-1532.15811
44.80000,-13.44002,-1532.06021
44.90000,-13.47004,-1532.84982
45.00000,-13.50005,-1532.67264
45.10000,-13.53001,-1533.20730
45.20000,-13.56002,-1533.37449
45.30000,-13.59003,-1533.90735
45.40000,-13.62011,-1534.50772
45.50000,-13.65000,-1534.61367
45.60000,-13.68002,-1534.27750
45.70000,-13.70997,-1534.05666
45.80000,-13.73999,-1534.06024
45.90000,-13.76994,-1533.66566
46.00000,-13.79990,-1533.38894
46.10000,-13.82997,-1532.88603
46.20000,-13.86004,-1532.07541
46.30000,-13.89000,-1530.62060
46.40000,-13.92007,-1529.31556
46.50000,-13.95003,-1527.93944
46.60000,-13.98004,-1526.10570
46.70000,-14.01005,-1521.47472
46.75800,-14.02745,-1504.79630
46.76000,-14.02805,-1486.86066
46.76200,-14.02865,-1452.80376
46.76400,-14.02925,-1404.50299
46.76600,-14.02984,-1346.60140
46.76800,-14.03044,-1281.90055
46.77000,-14.03104,-1211.73970
46.77200,-14.03164,-1137.89946
46.77400,-14.03230,-1062.41971
46.77600,-14.03289,-986.73031
46.77800,-14.03349,-911.78745
46.78000,-14.03415,-838.52656
46.78200,-14.03475,-767.82264
46.78400,-14.03535,-700.30294
46.78600,-14.03600,-636.39350
46.78800,-14.03660,-576.42661
46.79000,-14.03720,-520.64456
46.79200,-14.03780,-469.17722
46.79400,-14.03839,-422.06250
46.79600,-14.03899,-379.27393
46.79800,-14.03959,-340.72854
46.80000,-14.04019,-306.29253
46.80200,-14.04079,-275.79529
46.80400,-14.04138,-249.03893
46.80600,-14.04198,-225.80205
46.80800,-14.04258,-205.84604
46.81000,-14.04318,-188.92426
46.81200,-14.04378,-174.78842
46.81600,-14.04497,-153.88411
46.82000,-14.04623,-141.19974
46.84600,-14.05400,-155.37456
46.85400,-14.05645,-167.87654
46.86600,-14.06004,-182.06889
46.96600,-14.08987,-190.84817
47.06600,-14.11983,-191.39180
47.16600,-14.14984,-191.78009
47.26600,-14.17974,-192.06032
47.36600,-14.20981,-192.24588
47.46600,-14.23977,-192.35291
47.56600,-14.26990,-192.47672
47.66600,-14.29979,-192.50520
47.76600,-14.32981,-192.50821
47.86600,-14.35976,-192.37056
47.96600,-14.38984,-192.20736
48.06600,-14.41979,-191.44043
48.07600,-14.42278,-177.01779
48.08200,-14.42464,-161.60250
48.08800,-14.42649,-145.63779
48.09400,-14.42822,-131.12102
48.10200,-14.43062,-115.73023
48.11400,-14.43420,-101.80064
48.21400,-14.46422,-102.43591
48.31400,-14.49423,-103.77609
48.41400,-14.52419,-104.95031
48.51400,-14.55432,-105.95142
48.61400,-14.58421,-106.86528
48.71400,-14.61429,-107.67767
48.81400,-14.64424,-108.41783
48.91400,-14.67420,-109.13912
49.01400,-14.70427,-109.87869
49.11400,-14.73423,-110.59818
49.21400,-14.76412,-111.18249
49.31400,-14.79420,-111.83199
49.41400,-14.82415,-112.41754
49.51400,-14.85422,-113.05030
49.61400,-14.88418,-113.58502
49.71400,-14.91431,-114.21404
49.81400,-14.94421,-114.70199
49.91400,-14.97428,-115.24339
50.01400,-15.00412,-115.84293
50.11400,-15.03413,-116.38444
50.21400,-15.06408,-116.95325
50.31400,-15.09416,-117.52289
50.41400,-15.12417,-118.00992
50.51400,-15.15425,-118.56212
50.61400,-15.18426,-119.04501
50.71400,-15.21428,-119.59336
50.81400,-15.24423,-120.12282
50.91400,-15.27418,-120.62575
51.01400,-15.30426,-121.16684
51.11400,-15.33415,-121.60793
51.21400,-15.36429,-122.14705
51.31400,-15.39424,-122.60461
51.41400,-15.42426,-123.09290
51.51400,-15.45427,-123.56255
51.61400,-15.48423,-124.03043
51.71400,-15.51424,-124.55749
51.81400,-15.54425,-125.07515
51.91400,-15.57427,-125.57998
52.01400,-15.60416,-126.06420
52.11400,-15.63430,-126.50564
52.21400,-15.66407,-126.92994
52.31400,-15.69409,-127.33746
52.41400,-15.72410,-127.73714
52.51400,-15.75417,-128.19633
52.61400,-15.78419,-128.60334
52.71400,-15.81426,-129.03281
52.81400,-15.84434,-129.48178
52.91400,-15.87423,-129.89411
53.01400,-15.90425,-130.31968
53.11400,-15.93420,-130.71841
53.21400,-15.96428,-131.08110
53.31400,-15.99411,-131.54362
53.41400,-16.02424,-131.94201
53.51400,-16.05414,-132.31165
53.61400,-16.08415,-132.75206
53.71400,-16.11423,-133.10868
53.81400,-16.14418,-133.54118
53.91400,-16.17420,-133.99420
54.01400,-16.20427,-134.32754
54.11400,-16.23416,-134.70666
54.21400,-16.26424,-135.12665
54.31400,-16.29413,-135.49601
54.37000,-16.31099,-135.73569