File: data/RAW Test Data/Three Point Bend Test Results/Test50-15.is_comp_RawData/CoreEdge50-15.csv
Time,Extension,Load
(sec),(mm),(N)
0.00000,-0.00006,-0.24490
0.20000,-0.05698,0.73978
0.40000,-0.13130,0.72294
0.60000,-0.19982,-0.03222
0.80000,-0.26672,0.03554
1.00000,-0.33339,0.04338
1.20000,-0.40005,-0.03927
1.40000,-0.46672,0.21023
1.60000,-0.53338,-0.25234
1.80000,-0.59993,-0.00049
2.00000,-0.66659,-0.98987
2.20000,-0.73332,-0.12308
2.40000,-0.80004,-1.28676
2.60000,-0.86671,-0.82066
2.80000,-0.93337,-1.91423
3.00000,-0.99998,-1.46693
3.20000,-1.06670,-1.16534
3.40000,-1.13337,-1.99883
3.60000,-1.19992,-1.51354
3.80000,-1.26664,-1.46106
4.00000,-1.33331,-1.93264
4.20000,-1.40009,-1.97611
4.40000,-1.46676,-2.40108
4.60000,-1.53342,-2.03956
4.80000,-1.60003,-3.03913
5.00000,-1.66675,-2.81861
5.20000,-1.73336,-2.78414
5.40000,-1.80002,-3.07751
5.60000,-1.86657,-3.09944
5.80000,-1.93329,-2.56872
6.00000,-1.99996,-3.57416
6.20000,-2.06668,-3.42414
6.40000,-2.13329,-3.27570
6.60000,-2.19995,-3.24045
6.80000,-2.26668,-3.81543
7.00000,-2.33329,-4.28740
7.20000,-2.39995,-4.68691
7.40000,-2.46662,-3.48995
7.60000,-2.53328,-4.18792
7.80000,-2.60001,-4.02929
8.00000,-2.66667,-4.66968
8.20000,-2.73340,-4.81225
8.40000,-2.79994,-5.45578
8.60000,-2.86673,-5.20863
8.80000,-2.93339,-5.80985
9.00000,-3.00012,-5.40447
9.20000,-3.06660,-5.53920
9.40000,-3.13333,-5.81612
9.60000,-3.20005,-5.37940
9.80000,-3.26666,-6.30180
10.00000,-3.33332,-6.18743
10.20000,-3.39987,-6.46709
10.40000,-3.46666,-6.31198
10.60000,-3.53344,-6.74205
10.80000,-3.59999,-6.90929
11.00000,-3.66659,-6.20349
11.20000,-3.73326,-6.94141
11.40000,-3.80010,-6.71189
11.60000,-3.86671,-7.16232
11.80000,-3.93337,-7.17093
12.00000,-3.99992,-7.14391
12.20000,-4.06664,-7.62175
12.40000,-4.13343,-6.87365
12.60000,-4.19997,-7.78038
12.80000,-4.26664,-8.33617
13.00000,-4.33324,-7.39223
13.20000,-4.39997,-7.71223
13.40000,-4.46675,-8.39649
13.60000,-4.53342,-8.20026
13.80000,-4.59997,-8.71571
14.00000,-4.66663,-8.05142
14.20000,-4.73336,-8.64482
14.40000,-4.79996,-8.79992
14.60000,-4.86675,-9.27659
14.80000,-4.93323,-9.48771
15.00000,-4.99984,-8.95307
15.20000,-5.06674,-9.00477
15.40000,-5.13335,-9.73016
15.60000,-5.19995,-8.71454
15.80000,-5.26656,-9.99493
16.00000,-5.33322,-9.66357
16.20000,-5.39983,-10.19312
16.40000,-5.46673,-9.42230
16.60000,-5.53340,-9.88252
16.80000,-5.59994,-10.46338
17.00000,-5.66685,-10.86485
17.20000,-5.73345,-10.18489
17.40000,-5.80006,-10.68193
17.60000,-5.86655,-10.49941
17.80000,-5.93327,-10.57461
18.00000,-6.00000,-10.86367
18.20000,-6.06666,-10.53074
18.40000,-6.13345,-11.18602
18.60000,-6.19999,-11.24477
18.80000,-6.26660,-11.03092
19.00000,-6.33326,-12.03126
19.20000,-6.40005,-11.80135
19.40000,-6.46665,-11.57378
19.60000,-6.53332,-12.12370
19.80000,-6.60010,-13.07352
20.00000,-6.66659,-11.61217
20.20000,-6.73331,-12.54789
20.40000,-6.79998,-12.54123
20.60000,-6.86658,-12.89883
20.80000,-6.93325,-12.41550
21.00000,-6.99998,-13.13423
21.20000,-7.06664,-12.90666
21.40000,-7.13331,-12.74020
21.60000,-7.19991,-13.06255
21.80000,-7.26664,-13.33477
22.00000,-7.33336,-12.55650
22.20000,-7.39997,-13.44835
22.40000,-7.46675,-12.96972
22.60000,-7.53330,-12.83655
22.80000,-7.59990,-13.78089
23.00000,-7.66663,-13.80830
23.20000,-7.73341,-13.80478
23.40000,-7.79996,-13.97320
23.60000,-7.86674,-13.91954
23.80000,-7.93335,-14.12282
24.00000,-7.99995,-13.95048
24.20000,-8.06668,-14.65237
24.40000,-8.13329,-14.47925
24.60000,-8.20001,-13.79029
24.80000,-8.26674,-14.48982
25.00000,-8.33346,-15.12630
25.20000,-8.40001,-14.80747
25.40000,-8.46667,-14.94965
25.60000,-8.53328,-15.17173
25.80000,-8.59994,-15.20228
26.00000,-8.66673,-15.04405
26.20000,-8.73333,-14.87876
26.40000,-8.80006,-15.48978
26.60000,-8.86672,-15.41771
26.80000,-8.93327,-14.95239
27.00000,-9.00005,-15.53404
27.20000,-9.06672,-15.79450
27.40000,-9.13338,-14.83176
27.60000,-9.20005,-15.89908
27.80000,-9.26665,-15.95431
28.00000,-9.33332,-15.96801
28.20000,-9.39999,-16.02089
28.40000,-9.46665,-14.97981
28.60000,-9.53332,-14.45026
28.80000,-9.60010,-15.57046
29.00000,-9.66665,-14.84938
29.20000,-9.73331,-15.06833
29.40000,-9.80004,-15.90848
29.60000,-9.86676,-9.89505
29.80000,-9.93331,-10.44301
30.00000,-9.99991,-10.90597
30.20000,-10.06658,-9.94910
30.40000,-10.13330,-10.08227
30.60000,-10.20003,-10.59498
30.80000,-10.26663,-10.58519
31.00000,-10.33330,-10.73285
31.20000,-10.40003,-10.29848
31.40000,-10.46663,-10.19586
31.60000,-10.53342,-10.16923
31.80000,-10.60002,-10.41833
32.00000,-10.66663,-10.55385
32.20000,-10.73341,-9.27581
32.40000,-10.80008,-10.22132
32.60000,-10.86656,-10.21388
32.80000,-10.93329,-10.16413
33.00000,-11.00001,-10.54719
33.20000,-11.06668,-9.71331
33.40000,-11.13334,-9.36276
33.60000,-11.20001,-10.20996
33.80000,-11.26667,-9.53197
34.00000,-11.33334,-10.59576
34.20000,-11.40001,-10.70896
34.40000,-11.46679,-10.41598
34.60000,-11.53333,-10.41167
34.80000,-11.59994,-11.09476
35.00000,-11.66667,-10.79356
35.20000,-11.73333,-10.56678
35.40000,-11.80000,-9.97025
35.60000,-11.86660,-10.02117
35.80000,-11.93327,-10.72306
36.00000,-11.99999,-11.40967
36.20000,-12.06678,-10.53388
36.40000,-12.13338,-10.85623
36.60000,-12.19993,-10.82764
36.80000,-12.26671,-11.19503
37.00000,-12.33332,-10.52409
37.20000,-12.39998,-11.06499
37.40000,-12.46671,-10.16413
37.60000,-12.53325,-10.45280
37.80000,-12.60004,-10.98431
38.00000,-12.66671,-11.95919
38.20000,-12.73343,-11.46255
38.40000,-12.79998,-10.81784
38.60000,-12.86658,-10.94083
38.80000,-12.93337,-11.28237
39.00000,-13.00003,-10.80649
39.20000,-13.06676,-11.78176
39.40000,-13.13330,-11.56125
39.60000,-13.20003,-11.23106
39.80000,-13.26663,-11.69050
40.00000,-13.33336,-11.95058
40.20000,-13.40014,-10.94945
40.40000,-13.46669,-11.61687
40.60000,-13.53335,-11.89026
40.80000,-13.60002,-11.91376
41.00000,-13.66662,-12.18637
41.20000,-13.73335,-12.47582
41.40000,-13.80007,-11.83072
41.60000,-13.86668,-12.41824
41.80000,-13.93329,-10.98744
42.00000,-14.00007,-12.29094
42.20000,-14.06674,-12.15699
42.40000,-14.13328,-12.10216
42.60000,-14.19995,-12.62152
42.80000,-14.26667,-12.50558
43.00000,-14.33346,-11.80761
43.20000,-14.40000,-12.43821
43.40000,-14.46661,-12.61251
43.60000,-14.53339,-12.75900
43.80000,-14.60000,-12.55298
44.00000,-14.66672,-12.55494
44.20000,-14.73339,-12.77271
44.40000,-14.80005,-12.98108
44.60000,-14.86660,-12.73158
44.80000,-14.93344,-12.98617
45.00000,-14.99993,-12.64463
45.20000,-15.06671,-13.07783
45.40000,-15.13338,-11.99444
45.60000,-15.19993,-12.56159
45.80000,-15.26671,-12.56003
46.00000,-15.33332,-12.74882
46.20000,-15.39992,-13.07195
46.40000,-15.46659,-12.93878
46.60000,-15.53325,-12.70142
46.80000,-15.59992,-12.82284
47.00000,-15.66676,-12.22201
47.20000,-15.73325,-12.63758
47.40000,-15.79997,-12.86084
47.60000,-15.86676,-12.13114
47.80000,-15.93336,-13.22940
48.00000,-16.00003,-12.33168
48.20000,-16.06675,-12.87219
48.40000,-16.13324,-13.32811
48.60000,-16.20003,-12.96071
48.80000,-16.26663,-12.68106
49.00000,-16.33336,-13.50710
49.20000,-16.39996,-12.89922
49.40000,-16.46663,-12.91802
49.60000,-16.53335,-12.51303
49.80000,-16.59996,-13.53570
50.00000,-16.66668,-13.27640
50.20000,-16.73329,-13.43112
50.40000,-16.80007,-12.79503
50.60000,-16.86662,-12.80130
50.80000,-16.93334,-13.03357
51.00000,-17.00001,-13.94500
51.20000,-17.06661,-13.48674
51.40000,-17.13334,-13.58701
51.60000,-17.20000,-13.30226
51.80000,-17.26661,-14.12047
52.00000,-17.33340,-13.91719
52.20000,-17.40006,-14.17061
52.40000,-17.46667,-14.56581
52.60000,-17.53327,-13.42446
52.80000,-17.60005,-14.08992
53.00000,-17.66654,-14.06720
53.20000,-17.73327,-13.03122
53.40000,-17.80005,-13.64576
53.60000,-17.86660,-13.63479
53.80000,-17.93338,-14.12830
54.00000,-18.00005,-13.98495
54.20000,-18.06671,-14.10324
54.40000,-18.13344,-14.46397
54.60000,-18.19998,-14.55249
54.80000,-18.26671,-14.34921
55.00000,-18.33332,-14.44870
55.20000,-18.39998,-14.18627
55.40000,-18.46659,-14.49061
55.60000,-18.53331,-14.65041
55.80000,-18.59998,-14.79729
56.00000,-18.66676,-14.88973
56.20000,-18.73337,-13.93011
56.40000,-18.79997,-14.68409
56.60000,-18.86670,-14.07425
56.80000,-18.93324,-15.02368
57.00000,-18.99991,-15.13022
57.20000,-19.06669,-13.94265
57.40000,-19.13324,-14.35744
57.60000,-19.19978,-15.17918
57.80000,-19.26681,-14.91832
58.00000,-19.33341,-15.22618
58.20000,-19.39990,-14.83489
58.40000,-19.46668,-14.78867
58.60000,-19.53341,-14.69741
58.80000,-19.60001,-14.88385
59.00000,-19.66680,-14.85095
59.20000,-19.73329,-15.14823
59.40000,-19.80001,-14.49217
59.60000,-19.86668,-15.19993
59.80000,-19.93328,-14.93751
60.00000,-20.00007,-15.09771
60.20000,-20.06667,-15.59044
60.40000,-20.13328,-15.01154
60.60000,-20.20000,-14.90578
60.80000,-20.26667,-15.77962
61.00000,-20.33327,-15.34603
61.20000,-20.40006,-14.98960
61.40000,-20.46667,-15.24184
61.60000,-20.53339,-15.20150
61.80000,-20.60017,-15.28375
62.00000,-20.66666,-15.54265
62.20000,-20.73332,-15.21952
62.40000,-20.79999,-15.94804
62.60000,-20.86666,-15.30138
62.80000,-20.93338,-15.34681
63.00000,-20.99987,-16.05693
63.20000,-21.06665,-14.88855
63.40000,-21.13326,-15.13413
63.60000,-21.20004,-15.80077
63.80000,-21.26671,-15.01271
64.00000,-21.33325,-15.76708
64.20000,-21.39998,-15.66603
64.40000,-21.46664,-16.25825
64.60001,-21.53331,-15.99739
64.80000,-21.59985,-16.49756
65.00000,-21.66670,-15.88772
65.20000,-21.73336,-15.67974
65.40000,-21.79997,-15.52150
65.60001,-21.86663,-16.41257
65.80000,-21.93330,-16.86417
66.00000,-21.99997,-15.67504
66.20001,-22.06669,-16.10471
66.40000,-22.13336,-14.33589
66.60001,-22.19996,-15.16742
66.80000,-22.26663,-15.00645
67.00000,-22.33335,-15.14823
67.20001,-22.40002,-15.30725
67.40000,-22.46674,-15.45139
67.60001,-22.53329,-15.20973
67.80000,-22.60001,-14.82902
68.00000,-22.66668,-15.04405
68.20001,-22.73328,-14.61320
68.40000,-22.79995,-15.16664
68.60001,-22.86667,-15.31587
68.80000,-22.93334,-15.35817
69.00000,-23.00007,-15.95156
69.20001,-23.06673,-16.15093
69.40000,-23.13334,-15.43337
69.60001,-23.19994,-15.87323
69.80000,-23.26667,-16.40395
70.00000,-23.33327,-15.62843
70.20001,-23.40012,-16.44821
70.40000,-23.46666,-16.23005
70.60001,-23.53333,-16.08630
70.80000,-23.60011,-16.26765
71.00000,-23.66672,-16.09570
71.20001,-23.73332,-16.04361
71.40000,-23.80005,-16.20145
71.60001,-23.86665,-15.90887
71.80000,-23.93332,-16.38750
72.00000,-24.00005,-16.35499
72.20001,-24.06659,-15.76238
72.40000,-24.13337,-16.40630
72.60001,-24.19998,-16.08787
72.80000,-24.26670,-16.33933
73.00000,-24.33337,-16.60175
73.20001,-24.40009,-16.61350
73.40000,-24.46658,-16.15210
73.60001,-24.53331,-16.42549
73.80000,-24.59997,-16.71024
74.00000,-24.66670,-16.62877
74.20001,-24.73330,-16.49090
74.40000,-24.79997,-17.09918
74.60001,-24.86669,-16.90608
74.80000,-24.93330,-16.76469
75.00000,-25.00002,-16.47328
75.20001,-25.06669,-16.35813
75.40000,-25.13335,-17.44973
75.60001,-25.19984,-17.24410
75.80000,-25.26656,-17.00126
76.00000,-25.33335,-16.92018
76.20001,-25.39995,-15.81095
76.40000,-25.46668,-16.60057
76.60001,-25.53341,-16.92802
76.80000,-25.60013,-16.98716
77.00000,-25.66674,-17.09605
77.20001,-25.73340,-17.16733
77.40000,-25.79995,-16.55240
77.60001,-25.86661,-16.86731
77.80000,-25.93340,-16.93938
78.00000,-26.00000,-17.10310
78.20001,-26.06673,-16.95504
78.40000,-26.13327,-16.34990
78.60001,-26.19994,-16.68361
78.80000,-26.26666,-16.14858
79.00000,-26.33333,-17.12699
79.20001,-26.39999,-16.55514
79.40000,-26.46660,-16.24297
79.60001,-26.53326,-17.28993
79.80000,-26.60005,-16.30368
80.00000,-26.66665,-16.34716
80.20001,-26.73332,-16.36518
80.40000,-26.79999,-15.96057
80.60001,-26.86665,-16.85830
80.80000,-26.93332,-16.88376
81.00001,-26.99998,-16.19480
81.20001,-27.06659,-16.70398
81.40000,-27.13325,-17.01497
81.60001,-27.20004,-16.57707
81.80000,-27.26676,-16.77800
82.00001,-27.33337,-15.85560
82.20001,-27.40003,-16.29154
82.40000,-27.46658,-16.81208
82.60001,-27.53330,-16.39298
82.80000,-27.60003,-16.71534
83.00001,-27.66663,-16.71690
83.20001,-27.73330,-17.02202
83.40000,-27.79996,-16.84420
83.60001,-27.86675,-16.94682
83.80000,-27.93336,-16.87749
84.00001,-28.00008,-16.19284
84.20001,-28.06663,-16.06711
84.40000,-28.13341,-16.16307
84.60001,-28.19996,-16.54026
84.80000,-28.26668,-17.02124
85.00001,-28.33341,-16.39768
85.20001,-28.39995,-16.90452
85.40000,-28.46674,-16.41962
85.60001,-28.53346,-17.12464
85.80000,-28.60007,-16.07964
86.00001,-28.66661,-17.32048
86.20001,-28.73334,-17.36199
86.40000,-28.79989,-16.75294
86.60001,-28.86667,-16.65815
86.80000,-28.93334,-17.05649
87.00001,-29.00000,-17.20258
87.20001,-29.06667,-16.74158
87.40000,-29.13333,-16.40865
87.60001,-29.19994,-16.83480
87.80000,-29.26660,-17.15284
88.00001,-29.33333,-17.38471
88.20001,-29.40005,-16.92097
88.40000,-29.46672,-16.68909
88.60001,-29.53338,-16.89864
88.80000,-29.59999,-16.62525
89.00001,-29.66677,-16.70280
89.20001,-29.73344,-16.47563
89.40000,-29.79998,-17.02084
89.60001,-29.86671,-17.02946
89.80000,-29.93332,-16.84694
90.00001,-29.99986,-16.66951
90.20001,-30.06671,-16.22574
90.40000,-30.13325,-16.63152
90.60001,-30.20004,-16.70398
90.80000,-30.26670,-16.94878
91.00001,-30.33336,-17.08586
91.20001,-30.39997,-16.58765
91.40000,-30.46670,-17.02398
91.60001,-30.53330,-16.30877
91.80000,-30.60003,-16.56219
92.00001,-30.66675,-16.66403
92.20001,-30.73336,-15.92415
92.40000,-30.80002,-16.50383
92.60001,-30.86663,-16.70711
92.80000,-30.93341,-17.14266
93.00001,-31.00008,-16.60332
93.20001,-31.06662,-16.59392
93.40000,-31.13329,-16.97854
93.60001,-31.20007,-17.88998
93.80000,-31.26668,-16.49600
94.00001,-31.33334,-16.46505
94.20001,-31.40007,-16.35068
94.40000,-31.46662,-16.56963
94.60001,-31.53328,-15.81800
94.80000,-31.60013,-15.30138
95.00001,-31.66667,-15.78941
95.20001,-31.73328,-16.11568
95.40000,-31.79994,-16.60253
95.60001,-31.86673,-16.06750
95.80000,-31.93339,-15.55832
96.00001,-32.00000,-16.04948
96.20001,-32.06667,-16.21164
96.40000,-32.13339,-16.53986
96.60001,-32.20006,-15.98016
96.80000,-32.26672,-16.48464
97.00001,-32.33332,-15.41927
97.20001,-32.39987,-16.44116
97.40000,-32.46672,-15.97193
97.60001,-32.53344,-15.94765
97.80000,-32.60005,-16.29820
98.00001,-32.66677,-16.37418
98.20001,-32.73332,-16.43568
98.40000,-32.79992,-15.98368
98.60001,-32.86665,-15.32684
98.80000,-32.93325,-16.04008
99.00001,-32.99992,-16.00366
99.20001,-33.06658,-16.45017
99.40000,-33.13337,-16.53477
99.60001,-33.20003,-15.65781
99.80000,-33.26676,-15.70951
100.00001,-33.33342,-16.51676
100.20001,-33.39997,-15.33820
100.40000,-33.46676,-15.20777
100.60001,-33.53336,-15.79959
100.80000,-33.59990,-16.20772
101.00001,-33.66663,-16.34481
101.20001,-33.73330,-16.00091
101.40000,-33.80008,-16.09883
101.60001,-33.86675,-15.49291
101.80000,-33.93335,-15.30060
102.00001,-34.00002,-15.56537
102.20001,-34.06674,-16.13683
102.40000,-34.13329,-15.91279
102.60001,-34.20007,-15.54618
102.80000,-34.26668,-12.86554
103.00001,-34.33328,-13.73271
103.20001,-34.40001,-13.38764
103.40000,-34.46650,-13.63048
103.60001,-34.53322,-13.74289
103.80000,-34.60006,-14.25834
104.00001,-34.66667,-14.03352
104.20001,-34.73340,-14.26813
104.40000,-34.80006,-12.53261
104.60001,-34.86655,-11.59454
104.80000,-34.93339,-11.94744
105.00001,-35.00000,-12.14759
105.20001,-35.06672,-12.97285
105.40000,-35.13333,-12.76722
105.60001,-35.19981,-12.23337
105.80000,-35.26690,-12.53692
106.00001,-35.33350,-12.91058
106.20001,-35.40005,-11.59180
106.40000,-35.46660,-12.33364
106.60001,-35.53332,-12.87689
106.80000,-35.60004,-12.81697
107.00001,-35.66671,-12.46132
107.20001,-35.73338,-11.92277
107.40000,-35.80004,-11.64742
107.60001,-35.86671,-12.17501
107.80000,-35.93337,-12.13231
108.00001,-35.99998,-11.99053
108.20001,-36.06658,-11.94392
108.40000,-36.13343,-12.37868
108.60001,-36.19997,-12.03479
108.80000,-36.26664,-12.33755
109.00001,-36.33330,-11.93883
109.20001,-36.39997,-12.00933
109.40000,-36.46669,-11.95371
109.60001,-36.53318,-12.21574
109.80000,-36.60002,-12.25138
110.00001,-36.66663,-12.12056
110.20001,-36.73329,-11.76140
110.40000,-36.80002,-12.05085
110.60001,-36.86669,-12.62387
110.80000,-36.93335,-8.74313
111.00001,-37.00001,-10.45045
111.20001,-37.06674,-10.63336
111.40000,-37.13335,-10.37564
111.60001,-37.20001,-10.59498
111.80000,-37.26674,-11.03327
112.00001,-37.33334,-10.68663
112.20001,-37.40007,-10.75988
112.40000,-37.46667,-10.56600
112.60001,-37.53334,-10.57657
112.80000,-37.59994,-11.29138
113.00001,-37.66667,-10.07209
113.20001,-37.73334,-10.87581
113.40001,-37.79988,-10.96551
113.60001,-37.86660,-11.10768
113.80000,-37.93327,-10.75635
114.00001,-38.00005,-11.09594
114.20001,-38.06660,-10.96277
114.40001,-38.13327,-10.83390
114.60001,-38.20005,-11.18641
114.80000,-38.26665,-11.78803
115.00001,-38.33338,-10.71483
115.20001,-38.39999,-10.07562
115.40001,-38.46671,-10.63611
115.60001,-38.53332,-11.14450
115.80000,-38.60010,-11.55067
116.00001,-38.66671,-10.87542
116.20001,-38.73325,-11.27062
116.40001,-38.80004,-10.56247
116.60001,-38.86664,-10.67606
116.80000,-38.93343,-10.59772
117.00001,-38.99997,-10.41872
117.20001,-39.06658,-10.78338
117.40001,-39.13336,-9.88722
117.60001,-39.20003,-10.18058
117.80000,-39.26669,-10.85074
118.00001,-39.33336,-10.77515
118.20001,-39.40009,-10.50333
118.40001,-39.46663,-10.73755
118.60001,-39.53342,-10.29848
118.80000,-39.59996,-11.16840
119.00001,-39.66675,-10.62083
119.20001,-39.73335,-10.48727
119.40001,-39.79996,-10.70974
119.60001,-39.86668,-10.34235
119.80000,-39.93341,-9.91581
120.00001,-39.99989,-10.59890
120.20001,-40.06668,-10.48061
120.40001,-40.13329,-11.09985
120.60001,-40.20007,-10.95846
120.80000,-40.26667,-10.61026
121.00001,-40.33334,-10.10577
121.20001,-40.40007,-10.29182
121.40001,-40.46667,-10.11909
121.60001,-40.53328,-10.45633
121.80000,-40.59994,-10.54563
122.00001,-40.66673,-10.84644
122.20001,-40.73327,-10.12497
122.40001,-40.80018,-10.39562
122.60001,-40.86672,-10.69486
122.80000,-40.93327,-9.31772
123.00001,-41.00000,-10.40932
123.20001,-41.06660,-9.53549
123.40001,-41.13338,-10.36976
123.60001,-41.19999,-10.08697
123.80000,-41.26671,-9.41721
124.00001,-41.33326,-10.32433
124.20001,-41.39998,-10.46377
124.40001,-41.46671,-10.55229
124.60001,-41.53332,-10.15121
124.80000,-41.59998,-9.88604
125.00001,-41.66665,-9.44227
125.20001,-41.73331,-9.52022
125.40001,-41.80004,-10.28438
125.60001,-41.86658,-10.16648
125.80000,-41.93331,-9.29030
126.00001,-42.00003,-10.12144
126.20001,-42.06664,-9.54646
126.40001,-42.13336,-10.53270
126.60001,-42.19997,-9.78851
126.80000,-42.26658,-9.92521
127.00001,-42.33336,-9.73055
127.20001,-42.40002,-10.04741
127.40001,-42.46669,-10.23855
127.60001,-42.53342,-9.77872
127.80000,-42.59990,-10.21975
128.00000,-42.66663,-10.13319
128.20002,-42.73341,-10.04781
128.40001,-42.79996,-9.87625
128.60001,-42.86656,-10.33569
128.80000,-42.93335,-9.44776
129.00000,-43.00007,-8.71728
129.20002,-43.06662,-9.97064
129.40001,-43.13334,-9.64673
129.60001,-43.20001,-9.48222
129.80000,-43.26667,-9.59503
130.00000,-43.33334,-9.90680
130.20002,-43.40000,-8.71963
130.40001,-43.46661,-9.70626
130.60001,-43.53333,-9.70744
130.80000,-43.59994,-9.78342
131.00000,-43.66678,-9.46186
131.20002,-43.73327,-9.58915
131.40002,-43.80005,-8.68007
131.60000,-43.86672,-9.47674
131.80000,-43.93338,-9.71488
132.00000,-44.00005,-9.37099
132.20002,-44.06672,-8.76585
132.40002,-44.13338,-8.98793
132.60000,-44.19993,-8.53280
132.80000,-44.26665,-6.94415
133.00000,-44.33314,-7.81368
133.20002,-44.39998,-8.57431
133.40002,-44.46665,-8.13994
133.60000,-44.53331,-7.91355
133.80000,-44.60004,-8.65343
134.00000,-44.66671,-7.82582
134.20002,-44.73337,-7.65035
134.40002,-44.79998,-8.11370
134.60000,-44.86670,-7.59081
134.80000,-44.93331,-6.96178
135.00000,-45.00003,-7.72241
135.20002,-45.06663,-7.77725
135.40002,-45.13336,-7.40594
135.60000,-45.20009,-7.16192
135.80000,-45.26669,-7.18699
136.00000,-45.33330,-7.29157
136.20002,-45.40002,-7.34640
136.40002,-45.46669,-6.87248
136.60000,-45.53329,-6.72990
136.80000,-45.59996,-7.46665
137.00000,-45.66650,-6.60183
137.20002,-45.73323,-7.41651
137.40002,-45.80007,-6.55796
137.60000,-45.86680,-5.85059
137.80000,-45.93329,-6.56422
138.00000,-46.00001,-7.11257
138.20002,-46.06661,-6.97705
138.40002,-46.13334,-6.60339
138.60000,-46.19995,-6.70562
138.80000,-46.26661,-6.70249
139.00000,-46.33340,-6.56383
139.20002,-46.40000,-6.14200
139.40002,-46.46673,-6.35233
139.60000,-46.53333,-6.55913
139.80000,-46.59994,-6.62846
140.00000,-46.66660,-7.19130
140.20002,-46.73345,-5.79340
140.40002,-46.80005,-5.65592
140.60000,-46.86672,-6.13808
140.80000,-46.93332,-6.16040
141.00000,-46.99999,-5.93832
141.20002,-47.06665,-6.03428
141.40002,-47.13338,-5.31712
141.60000,-47.19999,-5.98219
141.80000,-47.26671,-5.63517
142.00000,-47.33332,-6.09969
142.20002,-47.40004,-5.89093
142.40002,-47.46676,-5.70253
142.60000,-47.53331,-5.72016
142.80000,-47.60004,-6.12280
143.00000,-47.66670,-5.85333
143.20002,-47.73325,-5.72564
143.40002,-47.79991,-5.33788
143.60000,-47.86676,-5.43658
143.80000,-47.93324,-5.17298
144.00000,-48.00003,-5.14674
144.20002,-48.06669,-5.40172
144.40002,-48.13324,-5.98454
144.60000,-48.19996,-5.83962
144.80000,-48.26669,-6.13338
145.00000,-48.33329,-5.76481
145.20002,-48.40008,-5.35707
145.40002,-48.46674,-5.58072
145.60000,-48.53353,-5.23996
145.80000,-48.60008,-6.25323
146.00000,-48.66674,-5.09152
146.20002,-48.73328,-5.32691
146.40002,-48.80001,-4.99085
146.60000,-48.86662,-5.12324
146.80000,-48.93340,-5.74718
147.00000,-49.00007,-4.79580
147.20002,-49.06667,-5.27130
147.40002,-49.13340,-4.74449
147.60000,-49.20000,-4.87844
147.80000,-49.26667,-5.24780
148.00000,-49.33345,-5.05156
148.20002,-49.40000,-5.42444
148.40002,-49.46661,-5.74797
148.60000,-49.53327,-5.35433
148.80000,-49.59999,-5.56897
149.00000,-49.66660,-4.76016
149.20002,-49.73345,-5.13734
149.40002,-49.79999,-5.17612
149.60000,-49.86660,-4.20828
149.80000,-49.93338,-5.47967
150.00000,-50.00005,-4.52202
150.20002,-50.06671,-5.78361
150.40002,-50.13338,-5.66611
150.60000,-50.20004,-5.15967
150.80000,-50.26665,-4.87139
151.00000,-50.33343,-4.85768
151.13000,-50.37660,-5.08055